INFO 2020-03-19 15:25:56,742 autoreload 578 Watching for file changes with StatReloader
INFO 2020-03-19 15:31:35,772 autoreload 578 Watching for file changes with StatReloader
INFO 2020-03-19 16:18:47,217 autoreload 578 Watching for file changes with StatReloader
INFO 2020-03-19 16:19:25,911 autoreload 578 Watching for file changes with StatReloader
INFO 2020-03-19 16:28:01,166 autoreload 578 Watching for file changes with StatReloader
INFO 2020-03-19 16:33:44,542 basehttp 154 "GET / HTTP/1.1" 200 16286
INFO 2020-03-19 16:33:44,628 basehttp 154 "GET /static/admin/css/fonts.css HTTP/1.1" 200 423
INFO 2020-03-19 16:33:44,954 basehttp 154 "GET /static/admin/fonts/Roboto-Bold-webfont.woff HTTP/1.1" 200 82564
INFO 2020-03-19 16:33:44,956 basehttp 154 "GET /static/admin/fonts/Roboto-Regular-webfont.woff HTTP/1.1" 200 80304
INFO 2020-03-19 16:33:44,962 basehttp 154 "GET /static/admin/fonts/Roboto-Light-webfont.woff HTTP/1.1" 200 81348
WARNING 2020-03-19 16:33:45,002 log 228 Not Found: /favicon.ico
WARNING 2020-03-19 16:33:45,003 basehttp 154 "GET /favicon.ico HTTP/1.1" 404 1976
WARNING 2020-03-19 17:04:08,065 log 228 Not Found: /
WARNING 2020-03-19 17:04:08,067 basehttp 154 "GET / HTTP/1.1" 404 2079
WARNING 2020-03-19 17:04:45,740 log 228 Not Found: /
WARNING 2020-03-19 17:04:45,740 basehttp 154 "GET / HTTP/1.1" 404 2079
INFO 2020-03-19 17:04:54,760 basehttp 154 "GET /users HTTP/1.1" 301 0
ERROR 2020-03-19 17:04:54,847 log 228 Internal Server Error: /users/
Traceback (most recent call last):
  File "/home/yudashan/.virtualenvs/Django/lib/python3.6/site-packages/django/core/handlers/exception.py", line 34, in inner
    response = get_response(request)
  File "/home/yudashan/.virtualenvs/Django/lib/python3.6/site-packages/django/core/handlers/base.py", line 126, in _get_response
    response = self.process_exception_by_middleware(e, request)
  File "/home/yudashan/.virtualenvs/Django/lib/python3.6/site-packages/django/core/handlers/base.py", line 124, in _get_response
    response = wrapped_callback(request, *callback_args, **callback_kwargs)
  File "/home/yudashan/.virtualenvs/Django/lib/python3.6/site-packages/django/views/decorators/csrf.py", line 54, in wrapped_view
    return view_func(*args, **kwargs)
  File "/home/yudashan/.virtualenvs/Django/lib/python3.6/site-packages/django/views/generic/base.py", line 68, in view
    return self.dispatch(request, *args, **kwargs)
  File "/home/yudashan/.virtualenvs/Django/lib/python3.6/site-packages/rest_framework/views.py", line 505, in dispatch
    response = self.handle_exception(exc)
  File "/home/yudashan/.virtualenvs/Django/lib/python3.6/site-packages/rest_framework/views.py", line 465, in handle_exception
    self.raise_uncaught_exception(exc)
  File "/home/yudashan/.virtualenvs/Django/lib/python3.6/site-packages/rest_framework/views.py", line 476, in raise_uncaught_exception
    raise exc
  File "/home/yudashan/.virtualenvs/Django/lib/python3.6/site-packages/rest_framework/views.py", line 502, in dispatch
    response = handler(request, *args, **kwargs)
  File "/home/yudashan/Desktop/Django-project/B2C-Django-2.2/b2c_django/b2c_django/apps/users/views.py", line 15, in get
    return Response({data})
TypeError: unhashable type: 'dict'
ERROR 2020-03-19 17:04:54,849 basehttp 154 "GET /users/ HTTP/1.1" 500 97108
INFO 2020-03-19 17:05:49,930 basehttp 154 "GET /users/ HTTP/1.1" 200 5179
INFO 2020-03-19 17:05:49,964 basehttp 154 "GET /static/rest_framework/css/bootstrap-tweaks.css HTTP/1.1" 200 3385
INFO 2020-03-19 17:05:49,965 basehttp 154 "GET /static/rest_framework/css/prettify.css HTTP/1.1" 200 817
INFO 2020-03-19 17:05:49,970 basehttp 154 "GET /static/rest_framework/js/ajax-form.js HTTP/1.1" 200 3597
INFO 2020-03-19 17:05:49,974 basehttp 154 "GET /static/rest_framework/js/csrf.js HTTP/1.1" 200 1719
INFO 2020-03-19 17:05:49,976 basehttp 154 "GET /static/rest_framework/css/default.css HTTP/1.1" 200 1131
INFO 2020-03-19 17:05:49,988 basehttp 154 "GET /static/rest_framework/js/prettify-min.js HTTP/1.1" 200 13632
INFO 2020-03-19 17:05:49,991 basehttp 154 "GET /static/rest_framework/js/default.js HTTP/1.1" 200 1268
INFO 2020-03-19 17:05:49,992 basehttp 154 "GET /static/rest_framework/js/bootstrap.min.js HTTP/1.1" 200 39680
INFO 2020-03-19 17:05:49,992 basehttp 154 "GET /static/rest_framework/css/bootstrap.min.css HTTP/1.1" 200 121457
INFO 2020-03-19 17:05:49,993 basehttp 154 "GET /static/rest_framework/js/jquery-3.4.1.min.js HTTP/1.1" 200 88145
INFO 2020-03-19 17:05:50,089 basehttp 154 "GET /static/rest_framework/img/grid.png HTTP/1.1" 200 1458
WARNING 2020-03-19 17:06:11,682 log 228 Not Found: /
WARNING 2020-03-19 17:06:11,682 basehttp 154 "GET / HTTP/1.1" 404 2079
WARNING 2020-03-20 14:35:01,510 log 228 Not Found: /
WARNING 2020-03-20 14:35:01,531 basehttp 154 "GET / HTTP/1.1" 404 2079
WARNING 2020-03-20 14:35:03,089 log 228 Not Found: /favicon.ico
WARNING 2020-03-20 14:35:03,089 basehttp 154 "GET /favicon.ico HTTP/1.1" 404 2130
WARNING 2020-03-20 14:35:27,692 log 228 Not Found: /user
WARNING 2020-03-20 14:35:27,693 basehttp 154 "GET /user HTTP/1.1" 404 2109
WARNING 2020-03-20 14:35:32,774 log 228 Not Found: /user/
WARNING 2020-03-20 14:35:32,775 basehttp 154 "GET /user/ HTTP/1.1" 404 2112
INFO 2020-03-20 14:36:11,454 basehttp 154 "GET /users/ HTTP/1.1" 200 5179
INFO 2020-03-20 14:36:11,473 basehttp 154 "GET /static/rest_framework/css/bootstrap.min.css HTTP/1.1" 304 0
INFO 2020-03-20 14:36:11,474 basehttp 154 "GET /static/rest_framework/css/bootstrap-tweaks.css HTTP/1.1" 304 0
INFO 2020-03-20 14:36:11,474 basehttp 154 "GET /static/rest_framework/css/prettify.css HTTP/1.1" 304 0
INFO 2020-03-20 14:36:11,484 basehttp 154 "GET /static/rest_framework/css/default.css HTTP/1.1" 304 0
INFO 2020-03-20 14:36:11,485 basehttp 154 "GET /static/rest_framework/js/bootstrap.min.js HTTP/1.1" 304 0
INFO 2020-03-20 14:36:11,488 basehttp 154 "GET /static/rest_framework/js/csrf.js HTTP/1.1" 304 0
INFO 2020-03-20 14:36:11,489 basehttp 154 "GET /static/rest_framework/js/prettify-min.js HTTP/1.1" 304 0
INFO 2020-03-20 14:36:11,497 basehttp 154 "GET /static/rest_framework/js/jquery-3.4.1.min.js HTTP/1.1" 304 0
INFO 2020-03-20 14:36:11,491 basehttp 154 "GET /static/rest_framework/js/default.js HTTP/1.1" 304 0
INFO 2020-03-20 14:36:11,498 basehttp 154 "GET /static/rest_framework/js/ajax-form.js HTTP/1.1" 304 0
INFO 2020-03-20 14:36:11,502 basehttp 154 "GET /static/rest_framework/img/grid.png HTTP/1.1" 304 0
WARNING 2020-03-20 15:24:32,398 log 228 Not Found: /
WARNING 2020-03-20 15:24:32,398 basehttp 154 "GET / HTTP/1.1" 404 2074
INFO 2020-03-20 15:26:21,066 basehttp 154 "GET /users/ HTTP/1.1" 200 5179
WARNING 2020-03-20 15:26:48,648 log 228 Not Found: /
WARNING 2020-03-20 15:26:48,649 basehttp 154 "GET / HTTP/1.1" 404 2227
WARNING 2020-03-20 15:26:52,820 log 228 Not Found: /
WARNING 2020-03-20 15:26:52,820 basehttp 154 "GET / HTTP/1.1" 404 2227
WARNING 2020-03-20 15:27:25,013 log 228 Not Found: /
WARNING 2020-03-20 15:27:25,014 basehttp 154 "GET / HTTP/1.1" 404 2026
WARNING 2020-03-20 15:27:26,426 log 228 Not Found: /
WARNING 2020-03-20 15:27:26,427 basehttp 154 "GET / HTTP/1.1" 404 2026
WARNING 2020-03-20 15:27:29,097 log 228 Not Found: /
WARNING 2020-03-20 15:27:29,097 basehttp 154 "GET / HTTP/1.1" 404 2026
WARNING 2020-03-20 15:28:18,576 log 228 Not Found: /
WARNING 2020-03-20 15:28:18,577 basehttp 154 "GET / HTTP/1.1" 404 2026
WARNING 2020-03-20 15:28:19,689 log 228 Not Found: /
WARNING 2020-03-20 15:28:19,690 basehttp 154 "GET / HTTP/1.1" 404 2026
WARNING 2020-03-20 15:28:19,907 log 228 Not Found: /
WARNING 2020-03-20 15:28:19,907 basehttp 154 "GET / HTTP/1.1" 404 2026
WARNING 2020-03-20 15:28:58,033 log 228 Not Found: /
WARNING 2020-03-20 15:28:58,033 basehttp 154 "GET / HTTP/1.1" 404 2026
WARNING 2020-03-20 15:28:58,833 log 228 Not Found: /
WARNING 2020-03-20 15:28:58,833 basehttp 154 "GET / HTTP/1.1" 404 2026
WARNING 2020-03-20 15:28:59,064 log 228 Not Found: /
WARNING 2020-03-20 15:28:59,064 basehttp 154 "GET / HTTP/1.1" 404 2026
WARNING 2020-03-20 15:28:59,304 log 228 Not Found: /
WARNING 2020-03-20 15:28:59,304 basehttp 154 "GET / HTTP/1.1" 404 2026
WARNING 2020-03-20 15:38:04,534 log 228 Not Found: /
WARNING 2020-03-20 15:38:04,534 basehttp 154 "GET / HTTP/1.1" 404 2079
INFO 2020-03-20 15:38:09,738 basehttp 154 "GET /users/ HTTP/1.1" 200 5179
WARNING 2020-03-20 15:39:06,185 log 228 Not Found: /
WARNING 2020-03-20 15:39:06,186 basehttp 154 "GET / HTTP/1.1" 404 2074
WARNING 2020-03-20 15:39:28,484 log 228 Not Found: /
WARNING 2020-03-20 15:39:28,484 basehttp 154 "GET / HTTP/1.1" 404 2073
WARNING 2020-03-20 15:40:46,153 log 228 Not Found: /
WARNING 2020-03-20 15:40:46,154 basehttp 154 "GET / HTTP/1.1" 404 2074
WARNING 2020-03-20 15:41:45,875 log 228 Not Found: /
WARNING 2020-03-20 15:41:45,875 basehttp 154 "GET / HTTP/1.1" 404 2073
INFO 2020-03-20 15:42:07,701 basehttp 154 "GET / HTTP/1.1" 200 5143
INFO 2020-03-20 15:42:47,898 basehttp 154 "GET / HTTP/1.1" 200 5143
INFO 2020-03-20 15:42:52,783 basehttp 154 "GET /users/ HTTP/1.1" 200 5179
INFO 2020-03-20 15:44:01,607 basehttp 154 "GET /users/ HTTP/1.1" 200 5179
WARNING 2020-03-22 10:26:36,143 log 228 Method Not Allowed: /
WARNING 2020-03-22 10:26:36,144 basehttp 154 "GET / HTTP/1.1" 405 3902
INFO 2020-03-22 10:26:36,292 basehttp 154 "GET /static/rest_framework/css/bootstrap-tweaks.css HTTP/1.1" 304 0
INFO 2020-03-22 10:26:36,293 basehttp 154 "GET /static/rest_framework/css/bootstrap.min.css HTTP/1.1" 304 0
INFO 2020-03-22 10:26:36,302 basehttp 154 "GET /static/rest_framework/js/jquery-3.4.1.min.js HTTP/1.1" 304 0
INFO 2020-03-22 10:26:36,306 basehttp 154 "GET /static/rest_framework/css/default.css HTTP/1.1" 304 0
INFO 2020-03-22 10:26:36,312 basehttp 154 "GET /static/rest_framework/js/csrf.js HTTP/1.1" 304 0
INFO 2020-03-22 10:26:36,312 basehttp 154 "GET /static/rest_framework/js/prettify-min.js HTTP/1.1" 304 0
INFO 2020-03-22 10:26:36,314 basehttp 154 "GET /static/rest_framework/css/prettify.css HTTP/1.1" 304 0
INFO 2020-03-22 10:26:36,321 basehttp 154 "GET /static/rest_framework/js/ajax-form.js HTTP/1.1" 304 0
INFO 2020-03-22 10:26:36,326 basehttp 154 "GET /static/rest_framework/js/bootstrap.min.js HTTP/1.1" 304 0
INFO 2020-03-22 10:26:36,334 basehttp 154 "GET /static/rest_framework/js/default.js HTTP/1.1" 304 0
INFO 2020-03-22 10:26:36,444 basehttp 154 "GET /static/rest_framework/img/grid.png HTTP/1.1" 304 0
WARNING 2020-03-22 10:26:36,632 log 228 Method Not Allowed: /favicon.ico
WARNING 2020-03-22 10:26:36,632 basehttp 154 "GET /favicon.ico HTTP/1.1" 405 45
WARNING 2020-03-22 11:13:18,664 log 228 Method Not Allowed: /
WARNING 2020-03-22 11:13:18,667 basehttp 154 "GET / HTTP/1.1" 405 3902
WARNING 2020-03-22 11:13:18,923 log 228 Method Not Allowed: /favicon.ico
WARNING 2020-03-22 11:13:18,923 basehttp 154 "GET /favicon.ico HTTP/1.1" 405 45
ERROR 2020-03-22 11:17:48,271 exception 77 Invalid HTTP_HOST header: '192.168.137.11:8000'. You may need to add '192.168.137.11' to ALLOWED_HOSTS.
WARNING 2020-03-22 11:17:48,356 log 228 Bad Request: /
WARNING 2020-03-22 11:18:03,437 basehttp 154 "GET / HTTP/1.1" 400 71114
WARNING 2020-03-22 11:21:36,332 log 228 Method Not Allowed: /
WARNING 2020-03-22 11:21:49,581 basehttp 154 "GET / HTTP/1.1" 405 45
WARNING 2020-03-22 11:22:04,000 log 228 Method Not Allowed: /
WARNING 2020-03-22 11:22:04,001 basehttp 154 "GET / HTTP/1.1" 405 3902
INFO 2020-03-22 11:22:04,029 basehttp 154 "GET /static/rest_framework/css/bootstrap.min.css HTTP/1.1" 200 121457
INFO 2020-03-22 11:22:04,045 basehttp 154 "GET /static/rest_framework/css/bootstrap-tweaks.css HTTP/1.1" 200 3385
INFO 2020-03-22 11:22:04,046 basehttp 154 "GET /static/rest_framework/js/ajax-form.js HTTP/1.1" 200 3597
INFO 2020-03-22 11:22:04,049 basehttp 154 "GET /static/rest_framework/js/csrf.js HTTP/1.1" 200 1719
INFO 2020-03-22 11:22:04,051 basehttp 154 "GET /static/rest_framework/css/default.css HTTP/1.1" 200 1131
INFO 2020-03-22 11:22:04,060 basehttp 154 "GET /static/rest_framework/js/bootstrap.min.js HTTP/1.1" 200 39680
INFO 2020-03-22 11:22:04,060 basehttp 154 "GET /static/rest_framework/js/jquery-3.4.1.min.js HTTP/1.1" 200 88145
INFO 2020-03-22 11:22:04,064 basehttp 154 "GET /static/rest_framework/js/default.js HTTP/1.1" 200 1268
INFO 2020-03-22 11:22:04,065 basehttp 154 "GET /static/rest_framework/js/prettify-min.js HTTP/1.1" 200 13632
INFO 2020-03-22 11:22:04,066 basehttp 154 "GET /static/rest_framework/css/prettify.css HTTP/1.1" 200 817
INFO 2020-03-22 11:22:04,084 basehttp 154 "GET /static/rest_framework/img/grid.png HTTP/1.1" 200 1458
WARNING 2020-03-22 11:22:04,205 log 228 Method Not Allowed: /favicon.ico
WARNING 2020-03-22 11:22:04,206 basehttp 154 "GET /favicon.ico HTTP/1.1" 405 45
WARNING 2020-03-23 17:21:03,294 log 228 Method Not Allowed: /users/
WARNING 2020-03-23 17:21:03,295 basehttp 154 "GET /users/ HTTP/1.1" 405 3920
INFO 2020-03-23 17:21:03,348 basehttp 154 "GET /static/rest_framework/css/bootstrap-tweaks.css HTTP/1.1" 304 0
INFO 2020-03-23 17:21:03,353 basehttp 154 "GET /static/rest_framework/css/prettify.css HTTP/1.1" 304 0
INFO 2020-03-23 17:21:03,354 basehttp 154 "GET /static/rest_framework/js/csrf.js HTTP/1.1" 304 0
INFO 2020-03-23 17:21:03,355 basehttp 154 "GET /static/rest_framework/css/bootstrap.min.css HTTP/1.1" 304 0
INFO 2020-03-23 17:21:03,358 basehttp 154 "GET /static/rest_framework/js/bootstrap.min.js HTTP/1.1" 304 0
INFO 2020-03-23 17:21:03,359 basehttp 154 "GET /static/rest_framework/css/default.css HTTP/1.1" 304 0
INFO 2020-03-23 17:21:03,363 basehttp 154 "GET /static/rest_framework/js/prettify-min.js HTTP/1.1" 304 0
INFO 2020-03-23 17:21:03,364 basehttp 154 "GET /static/rest_framework/js/jquery-3.4.1.min.js HTTP/1.1" 304 0
INFO 2020-03-23 17:21:03,370 basehttp 154 "GET /static/rest_framework/js/default.js HTTP/1.1" 304 0
INFO 2020-03-23 17:21:03,373 basehttp 154 "GET /static/rest_framework/js/ajax-form.js HTTP/1.1" 304 0
INFO 2020-03-23 17:21:03,432 basehttp 154 "GET /static/rest_framework/img/grid.png HTTP/1.1" 304 0
WARNING 2020-03-23 17:21:03,564 log 228 Method Not Allowed: /favicon.ico
WARNING 2020-03-23 17:21:03,564 basehttp 154 "GET /favicon.ico HTTP/1.1" 405 45
WARNING 2020-03-23 17:21:21,952 log 228 Method Not Allowed: /users/beijung/7579
WARNING 2020-03-23 17:21:21,953 basehttp 154 "GET /users/beijung/7579 HTTP/1.1" 405 3956
WARNING 2020-03-23 17:21:22,064 log 228 Method Not Allowed: /favicon.ico
WARNING 2020-03-23 17:21:22,064 basehttp 154 "GET /favicon.ico HTTP/1.1" 405 45
WARNING 2020-03-23 17:22:53,204 log 228 Method Not Allowed: /sms/beijung/7579
WARNING 2020-03-23 17:22:53,204 basehttp 154 "GET /sms/beijung/7579 HTTP/1.1" 405 3950
WARNING 2020-03-23 17:22:53,431 log 228 Method Not Allowed: /favicon.ico
WARNING 2020-03-23 17:22:53,431 basehttp 154 "GET /favicon.ico HTTP/1.1" 405 45
WARNING 2020-03-23 17:25:33,216 log 228 Method Not Allowed: /sms/beijung/7579
WARNING 2020-03-23 17:25:33,216 basehttp 154 "GET /sms/beijung/7579 HTTP/1.1" 405 3950
WARNING 2020-03-23 17:25:33,342 log 228 Method Not Allowed: /favicon.ico
WARNING 2020-03-23 17:25:33,343 basehttp 154 "GET /favicon.ico HTTP/1.1" 405 45
INFO 2020-03-23 17:25:36,980 basehttp 154 "OPTIONS /sms/beijung/7579 HTTP/1.1" 200 4219
INFO 2020-03-23 17:25:42,241 basehttp 154 "OPTIONS /sms/beijung/7579 HTTP/1.1" 200 4219
INFO 2020-03-23 17:25:43,307 basehttp 154 "OPTIONS /sms/beijung/7579 HTTP/1.1" 200 4219
WARNING 2020-03-23 17:25:46,580 log 228 Method Not Allowed: /sms/beijung/7579
WARNING 2020-03-23 17:25:46,580 basehttp 154 "GET /sms/beijung/7579 HTTP/1.1" 405 3950
WARNING 2020-03-23 17:25:46,629 log 228 Method Not Allowed: /favicon.ico
WARNING 2020-03-23 17:25:46,630 basehttp 154 "GET /favicon.ico HTTP/1.1" 405 45
INFO 2020-03-23 17:29:24,699 basehttp 154 "OPTIONS /sms/beijung/7579 HTTP/1.1" 200 4219
ERROR 2020-03-23 17:33:03,717 log 228 Internal Server Error: /users/
Traceback (most recent call last):
  File "/home/yudashan/.virtualenvs/Django/lib/python3.6/site-packages/django/core/handlers/exception.py", line 34, in inner
    response = get_response(request)
  File "/home/yudashan/.virtualenvs/Django/lib/python3.6/site-packages/django/core/handlers/base.py", line 126, in _get_response
    response = self.process_exception_by_middleware(e, request)
  File "/home/yudashan/.virtualenvs/Django/lib/python3.6/site-packages/django/core/handlers/base.py", line 124, in _get_response
    response = wrapped_callback(request, *callback_args, **callback_kwargs)
  File "/home/yudashan/.virtualenvs/Django/lib/python3.6/site-packages/django/views/decorators/csrf.py", line 54, in wrapped_view
    return view_func(*args, **kwargs)
  File "/home/yudashan/.virtualenvs/Django/lib/python3.6/site-packages/django/views/generic/base.py", line 68, in view
    return self.dispatch(request, *args, **kwargs)
  File "/home/yudashan/.virtualenvs/Django/lib/python3.6/site-packages/rest_framework/views.py", line 507, in dispatch
    self.response = self.finalize_response(request, response, *args, **kwargs)
  File "/home/yudashan/.virtualenvs/Django/lib/python3.6/site-packages/rest_framework/views.py", line 422, in finalize_response
    % type(response)
AssertionError: Expected a `Response`, `HttpResponse` or `HttpStreamingResponse` to be returned from the view, but received a `<class 'NoneType'>`
ERROR 2020-03-23 17:33:03,718 basehttp 154 "GET /users/ HTTP/1.1" 500 86630
ERROR 2020-03-23 17:33:03,912 log 228 Internal Server Error: /favicon.ico
Traceback (most recent call last):
  File "/home/yudashan/.virtualenvs/Django/lib/python3.6/site-packages/django/core/handlers/exception.py", line 34, in inner
    response = get_response(request)
  File "/home/yudashan/.virtualenvs/Django/lib/python3.6/site-packages/django/core/handlers/base.py", line 126, in _get_response
    response = self.process_exception_by_middleware(e, request)
  File "/home/yudashan/.virtualenvs/Django/lib/python3.6/site-packages/django/core/handlers/base.py", line 124, in _get_response
    response = wrapped_callback(request, *callback_args, **callback_kwargs)
  File "/home/yudashan/.virtualenvs/Django/lib/python3.6/site-packages/django/views/decorators/csrf.py", line 54, in wrapped_view
    return view_func(*args, **kwargs)
  File "/home/yudashan/.virtualenvs/Django/lib/python3.6/site-packages/django/views/generic/base.py", line 68, in view
    return self.dispatch(request, *args, **kwargs)
  File "/home/yudashan/.virtualenvs/Django/lib/python3.6/site-packages/rest_framework/views.py", line 507, in dispatch
    self.response = self.finalize_response(request, response, *args, **kwargs)
  File "/home/yudashan/.virtualenvs/Django/lib/python3.6/site-packages/rest_framework/views.py", line 422, in finalize_response
    % type(response)
AssertionError: Expected a `Response`, `HttpResponse` or `HttpStreamingResponse` to be returned from the view, but received a `<class 'NoneType'>`
ERROR 2020-03-23 17:33:03,913 basehttp 154 "GET /favicon.ico HTTP/1.1" 500 86497
INFO 2020-03-23 17:34:35,128 basehttp 154 "GET /users/ HTTP/1.1" 200 5121
INFO 2020-03-23 17:34:35,349 basehttp 154 "GET /favicon.ico HTTP/1.1" 200 4
INFO 2020-03-23 17:34:46,193 basehttp 154 "GET /sms/beijung/7579 HTTP/1.1" 200 5181
INFO 2020-03-23 17:34:46,253 basehttp 154 "GET /favicon.ico HTTP/1.1" 200 4
INFO 2020-03-23 17:35:09,619 basehttp 154 "GET /sms/beijung/7579 HTTP/1.1" 200 5181
INFO 2020-03-23 17:35:09,687 basehttp 154 "GET /favicon.ico HTTP/1.1" 200 4
INFO 2020-03-23 17:36:05,887 basehttp 154 "GET /sms/beijing/7579 HTTP/1.1" 200 5181
INFO 2020-03-23 17:36:05,949 basehttp 154 "GET /favicon.ico HTTP/1.1" 200 4
INFO 2020-03-23 17:36:34,153 basehttp 154 "GET /sms/beijing/7579 HTTP/1.1" 200 5181
INFO 2020-03-23 17:36:34,303 basehttp 154 "GET /favicon.ico HTTP/1.1" 200 4
INFO 2020-03-23 17:38:54,371 basehttp 154 "GET /sms/beijing/7579 HTTP/1.1" 301 0
INFO 2020-03-23 17:39:10,401 basehttp 154 "GET /sms/beijing/7579/ HTTP/1.1" 200 5215
WARNING 2020-03-23 17:39:10,477 log 228 Not Found: /favicon.ico
WARNING 2020-03-23 17:39:10,478 basehttp 154 "GET /favicon.ico HTTP/1.1" 404 2303
WARNING 2020-03-23 17:39:27,899 log 228 Not Found: /
WARNING 2020-03-23 17:39:27,900 basehttp 154 "GET / HTTP/1.1" 404 2252
ERROR 2020-03-23 21:16:15,989 log 228 Internal Server Error: /sms/
Traceback (most recent call last):
  File "/home/yudashan/.virtualenvs/Django/lib/python3.6/site-packages/django/core/handlers/exception.py", line 34, in inner
    response = get_response(request)
  File "/home/yudashan/.virtualenvs/Django/lib/python3.6/site-packages/django/utils/deprecation.py", line 90, in __call__
    response = self.process_request(request)
  File "/home/yudashan/.virtualenvs/Django/lib/python3.6/site-packages/django/contrib/sessions/middleware.py", line 20, in process_request
    request.session = self.SessionStore(session_key)
  File "/home/yudashan/.virtualenvs/Django/lib/python3.6/site-packages/django/contrib/sessions/backends/cache.py", line 17, in __init__
    self._cache = caches[settings.SESSION_CACHE_ALIAS]
  File "/home/yudashan/.virtualenvs/Django/lib/python3.6/site-packages/django/core/cache/__init__.py", line 76, in __getitem__
    "Could not find config for '%s' in settings.CACHES" % alias
django.core.cache.backends.base.InvalidCacheBackendError: Could not find config for 'session' in settings.CACHES
ERROR 2020-03-23 21:16:27,367 basehttp 154 "GET /sms/?mobile HTTP/1.1" 500 75207
ERROR 2020-03-23 21:18:13,672 log 228 Internal Server Error: /sms/
Traceback (most recent call last):
  File "/home/yudashan/.virtualenvs/Django/lib/python3.6/site-packages/django/core/handlers/exception.py", line 34, in inner
    response = get_response(request)
  File "/home/yudashan/.virtualenvs/Django/lib/python3.6/site-packages/django/utils/deprecation.py", line 90, in __call__
    response = self.process_request(request)
  File "/home/yudashan/.virtualenvs/Django/lib/python3.6/site-packages/django/contrib/sessions/middleware.py", line 20, in process_request
    request.session = self.SessionStore(session_key)
  File "/home/yudashan/.virtualenvs/Django/lib/python3.6/site-packages/django/contrib/sessions/backends/cache.py", line 17, in __init__
    self._cache = caches[settings.SESSION_CACHE_ALIAS]
  File "/home/yudashan/.virtualenvs/Django/lib/python3.6/site-packages/django/core/cache/__init__.py", line 76, in __getitem__
    "Could not find config for '%s' in settings.CACHES" % alias
django.core.cache.backends.base.InvalidCacheBackendError: Could not find config for 'session' in settings.CACHES
ERROR 2020-03-23 21:18:22,101 basehttp 154 "GET /sms/?mobile HTTP/1.1" 500 75205
ERROR 2020-03-23 21:30:51,169 log 228 Internal Server Error: /sms/
Traceback (most recent call last):
  File "/home/yudashan/.virtualenvs/Django/lib/python3.6/site-packages/django/core/handlers/exception.py", line 34, in inner
    response = get_response(request)
  File "/home/yudashan/.virtualenvs/Django/lib/python3.6/site-packages/django/core/handlers/base.py", line 126, in _get_response
    response = self.process_exception_by_middleware(e, request)
  File "/home/yudashan/.virtualenvs/Django/lib/python3.6/site-packages/django/core/handlers/base.py", line 124, in _get_response
    response = wrapped_callback(request, *callback_args, **callback_kwargs)
  File "/home/yudashan/.virtualenvs/Django/lib/python3.6/site-packages/django/views/decorators/csrf.py", line 54, in wrapped_view
    return view_func(*args, **kwargs)
  File "/home/yudashan/.virtualenvs/Django/lib/python3.6/site-packages/django/views/generic/base.py", line 68, in view
    return self.dispatch(request, *args, **kwargs)
  File "/home/yudashan/.virtualenvs/Django/lib/python3.6/site-packages/rest_framework/views.py", line 505, in dispatch
    response = self.handle_exception(exc)
  File "/home/yudashan/.virtualenvs/Django/lib/python3.6/site-packages/rest_framework/views.py", line 465, in handle_exception
    self.raise_uncaught_exception(exc)
  File "/home/yudashan/.virtualenvs/Django/lib/python3.6/site-packages/rest_framework/views.py", line 476, in raise_uncaught_exception
    raise exc
  File "/home/yudashan/.virtualenvs/Django/lib/python3.6/site-packages/rest_framework/views.py", line 502, in dispatch
    response = handler(request, *args, **kwargs)
  File "/home/yudashan/Desktop/Django-project/DRFBlog-2.2/Blog_project/Blog_project/apps/users/views.py", line 18, in get
    mobile = request.query_params("mobile")
TypeError: 'QueryDict' object is not callable
ERROR 2020-03-23 21:30:59,632 basehttp 154 "GET /sms/?mobile HTTP/1.1" 500 19439
ERROR 2020-03-23 21:32:41,772 log 228 Internal Server Error: /sms/
Traceback (most recent call last):
  File "/home/yudashan/.virtualenvs/Django/lib/python3.6/site-packages/django/core/handlers/exception.py", line 34, in inner
    response = get_response(request)
  File "/home/yudashan/.virtualenvs/Django/lib/python3.6/site-packages/django/core/handlers/base.py", line 126, in _get_response
    response = self.process_exception_by_middleware(e, request)
  File "/home/yudashan/.virtualenvs/Django/lib/python3.6/site-packages/django/core/handlers/base.py", line 124, in _get_response
    response = wrapped_callback(request, *callback_args, **callback_kwargs)
  File "/home/yudashan/.virtualenvs/Django/lib/python3.6/site-packages/django/views/decorators/csrf.py", line 54, in wrapped_view
    return view_func(*args, **kwargs)
  File "/home/yudashan/.virtualenvs/Django/lib/python3.6/site-packages/django/views/generic/base.py", line 68, in view
    return self.dispatch(request, *args, **kwargs)
  File "/home/yudashan/.virtualenvs/Django/lib/python3.6/site-packages/rest_framework/views.py", line 505, in dispatch
    response = self.handle_exception(exc)
  File "/home/yudashan/.virtualenvs/Django/lib/python3.6/site-packages/rest_framework/views.py", line 465, in handle_exception
    self.raise_uncaught_exception(exc)
  File "/home/yudashan/.virtualenvs/Django/lib/python3.6/site-packages/rest_framework/views.py", line 476, in raise_uncaught_exception
    raise exc
  File "/home/yudashan/.virtualenvs/Django/lib/python3.6/site-packages/rest_framework/views.py", line 502, in dispatch
    response = handler(request, *args, **kwargs)
  File "/home/yudashan/Desktop/Django-project/DRFBlog-2.2/Blog_project/Blog_project/apps/users/views.py", line 18, in get
    mobile = self.request.query_params("mobile")
TypeError: 'QueryDict' object is not callable
ERROR 2020-03-23 21:32:42,203 basehttp 154 "GET /sms/?mobile HTTP/1.1" 500 19444
ERROR 2020-03-23 21:37:54,661 log 228 Internal Server Error: /sms/
Traceback (most recent call last):
  File "/home/yudashan/.virtualenvs/Django/lib/python3.6/site-packages/django/core/handlers/exception.py", line 34, in inner
    response = get_response(request)
  File "/home/yudashan/.virtualenvs/Django/lib/python3.6/site-packages/django/core/handlers/base.py", line 126, in _get_response
    response = self.process_exception_by_middleware(e, request)
  File "/home/yudashan/.virtualenvs/Django/lib/python3.6/site-packages/django/core/handlers/base.py", line 124, in _get_response
    response = wrapped_callback(request, *callback_args, **callback_kwargs)
  File "/home/yudashan/.virtualenvs/Django/lib/python3.6/site-packages/django/views/decorators/csrf.py", line 54, in wrapped_view
    return view_func(*args, **kwargs)
  File "/home/yudashan/.virtualenvs/Django/lib/python3.6/site-packages/django/views/generic/base.py", line 68, in view
    return self.dispatch(request, *args, **kwargs)
  File "/home/yudashan/.virtualenvs/Django/lib/python3.6/site-packages/rest_framework/views.py", line 505, in dispatch
    response = self.handle_exception(exc)
  File "/home/yudashan/.virtualenvs/Django/lib/python3.6/site-packages/rest_framework/views.py", line 465, in handle_exception
    self.raise_uncaught_exception(exc)
  File "/home/yudashan/.virtualenvs/Django/lib/python3.6/site-packages/rest_framework/views.py", line 476, in raise_uncaught_exception
    raise exc
  File "/home/yudashan/.virtualenvs/Django/lib/python3.6/site-packages/rest_framework/views.py", line 502, in dispatch
    response = handler(request, *args, **kwargs)
  File "/home/yudashan/Desktop/Django-project/DRFBlog-2.2/Blog_project/Blog_project/apps/users/views.py", line 20, in get
    if not re.match(r'1[3-9]\d{9}$', mobile):
  File "/home/yudashan/.virtualenvs/Django/lib/python3.6/re.py", line 172, in match
    return _compile(pattern, flags).match(string)
TypeError: expected string or bytes-like object
ERROR 2020-03-23 21:37:55,102 basehttp 154 "GET /sms/?mobile HTTP/1.1" 500 19574
ERROR 2020-03-23 21:41:23,788 log 228 Internal Server Error: /sms/
Traceback (most recent call last):
  File "/home/yudashan/.virtualenvs/Django/lib/python3.6/site-packages/django/core/handlers/exception.py", line 34, in inner
    response = get_response(request)
  File "/home/yudashan/.virtualenvs/Django/lib/python3.6/site-packages/django/core/handlers/base.py", line 126, in _get_response
    response = self.process_exception_by_middleware(e, request)
  File "/home/yudashan/.virtualenvs/Django/lib/python3.6/site-packages/django/core/handlers/base.py", line 124, in _get_response
    response = wrapped_callback(request, *callback_args, **callback_kwargs)
  File "/home/yudashan/.virtualenvs/Django/lib/python3.6/site-packages/django/views/decorators/csrf.py", line 54, in wrapped_view
    return view_func(*args, **kwargs)
  File "/home/yudashan/.virtualenvs/Django/lib/python3.6/site-packages/django/views/generic/base.py", line 68, in view
    return self.dispatch(request, *args, **kwargs)
  File "/home/yudashan/.virtualenvs/Django/lib/python3.6/site-packages/rest_framework/views.py", line 505, in dispatch
    response = self.handle_exception(exc)
  File "/home/yudashan/.virtualenvs/Django/lib/python3.6/site-packages/rest_framework/views.py", line 465, in handle_exception
    self.raise_uncaught_exception(exc)
  File "/home/yudashan/.virtualenvs/Django/lib/python3.6/site-packages/rest_framework/views.py", line 476, in raise_uncaught_exception
    raise exc
  File "/home/yudashan/.virtualenvs/Django/lib/python3.6/site-packages/rest_framework/views.py", line 502, in dispatch
    response = handler(request, *args, **kwargs)
  File "/home/yudashan/Desktop/Django-project/DRFBlog-2.2/Blog_project/Blog_project/apps/users/views.py", line 20, in get
    if not re.match(r'1[3-9]\d{9}$', mobile):
  File "/home/yudashan/.virtualenvs/Django/lib/python3.6/re.py", line 172, in match
    return _compile(pattern, flags).match(string)
TypeError: expected string or bytes-like object
ERROR 2020-03-23 21:41:24,217 basehttp 154 "GET /sms/?mobile HTTP/1.1" 500 19574
ERROR 2020-03-23 21:43:23,273 log 228 Internal Server Error: /sms/
Traceback (most recent call last):
  File "/home/yudashan/.virtualenvs/Django/lib/python3.6/site-packages/django/core/handlers/exception.py", line 34, in inner
    response = get_response(request)
  File "/home/yudashan/.virtualenvs/Django/lib/python3.6/site-packages/django/core/handlers/base.py", line 126, in _get_response
    response = self.process_exception_by_middleware(e, request)
  File "/home/yudashan/.virtualenvs/Django/lib/python3.6/site-packages/django/core/handlers/base.py", line 124, in _get_response
    response = wrapped_callback(request, *callback_args, **callback_kwargs)
  File "/home/yudashan/.virtualenvs/Django/lib/python3.6/site-packages/django/views/decorators/csrf.py", line 54, in wrapped_view
    return view_func(*args, **kwargs)
  File "/home/yudashan/.virtualenvs/Django/lib/python3.6/site-packages/django/views/generic/base.py", line 68, in view
    return self.dispatch(request, *args, **kwargs)
  File "/home/yudashan/.virtualenvs/Django/lib/python3.6/site-packages/rest_framework/views.py", line 505, in dispatch
    response = self.handle_exception(exc)
  File "/home/yudashan/.virtualenvs/Django/lib/python3.6/site-packages/rest_framework/views.py", line 465, in handle_exception
    self.raise_uncaught_exception(exc)
  File "/home/yudashan/.virtualenvs/Django/lib/python3.6/site-packages/rest_framework/views.py", line 476, in raise_uncaught_exception
    raise exc
  File "/home/yudashan/.virtualenvs/Django/lib/python3.6/site-packages/rest_framework/views.py", line 502, in dispatch
    response = handler(request, *args, **kwargs)
  File "/home/yudashan/Desktop/Django-project/DRFBlog-2.2/Blog_project/Blog_project/apps/users/views.py", line 20, in get
    if not re.match(r'1[3-9]\d{9}$', mobile):
  File "/home/yudashan/.virtualenvs/Django/lib/python3.6/re.py", line 172, in match
    return _compile(pattern, flags).match(string)
TypeError: expected string or bytes-like object
ERROR 2020-03-23 21:43:23,274 basehttp 154 "GET /sms/?mobile HTTP/1.1" 500 19568
INFO 2020-03-23 21:43:33,653 basehttp 154 "GET /sms?mobile=18638626525 HTTP/1.1" 301 0
ERROR 2020-03-23 21:43:33,712 log 228 Internal Server Error: /sms/
Traceback (most recent call last):
  File "/home/yudashan/.virtualenvs/Django/lib/python3.6/site-packages/django/core/handlers/exception.py", line 34, in inner
    response = get_response(request)
  File "/home/yudashan/.virtualenvs/Django/lib/python3.6/site-packages/django/core/handlers/base.py", line 126, in _get_response
    response = self.process_exception_by_middleware(e, request)
  File "/home/yudashan/.virtualenvs/Django/lib/python3.6/site-packages/django/core/handlers/base.py", line 124, in _get_response
    response = wrapped_callback(request, *callback_args, **callback_kwargs)
  File "/home/yudashan/.virtualenvs/Django/lib/python3.6/site-packages/django/views/decorators/csrf.py", line 54, in wrapped_view
    return view_func(*args, **kwargs)
  File "/home/yudashan/.virtualenvs/Django/lib/python3.6/site-packages/django/views/generic/base.py", line 68, in view
    return self.dispatch(request, *args, **kwargs)
  File "/home/yudashan/.virtualenvs/Django/lib/python3.6/site-packages/rest_framework/views.py", line 505, in dispatch
    response = self.handle_exception(exc)
  File "/home/yudashan/.virtualenvs/Django/lib/python3.6/site-packages/rest_framework/views.py", line 465, in handle_exception
    self.raise_uncaught_exception(exc)
  File "/home/yudashan/.virtualenvs/Django/lib/python3.6/site-packages/rest_framework/views.py", line 476, in raise_uncaught_exception
    raise exc
  File "/home/yudashan/.virtualenvs/Django/lib/python3.6/site-packages/rest_framework/views.py", line 502, in dispatch
    response = handler(request, *args, **kwargs)
  File "/home/yudashan/Desktop/Django-project/DRFBlog-2.2/Blog_project/Blog_project/apps/users/views.py", line 20, in get
    if not re.match(r'1[3-9]\d{9}$', mobile):
  File "/home/yudashan/.virtualenvs/Django/lib/python3.6/re.py", line 172, in match
    return _compile(pattern, flags).match(string)
TypeError: expected string or bytes-like object
ERROR 2020-03-23 21:43:33,715 basehttp 154 "GET /sms/?mobile=18638626525 HTTP/1.1" 500 19599
INFO 2020-03-23 21:43:59,448 basehttp 154 "GET /sms?mobile=18638626525 HTTP/1.1" 301 0
ERROR 2020-03-23 21:43:59,538 log 228 Internal Server Error: /sms/
Traceback (most recent call last):
  File "/home/yudashan/.virtualenvs/Django/lib/python3.6/site-packages/django/core/handlers/exception.py", line 34, in inner
    response = get_response(request)
  File "/home/yudashan/.virtualenvs/Django/lib/python3.6/site-packages/django/core/handlers/base.py", line 126, in _get_response
    response = self.process_exception_by_middleware(e, request)
  File "/home/yudashan/.virtualenvs/Django/lib/python3.6/site-packages/django/core/handlers/base.py", line 124, in _get_response
    response = wrapped_callback(request, *callback_args, **callback_kwargs)
  File "/home/yudashan/.virtualenvs/Django/lib/python3.6/site-packages/django/views/decorators/csrf.py", line 54, in wrapped_view
    return view_func(*args, **kwargs)
  File "/home/yudashan/.virtualenvs/Django/lib/python3.6/site-packages/django/views/generic/base.py", line 68, in view
    return self.dispatch(request, *args, **kwargs)
  File "/home/yudashan/.virtualenvs/Django/lib/python3.6/site-packages/rest_framework/views.py", line 505, in dispatch
    response = self.handle_exception(exc)
  File "/home/yudashan/.virtualenvs/Django/lib/python3.6/site-packages/rest_framework/views.py", line 465, in handle_exception
    self.raise_uncaught_exception(exc)
  File "/home/yudashan/.virtualenvs/Django/lib/python3.6/site-packages/rest_framework/views.py", line 476, in raise_uncaught_exception
    raise exc
  File "/home/yudashan/.virtualenvs/Django/lib/python3.6/site-packages/rest_framework/views.py", line 502, in dispatch
    response = handler(request, *args, **kwargs)
  File "/home/yudashan/Desktop/Django-project/DRFBlog-2.2/Blog_project/Blog_project/apps/users/views.py", line 20, in get
    if not re.match(r'1[3-9]\d{9}$', mobile):
  File "/home/yudashan/.virtualenvs/Django/lib/python3.6/re.py", line 172, in match
    return _compile(pattern, flags).match(string)
TypeError: expected string or bytes-like object
ERROR 2020-03-23 21:43:59,540 basehttp 154 "GET /sms/?mobile=18638626525 HTTP/1.1" 500 19599
INFO 2020-03-23 21:45:28,917 basehttp 154 "GET /sms?mobile=18638626525 HTTP/1.1" 301 0
INFO 2020-03-23 21:45:28,962 basehttp 154 "GET /sms/?mobile=18638626525 HTTP/1.1" 200 4
INFO 2020-03-23 21:47:01,530 basehttp 154 "GET /sms?mobile=18638626525 HTTP/1.1" 301 0
ERROR 2020-03-23 21:47:01,615 log 228 Internal Server Error: /sms/
Traceback (most recent call last):
  File "/home/yudashan/.virtualenvs/Django/lib/python3.6/site-packages/django/core/handlers/exception.py", line 34, in inner
    response = get_response(request)
  File "/home/yudashan/.virtualenvs/Django/lib/python3.6/site-packages/django/core/handlers/base.py", line 126, in _get_response
    response = self.process_exception_by_middleware(e, request)
  File "/home/yudashan/.virtualenvs/Django/lib/python3.6/site-packages/django/core/handlers/base.py", line 124, in _get_response
    response = wrapped_callback(request, *callback_args, **callback_kwargs)
  File "/home/yudashan/.virtualenvs/Django/lib/python3.6/site-packages/django/views/decorators/csrf.py", line 54, in wrapped_view
    return view_func(*args, **kwargs)
  File "/home/yudashan/.virtualenvs/Django/lib/python3.6/site-packages/django/views/generic/base.py", line 68, in view
    return self.dispatch(request, *args, **kwargs)
  File "/home/yudashan/.virtualenvs/Django/lib/python3.6/site-packages/rest_framework/views.py", line 505, in dispatch
    response = self.handle_exception(exc)
  File "/home/yudashan/.virtualenvs/Django/lib/python3.6/site-packages/rest_framework/views.py", line 465, in handle_exception
    self.raise_uncaught_exception(exc)
  File "/home/yudashan/.virtualenvs/Django/lib/python3.6/site-packages/rest_framework/views.py", line 476, in raise_uncaught_exception
    raise exc
  File "/home/yudashan/.virtualenvs/Django/lib/python3.6/site-packages/rest_framework/views.py", line 502, in dispatch
    response = handler(request, *args, **kwargs)
  File "/home/yudashan/Desktop/Django-project/DRFBlog-2.2/Blog_project/Blog_project/apps/users/views.py", line 23, in get
    sms_code = "%06d" % random.randint(0, 999999)
AttributeError: 'builtin_function_or_method' object has no attribute 'randint'
ERROR 2020-03-23 21:47:01,618 basehttp 154 "GET /sms/?mobile=18638626525 HTTP/1.1" 500 19540
INFO 2020-03-23 21:49:26,303 basehttp 154 "GET /sms?mobile=18638626525 HTTP/1.1" 301 0
ERROR 2020-03-23 21:49:26,383 log 228 Internal Server Error: /sms/
Traceback (most recent call last):
  File "/home/yudashan/.virtualenvs/Django/lib/python3.6/site-packages/django/core/handlers/exception.py", line 34, in inner
    response = get_response(request)
  File "/home/yudashan/.virtualenvs/Django/lib/python3.6/site-packages/django/core/handlers/base.py", line 126, in _get_response
    response = self.process_exception_by_middleware(e, request)
  File "/home/yudashan/.virtualenvs/Django/lib/python3.6/site-packages/django/core/handlers/base.py", line 124, in _get_response
    response = wrapped_callback(request, *callback_args, **callback_kwargs)
  File "/home/yudashan/.virtualenvs/Django/lib/python3.6/site-packages/django/views/decorators/csrf.py", line 54, in wrapped_view
    return view_func(*args, **kwargs)
  File "/home/yudashan/.virtualenvs/Django/lib/python3.6/site-packages/django/views/generic/base.py", line 68, in view
    return self.dispatch(request, *args, **kwargs)
  File "/home/yudashan/.virtualenvs/Django/lib/python3.6/site-packages/rest_framework/views.py", line 505, in dispatch
    response = self.handle_exception(exc)
  File "/home/yudashan/.virtualenvs/Django/lib/python3.6/site-packages/rest_framework/views.py", line 465, in handle_exception
    self.raise_uncaught_exception(exc)
  File "/home/yudashan/.virtualenvs/Django/lib/python3.6/site-packages/rest_framework/views.py", line 476, in raise_uncaught_exception
    raise exc
  File "/home/yudashan/.virtualenvs/Django/lib/python3.6/site-packages/rest_framework/views.py", line 502, in dispatch
    response = handler(request, *args, **kwargs)
  File "/home/yudashan/Desktop/Django-project/DRFBlog-2.2/Blog_project/Blog_project/apps/users/views.py", line 20, in get
    sms_code = "%06d" % random.randint(0, 999999)
AttributeError: 'builtin_function_or_method' object has no attribute 'randint'
ERROR 2020-03-23 21:49:26,386 basehttp 154 "GET /sms/?mobile=18638626525 HTTP/1.1" 500 19536
INFO 2020-03-23 21:53:15,779 basehttp 154 "GET /sms?mobile=18638626525 HTTP/1.1" 301 0
ERROR 2020-03-23 21:53:15,860 log 228 Internal Server Error: /sms/
Traceback (most recent call last):
  File "/home/yudashan/.virtualenvs/Django/lib/python3.6/site-packages/django/core/handlers/exception.py", line 34, in inner
    response = get_response(request)
  File "/home/yudashan/.virtualenvs/Django/lib/python3.6/site-packages/django/core/handlers/base.py", line 126, in _get_response
    response = self.process_exception_by_middleware(e, request)
  File "/home/yudashan/.virtualenvs/Django/lib/python3.6/site-packages/django/core/handlers/base.py", line 124, in _get_response
    response = wrapped_callback(request, *callback_args, **callback_kwargs)
  File "/home/yudashan/.virtualenvs/Django/lib/python3.6/site-packages/django/views/decorators/csrf.py", line 54, in wrapped_view
    return view_func(*args, **kwargs)
  File "/home/yudashan/.virtualenvs/Django/lib/python3.6/site-packages/django/views/generic/base.py", line 68, in view
    return self.dispatch(request, *args, **kwargs)
  File "/home/yudashan/.virtualenvs/Django/lib/python3.6/site-packages/rest_framework/views.py", line 505, in dispatch
    response = self.handle_exception(exc)
  File "/home/yudashan/.virtualenvs/Django/lib/python3.6/site-packages/rest_framework/views.py", line 465, in handle_exception
    self.raise_uncaught_exception(exc)
  File "/home/yudashan/.virtualenvs/Django/lib/python3.6/site-packages/rest_framework/views.py", line 476, in raise_uncaught_exception
    raise exc
  File "/home/yudashan/.virtualenvs/Django/lib/python3.6/site-packages/rest_framework/views.py", line 502, in dispatch
    response = handler(request, *args, **kwargs)
  File "/home/yudashan/Desktop/Django-project/DRFBlog-2.2/Blog_project/Blog_project/apps/users/views.py", line 26, in get
    redis_conn = get_redis_connection("verify_codes")
  File "/home/yudashan/.virtualenvs/Django/lib/python3.6/site-packages/django_redis/__init__.py", line 12, in get_redis_connection
    cache = caches[alias]
  File "/home/yudashan/.virtualenvs/Django/lib/python3.6/site-packages/django/core/cache/__init__.py", line 76, in __getitem__
    "Could not find config for '%s' in settings.CACHES" % alias
django.core.cache.backends.base.InvalidCacheBackendError: Could not find config for 'verify_codes' in settings.CACHES
ERROR 2020-03-23 21:53:15,862 basehttp 154 "GET /sms/?mobile=18638626525 HTTP/1.1" 500 19908
INFO 2020-03-23 22:00:18,027 basehttp 154 "GET /sms?mobile=18638626525 HTTP/1.1" 301 0
ERROR 2020-03-23 22:00:18,073 exceptions 25 [<users.views.SendSMSView object at 0x7ff03d191e80>] Error 111 connecting to 127.0.0.1:6739. Connection refused.
ERROR 2020-03-23 22:00:18,074 log 228 Insufficient Storage: /sms/
ERROR 2020-03-23 22:00:18,074 basehttp 154 "GET /sms/?mobile=18638626525 HTTP/1.1" 507 35
INFO 2020-03-23 22:01:11,925 basehttp 154 "GET /sms?mobile=18638626525 HTTP/1.1" 301 0
ERROR 2020-03-23 22:01:11,969 exceptions 25 [<users.views.SendSMSView object at 0x7ff03d191828>] Error 111 connecting to 127.0.0.1:6739. Connection refused.
ERROR 2020-03-23 22:01:11,971 log 228 Insufficient Storage: /sms/
ERROR 2020-03-23 22:01:11,973 basehttp 154 "GET /sms/?mobile=18638626525 HTTP/1.1" 507 35
INFO 2020-03-23 22:01:54,496 basehttp 154 "GET /sms?mobile=18638626525 HTTP/1.1" 301 0
ERROR 2020-03-23 22:01:54,544 exceptions 25 [<users.views.SendSMSView object at 0x7f0baf06fe10>] Error 111 connecting to 127.0.0.1:6739. Connection refused.
ERROR 2020-03-23 22:01:54,546 log 228 Insufficient Storage: /sms/
ERROR 2020-03-23 22:01:54,547 basehttp 154 "GET /sms/?mobile=18638626525 HTTP/1.1" 507 35
INFO 2020-03-23 22:04:12,617 basehttp 154 "GET /sms?mobile=18638626525 HTTP/1.1" 301 0
ERROR 2020-03-23 22:04:12,663 exceptions 25 [<users.views.SendSMSView object at 0x7f6a8104ce80>] Error 111 connecting to 127.0.0.1:6739. Connection refused.
ERROR 2020-03-23 22:04:12,663 log 228 Insufficient Storage: /sms/
ERROR 2020-03-23 22:04:12,664 basehttp 154 "GET /sms/?mobile=18638626525 HTTP/1.1" 507 35
INFO 2020-03-23 22:14:49,424 basehttp 154 "GET /sms?mobile=18638626525 HTTP/1.1" 301 0
ERROR 2020-03-23 22:14:49,473 exceptions 25 [<users.views.SendSMSView object at 0x7f200597ee80>] Error 111 connecting to 127.0.0.1:6739. Connection refused.
ERROR 2020-03-23 22:14:49,474 log 228 Insufficient Storage: /sms/
ERROR 2020-03-23 22:14:49,474 basehttp 154 "GET /sms/?mobile=18638626525 HTTP/1.1" 507 35
INFO 2020-03-23 22:22:20,181 basehttp 154 "GET /sms?mobile=18638626525 HTTP/1.1" 301 0
ERROR 2020-03-23 22:22:20,232 exceptions 25 [<users.views.SendSMSView object at 0x7f17d1db9eb8>] Error 111 connecting to 127.0.0.1:6739. Connection refused.
ERROR 2020-03-23 22:22:20,232 log 228 Insufficient Storage: /sms/
ERROR 2020-03-23 22:22:20,233 basehttp 154 "GET /sms/?mobile=18638626525 HTTP/1.1" 507 35
WARNING 2020-03-23 23:05:37,845 log 228 Not Found: /
WARNING 2020-03-23 23:05:37,860 basehttp 154 "GET / HTTP/1.1" 404 2235
WARNING 2020-03-23 23:05:38,011 log 228 Not Found: /favicon.ico
WARNING 2020-03-23 23:05:38,012 basehttp 154 "GET /favicon.ico HTTP/1.1" 404 2286
INFO 2020-03-23 23:06:09,454 basehttp 154 "GET /sms?mobile=18638626525 HTTP/1.1" 301 0
ERROR 2020-03-23 23:06:09,466 exceptions 25 [<users.views.SendSMSView object at 0x7f712c1234e0>] Error 111 connecting to 127.0.0.1:6739. Connection refused.
ERROR 2020-03-23 23:06:09,500 log 228 Insufficient Storage: /sms/
ERROR 2020-03-23 23:06:09,501 basehttp 154 "GET /sms/?mobile=18638626525 HTTP/1.1" 507 5306
ERROR 2020-03-23 23:06:22,958 exceptions 25 [<users.views.SendSMSView object at 0x7f712c140f60>] Error 111 connecting to 127.0.0.1:6739. Connection refused.
ERROR 2020-03-23 23:06:22,969 log 228 Insufficient Storage: /sms/
ERROR 2020-03-23 23:06:22,970 basehttp 154 "GET /sms/?mobile=18638626525 HTTP/1.1" 507 5306
ERROR 2020-03-23 23:06:27,199 exceptions 25 [<users.views.SendSMSView object at 0x7f712c0f3630>] Error 111 connecting to 127.0.0.1:6739. Connection refused.
ERROR 2020-03-23 23:06:27,208 log 228 Insufficient Storage: /sms/
ERROR 2020-03-23 23:06:27,208 basehttp 154 "GET /sms/?mobile=18638626525 HTTP/1.1" 507 5306
ERROR 2020-03-23 23:07:21,628 exceptions 25 [<users.views.SendSMSView object at 0x7f712c0efa90>] Error 111 connecting to 127.0.0.1:6739. Connection refused.
ERROR 2020-03-23 23:07:21,639 log 228 Insufficient Storage: /sms/
ERROR 2020-03-23 23:07:21,640 basehttp 154 "GET /sms/?mobile=18638626525 HTTP/1.1" 507 5306
INFO 2020-03-24 08:29:33,373 basehttp 154 "GET /sms?mobile=18638626525 HTTP/1.1" 301 0
ERROR 2020-03-24 08:29:33,428 exceptions 25 [<users.views.SendSMSView object at 0x7f5a84225d30>] Error 111 connecting to 127.0.0.1:6739. Connection refused.
ERROR 2020-03-24 08:29:33,429 log 228 Insufficient Storage: /sms/
ERROR 2020-03-24 08:29:33,430 basehttp 154 "GET /sms/?mobile=18638626525 HTTP/1.1" 507 35
WARNING 2020-03-24 08:31:02,834 log 228 Not Found: /
WARNING 2020-03-24 08:31:02,835 basehttp 154 "GET / HTTP/1.1" 404 2235
WARNING 2020-03-24 08:31:03,078 log 228 Not Found: /favicon.ico
WARNING 2020-03-24 08:31:03,079 basehttp 154 "GET /favicon.ico HTTP/1.1" 404 2286
ERROR 2020-03-24 08:31:30,856 exceptions 25 [<users.views.SendSMSView object at 0x7f71c9f18438>] Error 111 connecting to 127.0.0.1:6739. Connection refused.
ERROR 2020-03-24 08:31:30,880 log 228 Insufficient Storage: /sms/
ERROR 2020-03-24 08:31:30,880 basehttp 154 "GET /sms/?mobile=18638626525 HTTP/1.1" 507 5306
INFO 2020-03-24 08:31:30,902 basehttp 154 "GET /static/rest_framework/css/bootstrap-tweaks.css HTTP/1.1" 304 0
INFO 2020-03-24 08:31:30,903 basehttp 154 "GET /static/rest_framework/css/bootstrap.min.css HTTP/1.1" 304 0
INFO 2020-03-24 08:31:30,907 basehttp 154 "GET /static/rest_framework/js/jquery-3.4.1.min.js HTTP/1.1" 304 0
INFO 2020-03-24 08:31:30,913 basehttp 154 "GET /static/rest_framework/js/ajax-form.js HTTP/1.1" 304 0
INFO 2020-03-24 08:31:30,917 basehttp 154 "GET /static/rest_framework/js/csrf.js HTTP/1.1" 304 0
INFO 2020-03-24 08:31:30,919 basehttp 154 "GET /static/rest_framework/css/prettify.css HTTP/1.1" 304 0
INFO 2020-03-24 08:31:30,922 basehttp 154 "GET /static/rest_framework/js/default.js HTTP/1.1" 304 0
INFO 2020-03-24 08:31:30,924 basehttp 154 "GET /static/rest_framework/css/default.css HTTP/1.1" 304 0
INFO 2020-03-24 08:31:30,925 basehttp 154 "GET /static/rest_framework/js/bootstrap.min.js HTTP/1.1" 304 0
INFO 2020-03-24 08:31:30,929 basehttp 154 "GET /static/rest_framework/js/prettify-min.js HTTP/1.1" 304 0
INFO 2020-03-24 08:31:30,977 basehttp 154 "GET /static/rest_framework/img/grid.png HTTP/1.1" 304 0
ERROR 2020-03-24 08:33:09,233 exceptions 25 [<users.views.SendSMSView object at 0x7fd19378e9b0>] Error 111 connecting to 127.0.0.1:6739. Connection refused.
ERROR 2020-03-24 08:33:13,084 log 228 Insufficient Storage: /sms/
ERROR 2020-03-24 08:33:13,087 basehttp 154 "GET /sms/?mobile=18638626525 HTTP/1.1" 507 5306
ERROR 2020-03-24 08:39:15,100 exceptions 25 [<users.views.SendSMSView object at 0x7fe0fa80ba58>] Error 111 connecting to 127.0.0.1:6739. Connection refused.
ERROR 2020-03-24 08:39:15,132 log 228 Insufficient Storage: /sms/
ERROR 2020-03-24 08:39:15,133 basehttp 154 "GET /sms/?mobile=18638626525 HTTP/1.1" 507 5306
ERROR 2020-03-24 08:51:44,702 exceptions 25 [<users.views.SendSMSView object at 0x7ffa9e3c47b8>] Error 111 connecting to 127.0.0.1:6739. Connection refused.
ERROR 2020-03-24 08:51:44,737 log 228 Insufficient Storage: /sms/
ERROR 2020-03-24 08:51:44,738 basehttp 154 "GET /sms/?mobile=18638626525 HTTP/1.1" 507 5306
ERROR 2020-03-24 08:52:08,149 exceptions 25 [<users.views.SendSMSView object at 0x7f21b2f6d940>] Error 111 connecting to 127.0.0.1:6739. Connection refused.
ERROR 2020-03-24 08:52:08,164 log 228 Insufficient Storage: /sms/
ERROR 2020-03-24 08:52:08,165 basehttp 154 "GET /sms/?mobile=18638626525 HTTP/1.1" 507 5306
ERROR 2020-03-24 08:52:09,519 exceptions 25 [<users.views.SendSMSView object at 0x7f21b16316a0>] Error 111 connecting to 127.0.0.1:6739. Connection refused.
ERROR 2020-03-24 08:52:09,530 log 228 Insufficient Storage: /sms/
ERROR 2020-03-24 08:52:09,531 basehttp 154 "GET /sms/?mobile=18638626525 HTTP/1.1" 507 5306
ERROR 2020-03-24 08:52:09,744 exceptions 25 [<users.views.SendSMSView object at 0x7f21b15e3da0>] Error 111 connecting to 127.0.0.1:6739. Connection refused.
ERROR 2020-03-24 08:52:09,751 log 228 Insufficient Storage: /sms/
ERROR 2020-03-24 08:52:09,752 basehttp 154 "GET /sms/?mobile=18638626525 HTTP/1.1" 507 5306
ERROR 2020-03-24 08:52:09,975 exceptions 25 [<users.views.SendSMSView object at 0x7f21b1672b38>] Error 111 connecting to 127.0.0.1:6739. Connection refused.
ERROR 2020-03-24 08:52:09,983 log 228 Insufficient Storage: /sms/
ERROR 2020-03-24 08:52:09,984 basehttp 154 "GET /sms/?mobile=18638626525 HTTP/1.1" 507 5306
ERROR 2020-03-24 09:30:15,869 exceptions 25 [<users.views.SendSMSView object at 0x7fbe2efdf978>] Error 111 connecting to localhost:6739. Connection refused.
ERROR 2020-03-24 09:30:15,907 log 228 Insufficient Storage: /sms/
ERROR 2020-03-24 09:30:15,908 basehttp 154 "GET /sms/?mobile=18638626525 HTTP/1.1" 507 5306
WARNING 2020-03-24 09:30:16,267 log 228 Not Found: /favicon.ico
WARNING 2020-03-24 09:30:16,268 basehttp 154 "GET /favicon.ico HTTP/1.1" 404 2286
INFO 2020-03-24 09:38:07,544 basehttp 154 "GET /sms/?mobile=18638626525 HTTP/1.1" 200 5240
INFO 2020-03-24 09:47:25,160 basehttp 154 "GET /users/sms?mobile=18638626525 HTTP/1.1" 301 0
INFO 2020-03-24 09:47:25,211 basehttp 154 "GET /users/sms/?mobile=18638626525 HTTP/1.1" 200 4
INFO 2020-03-24 09:48:24,527 basehttp 154 "GET /users/sms?mobile=18638626525 HTTP/1.1" 301 0
INFO 2020-03-24 09:48:24,576 basehttp 154 "GET /users/sms/?mobile=18638626525 HTTP/1.1" 200 4
WARNING 2020-03-24 09:48:51,301 log 228 Not Found: /users/sms
WARNING 2020-03-24 09:48:51,304 basehttp 154 "GET /users/sms?mobile=18638626525 HTTP/1.1" 404 2304
INFO 2020-03-24 09:49:11,524 basehttp 154 "GET /sms?mobile=18638626525 HTTP/1.1" 301 0
INFO 2020-03-24 09:49:11,568 basehttp 154 "GET /sms/?mobile=18638626525 HTTP/1.1" 200 4
INFO 2020-03-24 09:50:13,982 basehttp 154 "GET /users/sms?mobile=18638626525 HTTP/1.1" 301 0
INFO 2020-03-24 09:50:14,026 basehttp 154 "GET /users/sms/?mobile=18638626525 HTTP/1.1" 200 4
INFO 2020-03-24 09:55:40,647 basehttp 154 "GET /users/sms?mobile=18638626525 HTTP/1.1" 200 4
INFO 2020-03-24 09:56:43,933 basehttp 154 "GET /users/sms?mobile=18638626525 HTTP/1.1" 200 4
INFO 2020-03-24 09:57:31,056 basehttp 154 "GET /users/sms?mobile=18638626525 HTTP/1.1" 301 0
INFO 2020-03-24 09:57:31,102 basehttp 154 "GET /users/sms/?mobile=18638626525 HTTP/1.1" 200 4
INFO 2020-03-24 09:57:56,362 basehttp 154 "GET /users/sms?mobile=18638626525 HTTP/1.1" 301 0
INFO 2020-03-24 09:57:56,411 basehttp 154 "GET /users/sms/?mobile=18638626525 HTTP/1.1" 200 4
INFO 2020-03-24 09:58:24,433 basehttp 154 "GET /users/sms?mobile=18638626525 HTTP/1.1" 301 0
INFO 2020-03-24 09:58:24,479 basehttp 154 "GET /users/sms/?mobile=18638626525 HTTP/1.1" 200 4
INFO 2020-03-24 09:58:57,729 basehttp 154 "GET /users/sms?mobile=18638626525 HTTP/1.1" 301 0
INFO 2020-03-24 09:58:57,779 basehttp 154 "GET /users/sms/?mobile=18638626525 HTTP/1.1" 200 4
INFO 2020-03-24 09:59:13,524 basehttp 154 "GET /users/sms?mobile=18638626525 HTTP/1.1" 301 0
INFO 2020-03-24 09:59:13,570 basehttp 154 "GET /users/sms/?mobile=18638626525 HTTP/1.1" 200 4
WARNING 2020-03-24 09:59:21,526 log 228 Not Found: /users/
WARNING 2020-03-24 09:59:21,528 basehttp 154 "GET /users/ HTTP/1.1" 404 2284
WARNING 2020-03-24 09:59:28,345 log 228 Not Found: /users
WARNING 2020-03-24 09:59:28,346 basehttp 154 "GET /users HTTP/1.1" 404 2072
WARNING 2020-03-24 09:59:57,412 log 228 Not Found: /users/
WARNING 2020-03-24 09:59:57,413 basehttp 154 "GET /users/ HTTP/1.1" 404 2284
WARNING 2020-03-24 10:00:39,578 log 228 Not Found: /users/
WARNING 2020-03-24 10:00:39,579 basehttp 154 "GET /users/ HTTP/1.1" 404 2284
WARNING 2020-03-24 10:00:45,965 log 228 Not Found: /users
WARNING 2020-03-24 10:00:45,965 basehttp 154 "GET /users HTTP/1.1" 404 2072
INFO 2020-03-24 10:01:04,282 basehttp 154 "GET /users HTTP/1.1" 301 0
INFO 2020-03-24 10:01:04,329 basehttp 154 "GET /users/ HTTP/1.1" 200 4
INFO 2020-03-24 10:01:35,154 basehttp 154 "GET /users/sms?mobile=18638626525 HTTP/1.1" 200 4
INFO 2020-03-24 10:02:16,770 basehttp 154 "GET /users/sms?mobile=18638626525 HTTP/1.1" 200 4
INFO 2020-03-24 10:02:18,685 basehttp 154 "GET /users/sms?mobile=18638626525 HTTP/1.1" 200 4
INFO 2020-03-24 10:02:54,749 basehttp 154 "GET /users/sms?mobile=18638626525 HTTP/1.1" 301 0
INFO 2020-03-24 10:02:54,796 basehttp 154 "GET /users/sms/?mobile=18638626525 HTTP/1.1" 200 4
INFO 2020-03-24 10:03:06,341 basehttp 154 "GET /users/sms?mobile=18638626525 HTTP/1.1" 301 0
INFO 2020-03-24 10:03:06,386 basehttp 154 "GET /users/sms/?mobile=18638626525 HTTP/1.1" 200 4
WARNING 2020-03-24 10:03:13,402 log 228 Not Found: /users
WARNING 2020-03-24 10:03:13,403 basehttp 154 "GET /users HTTP/1.1" 404 2071
WARNING 2020-03-24 10:03:34,403 log 228 Not Found: /users/
WARNING 2020-03-24 10:03:34,404 basehttp 154 "GET /users/ HTTP/1.1" 404 2282
INFO 2020-03-24 10:04:26,331 basehttp 154 "GET /users/register HTTP/1.1" 301 0
INFO 2020-03-24 10:04:26,377 basehttp 154 "GET /users/register/ HTTP/1.1" 200 4
INFO 2020-03-24 10:17:59,204 basehttp 154 "GET /users/sms?mobile=18638626525 HTTP/1.1" 301 0
INFO 2020-03-24 10:17:59,258 basehttp 154 "GET /users/sms/?mobile=18638626525 HTTP/1.1" 200 4
ERROR 2020-03-24 10:18:16,247 log 228 Internal Server Error: /users/register
Traceback (most recent call last):
  File "/home/yudashan/.virtualenvs/Django/lib/python3.6/site-packages/django/core/handlers/exception.py", line 34, in inner
    response = get_response(request)
  File "/home/yudashan/.virtualenvs/Django/lib/python3.6/site-packages/django/utils/deprecation.py", line 90, in __call__
    response = self.process_request(request)
  File "/home/yudashan/.virtualenvs/Django/lib/python3.6/site-packages/django/middleware/common.py", line 53, in process_request
    path = self.get_full_path_with_slash(request)
  File "/home/yudashan/.virtualenvs/Django/lib/python3.6/site-packages/django/middleware/common.py", line 93, in get_full_path_with_slash
    'url': request.get_host() + new_path,
RuntimeError: You called this URL via POST, but the URL doesn't end in a slash and you have APPEND_SLASH set. Django can't redirect to the slash URL while maintaining POST data. Change your form to point to 192.168.43.175:8000/users/register/?mibile=18638626525&password=123456&password2=123456&allow=true&sms_code=462863 (note the trailing slash), or set APPEND_SLASH=False in your Django settings.
ERROR 2020-03-24 10:18:16,253 basehttp 154 "POST /users/register?mibile=18638626525&password=123456&password2=123456&allow=true&sms_code=462863 HTTP/1.1" 500 74386
ERROR 2020-03-24 10:21:01,837 log 228 Internal Server Error: /users/register
Traceback (most recent call last):
  File "/home/yudashan/.virtualenvs/Django/lib/python3.6/site-packages/django/core/handlers/exception.py", line 34, in inner
    response = get_response(request)
  File "/home/yudashan/.virtualenvs/Django/lib/python3.6/site-packages/django/utils/deprecation.py", line 90, in __call__
    response = self.process_request(request)
  File "/home/yudashan/.virtualenvs/Django/lib/python3.6/site-packages/django/middleware/common.py", line 53, in process_request
    path = self.get_full_path_with_slash(request)
  File "/home/yudashan/.virtualenvs/Django/lib/python3.6/site-packages/django/middleware/common.py", line 93, in get_full_path_with_slash
    'url': request.get_host() + new_path,
RuntimeError: You called this URL via POST, but the URL doesn't end in a slash and you have APPEND_SLASH set. Django can't redirect to the slash URL while maintaining POST data. Change your form to point to 192.168.43.175:8000/users/register/?mibile=18638626525&password=123456&password2=123456&allow=true&sms_code=462863/ (note the trailing slash), or set APPEND_SLASH=False in your Django settings.
ERROR 2020-03-24 10:21:01,840 basehttp 154 "POST /users/register?mibile=18638626525&password=123456&password2=123456&allow=true&sms_code=462863/ HTTP/1.1" 500 74399
ERROR 2020-03-24 10:22:57,749 log 228 Internal Server Error: /users/register
Traceback (most recent call last):
  File "/home/yudashan/.virtualenvs/Django/lib/python3.6/site-packages/django/core/handlers/exception.py", line 34, in inner
    response = get_response(request)
  File "/home/yudashan/.virtualenvs/Django/lib/python3.6/site-packages/django/utils/deprecation.py", line 90, in __call__
    response = self.process_request(request)
  File "/home/yudashan/.virtualenvs/Django/lib/python3.6/site-packages/django/middleware/common.py", line 53, in process_request
    path = self.get_full_path_with_slash(request)
  File "/home/yudashan/.virtualenvs/Django/lib/python3.6/site-packages/django/middleware/common.py", line 93, in get_full_path_with_slash
    'url': request.get_host() + new_path,
RuntimeError: You called this URL via POST, but the URL doesn't end in a slash and you have APPEND_SLASH set. Django can't redirect to the slash URL while maintaining POST data. Change your form to point to 192.168.43.175:8000/users/register/?mibile=18638626525&password=123456&password2=123456&allow=true&sms_code=462863/ (note the trailing slash), or set APPEND_SLASH=False in your Django settings.
ERROR 2020-03-24 10:22:57,752 basehttp 154 "POST /users/register?mibile=18638626525&password=123456&password2=123456&allow=true&sms_code=462863/ HTTP/1.1" 500 74399
WARNING 2020-03-24 10:23:32,314 log 228 Not Found: /users/register
WARNING 2020-03-24 10:23:32,316 basehttp 154 "POST /users/register?mibile=18638626525&password=123456&password2=123456&allow=true&sms_code=462863/ HTTP/1.1" 404 2411
WARNING 2020-03-24 10:23:54,020 log 228 Not Found: /users/register
WARNING 2020-03-24 10:23:54,021 basehttp 154 "POST /users/register?mibile=18638626525&password=123456&password2=123456&allow=true&sms_code=462863 HTTP/1.1" 404 2410
WARNING 2020-03-24 10:24:43,322 log 228 Not Found: /users/register
WARNING 2020-03-24 10:24:43,323 basehttp 154 "POST /users/register?mibile=18638626525&password=123456&password2=123456&allow=true&sms_code=462863 HTTP/1.1" 404 2410
WARNING 2020-03-24 10:26:01,293 log 228 Not Found: /users/register
WARNING 2020-03-24 10:26:01,295 basehttp 154 "POST /users/register HTTP/1.1" 404 2315
WARNING 2020-03-24 10:26:47,858 log 228 Not Found: /users/register
WARNING 2020-03-24 10:26:47,859 basehttp 154 "POST /users/register HTTP/1.1" 404 2316
WARNING 2020-03-24 10:34:15,639 log 228 Not Found: /users/register
WARNING 2020-03-24 10:34:15,641 basehttp 154 "POST /users/register HTTP/1.1" 404 2316
WARNING 2020-03-24 10:35:11,027 log 228 Not Found: /users/register
WARNING 2020-03-24 10:35:11,028 basehttp 154 "POST /users/register HTTP/1.1" 404 2318
WARNING 2020-03-24 10:35:22,674 log 228 Not Found: /users/sms
WARNING 2020-03-24 10:35:22,676 basehttp 154 "GET /users/sms?mobile=18638626525 HTTP/1.1" 404 2321
WARNING 2020-03-24 10:36:17,896 log 228 Not Found: /sms
WARNING 2020-03-24 10:36:17,899 basehttp 154 "GET /sms?mobile=18638626525 HTTP/1.1" 404 2289
WARNING 2020-03-24 10:37:13,804 log 228 Not Found: /sms/
WARNING 2020-03-24 10:37:13,805 basehttp 154 "GET /sms/?mobile=18638626525 HTTP/1.1" 404 2088
WARNING 2020-03-24 10:38:06,792 log 228 Not Found: /sms/
WARNING 2020-03-24 10:38:06,793 basehttp 154 "GET /sms/?mobile=18638626525 HTTP/1.1" 404 2088
INFO 2020-03-24 10:38:17,795 basehttp 154 "GET /users/sms/?mobile=18638626525 HTTP/1.1" 200 4
INFO 2020-03-24 10:38:31,889 basehttp 154 "POST /users/register/ HTTP/1.1" 200 4
WARNING 2020-03-24 10:39:16,398 log 228 Bad Request: /users/register/
WARNING 2020-03-24 10:39:16,399 basehttp 154 "POST /users/register/?mibile=18638626525&password=123456&password2=123456&allow=true&sms_code=462863 HTTP/1.1" 400 194
WARNING 2020-03-24 10:40:09,236 log 228 Bad Request: /users/register/
WARNING 2020-03-24 10:40:09,237 basehttp 154 "POST /users/register/?mibile=18638626525&password=123456&password2=123456&allow=true&sms_code=897007 HTTP/1.1" 400 194
WARNING 2020-03-24 10:43:34,561 log 228 Bad Request: /users/register/
WARNING 2020-03-24 10:43:34,561 basehttp 154 "POST /users/register/ HTTP/1.1" 400 73
WARNING 2020-03-24 10:44:27,455 log 228 Bad Request: /users/register/
WARNING 2020-03-24 10:44:27,456 basehttp 154 "POST /users/register/ HTTP/1.1" 400 35
WARNING 2020-03-24 10:44:39,184 log 228 Bad Request: /users/register/
WARNING 2020-03-24 10:44:39,184 basehttp 154 "POST /users/register/ HTTP/1.1" 400 35
WARNING 2020-03-24 10:45:00,839 log 228 Bad Request: /users/register/
WARNING 2020-03-24 10:45:00,840 basehttp 154 "POST /users/register/ HTTP/1.1" 400 35
WARNING 2020-03-24 10:45:56,228 log 228 Bad Request: /users/register/
WARNING 2020-03-24 10:45:56,228 basehttp 154 "POST /users/register/ HTTP/1.1" 400 35
ERROR 2020-03-24 10:47:26,230 log 228 Internal Server Error: /users/register/
Traceback (most recent call last):
  File "/home/yudashan/.virtualenvs/Django/lib/python3.6/site-packages/django/core/handlers/exception.py", line 34, in inner
    response = get_response(request)
  File "/home/yudashan/.virtualenvs/Django/lib/python3.6/site-packages/django/core/handlers/base.py", line 126, in _get_response
    response = self.process_exception_by_middleware(e, request)
  File "/home/yudashan/.virtualenvs/Django/lib/python3.6/site-packages/django/core/handlers/base.py", line 124, in _get_response
    response = wrapped_callback(request, *callback_args, **callback_kwargs)
  File "/home/yudashan/.virtualenvs/Django/lib/python3.6/site-packages/django/views/decorators/csrf.py", line 54, in wrapped_view
    return view_func(*args, **kwargs)
  File "/home/yudashan/.virtualenvs/Django/lib/python3.6/site-packages/django/views/generic/base.py", line 68, in view
    return self.dispatch(request, *args, **kwargs)
  File "/home/yudashan/.virtualenvs/Django/lib/python3.6/site-packages/rest_framework/views.py", line 505, in dispatch
    response = self.handle_exception(exc)
  File "/home/yudashan/.virtualenvs/Django/lib/python3.6/site-packages/rest_framework/views.py", line 465, in handle_exception
    self.raise_uncaught_exception(exc)
  File "/home/yudashan/.virtualenvs/Django/lib/python3.6/site-packages/rest_framework/views.py", line 476, in raise_uncaught_exception
    raise exc
  File "/home/yudashan/.virtualenvs/Django/lib/python3.6/site-packages/rest_framework/views.py", line 502, in dispatch
    response = handler(request, *args, **kwargs)
  File "/home/yudashan/.virtualenvs/Django/lib/python3.6/site-packages/rest_framework/generics.py", line 190, in post
    return self.create(request, *args, **kwargs)
  File "/home/yudashan/.virtualenvs/Django/lib/python3.6/site-packages/rest_framework/mixins.py", line 18, in create
    serializer.is_valid(raise_exception=True)
  File "/home/yudashan/.virtualenvs/Django/lib/python3.6/site-packages/rest_framework/serializers.py", line 234, in is_valid
    self._validated_data = self.run_validation(self.initial_data)
  File "/home/yudashan/.virtualenvs/Django/lib/python3.6/site-packages/rest_framework/serializers.py", line 436, in run_validation
    value = self.validate(value)
  File "/home/yudashan/Desktop/Django-project/DRFBlog-2.2/Blog_project/Blog_project/apps/users/serializers.py", line 36, in validate
    if attrs['password'] != attrs["passwoed"]:
KeyError: 'passwoed'
ERROR 2020-03-24 10:47:26,232 basehttp 154 "POST /users/register/ HTTP/1.1" 500 20130
ERROR 2020-03-24 10:47:58,909 log 228 Internal Server Error: /users/register/
Traceback (most recent call last):
  File "/home/yudashan/.virtualenvs/Django/lib/python3.6/site-packages/django/core/handlers/exception.py", line 34, in inner
    response = get_response(request)
  File "/home/yudashan/.virtualenvs/Django/lib/python3.6/site-packages/django/core/handlers/base.py", line 126, in _get_response
    response = self.process_exception_by_middleware(e, request)
  File "/home/yudashan/.virtualenvs/Django/lib/python3.6/site-packages/django/core/handlers/base.py", line 124, in _get_response
    response = wrapped_callback(request, *callback_args, **callback_kwargs)
  File "/home/yudashan/.virtualenvs/Django/lib/python3.6/site-packages/django/views/decorators/csrf.py", line 54, in wrapped_view
    return view_func(*args, **kwargs)
  File "/home/yudashan/.virtualenvs/Django/lib/python3.6/site-packages/django/views/generic/base.py", line 68, in view
    return self.dispatch(request, *args, **kwargs)
  File "/home/yudashan/.virtualenvs/Django/lib/python3.6/site-packages/rest_framework/views.py", line 505, in dispatch
    response = self.handle_exception(exc)
  File "/home/yudashan/.virtualenvs/Django/lib/python3.6/site-packages/rest_framework/views.py", line 465, in handle_exception
    self.raise_uncaught_exception(exc)
  File "/home/yudashan/.virtualenvs/Django/lib/python3.6/site-packages/rest_framework/views.py", line 476, in raise_uncaught_exception
    raise exc
  File "/home/yudashan/.virtualenvs/Django/lib/python3.6/site-packages/rest_framework/views.py", line 502, in dispatch
    response = handler(request, *args, **kwargs)
  File "/home/yudashan/.virtualenvs/Django/lib/python3.6/site-packages/rest_framework/generics.py", line 190, in post
    return self.create(request, *args, **kwargs)
  File "/home/yudashan/.virtualenvs/Django/lib/python3.6/site-packages/rest_framework/mixins.py", line 18, in create
    serializer.is_valid(raise_exception=True)
  File "/home/yudashan/.virtualenvs/Django/lib/python3.6/site-packages/rest_framework/serializers.py", line 234, in is_valid
    self._validated_data = self.run_validation(self.initial_data)
  File "/home/yudashan/.virtualenvs/Django/lib/python3.6/site-packages/rest_framework/serializers.py", line 436, in run_validation
    value = self.validate(value)
  File "/home/yudashan/Desktop/Django-project/DRFBlog-2.2/Blog_project/Blog_project/apps/users/serializers.py", line 39, in validate
    redis_conn = get_redis_connection("verfy_codes")
  File "/home/yudashan/.virtualenvs/Django/lib/python3.6/site-packages/django_redis/__init__.py", line 12, in get_redis_connection
    cache = caches[alias]
  File "/home/yudashan/.virtualenvs/Django/lib/python3.6/site-packages/django/core/cache/__init__.py", line 76, in __getitem__
    "Could not find config for '%s' in settings.CACHES" % alias
django.core.cache.backends.base.InvalidCacheBackendError: Could not find config for 'verfy_codes' in settings.CACHES
ERROR 2020-03-24 10:47:58,913 basehttp 154 "POST /users/register/ HTTP/1.1" 500 20614
WARNING 2020-03-24 10:48:21,478 log 228 Bad Request: /users/register/
WARNING 2020-03-24 10:48:21,479 basehttp 154 "POST /users/register/ HTTP/1.1" 400 55
INFO 2020-03-24 10:48:42,811 basehttp 154 "GET /users/sms/?mobile=18638626525 HTTP/1.1" 200 4
WARNING 2020-03-24 10:48:58,765 log 228 Bad Request: /users/register/
WARNING 2020-03-24 10:48:58,766 basehttp 154 "POST /users/register/ HTTP/1.1" 400 55
WARNING 2020-03-24 10:49:54,465 log 228 Bad Request: /users/register/
WARNING 2020-03-24 10:49:54,466 basehttp 154 "POST /users/register/ HTTP/1.1" 400 55
WARNING 2020-03-24 10:51:24,290 log 228 Bad Request: /users/register/
WARNING 2020-03-24 10:51:24,292 basehttp 154 "POST /users/register/ HTTP/1.1" 400 55
WARNING 2020-03-24 10:52:26,789 log 228 Bad Request: /users/register/
WARNING 2020-03-24 10:52:26,790 basehttp 154 "POST /users/register/ HTTP/1.1" 400 55
WARNING 2020-03-24 10:52:51,738 log 228 Bad Request: /users/register/
WARNING 2020-03-24 10:52:51,739 basehttp 154 "POST /users/register/ HTTP/1.1" 400 55
WARNING 2020-03-24 10:53:11,038 log 228 Bad Request: /users/register/
WARNING 2020-03-24 10:53:11,039 basehttp 154 "POST /users/register/ HTTP/1.1" 400 55
ERROR 2020-03-24 10:53:51,994 log 228 Internal Server Error: /users/register/
Traceback (most recent call last):
  File "/home/yudashan/.virtualenvs/Django/lib/python3.6/site-packages/django/core/handlers/exception.py", line 34, in inner
    response = get_response(request)
  File "/home/yudashan/.virtualenvs/Django/lib/python3.6/site-packages/django/core/handlers/base.py", line 126, in _get_response
    response = self.process_exception_by_middleware(e, request)
  File "/home/yudashan/.virtualenvs/Django/lib/python3.6/site-packages/django/core/handlers/base.py", line 124, in _get_response
    response = wrapped_callback(request, *callback_args, **callback_kwargs)
  File "/home/yudashan/.virtualenvs/Django/lib/python3.6/site-packages/django/views/decorators/csrf.py", line 54, in wrapped_view
    return view_func(*args, **kwargs)
  File "/home/yudashan/.virtualenvs/Django/lib/python3.6/site-packages/django/views/generic/base.py", line 68, in view
    return self.dispatch(request, *args, **kwargs)
  File "/home/yudashan/.virtualenvs/Django/lib/python3.6/site-packages/rest_framework/views.py", line 505, in dispatch
    response = self.handle_exception(exc)
  File "/home/yudashan/.virtualenvs/Django/lib/python3.6/site-packages/rest_framework/views.py", line 465, in handle_exception
    self.raise_uncaught_exception(exc)
  File "/home/yudashan/.virtualenvs/Django/lib/python3.6/site-packages/rest_framework/views.py", line 476, in raise_uncaught_exception
    raise exc
  File "/home/yudashan/.virtualenvs/Django/lib/python3.6/site-packages/rest_framework/views.py", line 502, in dispatch
    response = handler(request, *args, **kwargs)
  File "/home/yudashan/.virtualenvs/Django/lib/python3.6/site-packages/rest_framework/generics.py", line 190, in post
    return self.create(request, *args, **kwargs)
  File "/home/yudashan/.virtualenvs/Django/lib/python3.6/site-packages/rest_framework/mixins.py", line 18, in create
    serializer.is_valid(raise_exception=True)
  File "/home/yudashan/.virtualenvs/Django/lib/python3.6/site-packages/rest_framework/serializers.py", line 234, in is_valid
    self._validated_data = self.run_validation(self.initial_data)
  File "/home/yudashan/.virtualenvs/Django/lib/python3.6/site-packages/rest_framework/serializers.py", line 436, in run_validation
    value = self.validate(value)
  File "/home/yudashan/Desktop/Django-project/DRFBlog-2.2/Blog_project/Blog_project/apps/users/serializers.py", line 41, in validate
    real_sms_code = redis_conn.get("sms_%s" % mobile).decode()
AttributeError: 'NoneType' object has no attribute 'decode'
ERROR 2020-03-24 10:53:51,997 basehttp 154 "POST /users/register/ HTTP/1.1" 500 20224
INFO 2020-03-24 10:54:15,149 basehttp 154 "GET /users/sms/?mobile=18638626525 HTTP/1.1" 200 4
WARNING 2020-03-24 10:54:32,651 log 228 Bad Request: /users/register/
WARNING 2020-03-24 10:54:32,652 basehttp 154 "POST /users/register/ HTTP/1.1" 400 55
INFO 2020-03-24 10:54:49,555 basehttp 154 "POST /users/register/ HTTP/1.1" 201 38
WARNING 2020-03-24 11:02:47,826 log 228 Bad Request: /users/register/
WARNING 2020-03-24 11:02:47,827 basehttp 154 "POST /users/register/ HTTP/1.1" 400 55
ERROR 2020-03-24 11:02:59,314 log 228 Internal Server Error: /users/register/
Traceback (most recent call last):
  File "/home/yudashan/.virtualenvs/Django/lib/python3.6/site-packages/django/core/handlers/exception.py", line 34, in inner
    response = get_response(request)
  File "/home/yudashan/.virtualenvs/Django/lib/python3.6/site-packages/django/core/handlers/base.py", line 126, in _get_response
    response = self.process_exception_by_middleware(e, request)
  File "/home/yudashan/.virtualenvs/Django/lib/python3.6/site-packages/django/core/handlers/base.py", line 124, in _get_response
    response = wrapped_callback(request, *callback_args, **callback_kwargs)
  File "/home/yudashan/.virtualenvs/Django/lib/python3.6/site-packages/django/views/decorators/csrf.py", line 54, in wrapped_view
    return view_func(*args, **kwargs)
  File "/home/yudashan/.virtualenvs/Django/lib/python3.6/site-packages/django/views/generic/base.py", line 68, in view
    return self.dispatch(request, *args, **kwargs)
  File "/home/yudashan/.virtualenvs/Django/lib/python3.6/site-packages/rest_framework/views.py", line 505, in dispatch
    response = self.handle_exception(exc)
  File "/home/yudashan/.virtualenvs/Django/lib/python3.6/site-packages/rest_framework/views.py", line 465, in handle_exception
    self.raise_uncaught_exception(exc)
  File "/home/yudashan/.virtualenvs/Django/lib/python3.6/site-packages/rest_framework/views.py", line 476, in raise_uncaught_exception
    raise exc
  File "/home/yudashan/.virtualenvs/Django/lib/python3.6/site-packages/rest_framework/views.py", line 502, in dispatch
    response = handler(request, *args, **kwargs)
  File "/home/yudashan/.virtualenvs/Django/lib/python3.6/site-packages/rest_framework/generics.py", line 190, in post
    return self.create(request, *args, **kwargs)
  File "/home/yudashan/.virtualenvs/Django/lib/python3.6/site-packages/rest_framework/mixins.py", line 18, in create
    serializer.is_valid(raise_exception=True)
  File "/home/yudashan/.virtualenvs/Django/lib/python3.6/site-packages/rest_framework/serializers.py", line 234, in is_valid
    self._validated_data = self.run_validation(self.initial_data)
  File "/home/yudashan/.virtualenvs/Django/lib/python3.6/site-packages/rest_framework/serializers.py", line 436, in run_validation
    value = self.validate(value)
  File "/home/yudashan/Desktop/Django-project/DRFBlog-2.2/Blog_project/Blog_project/apps/users/serializers.py", line 38, in validate
    if attrs["username"] is None:
KeyError: 'username'
ERROR 2020-03-24 11:02:59,318 basehttp 154 "POST /users/register/ HTTP/1.1" 500 20117
WARNING 2020-03-24 11:04:13,729 log 228 Bad Request: /users/register/
WARNING 2020-03-24 11:04:13,731 basehttp 154 "POST /users/register/ HTTP/1.1" 400 55
INFO 2020-03-24 11:04:55,790 basehttp 154 "GET /users/sms/?mobile=18638626521 HTTP/1.1" 200 4
ERROR 2020-03-24 11:05:26,293 exceptions 25 [<users.views.UserView object at 0x7f3d21c06dd8>] (1062, "Duplicate entry '' for key 'username'")
ERROR 2020-03-24 11:05:26,294 log 228 Insufficient Storage: /users/register/
ERROR 2020-03-24 11:05:26,294 basehttp 154 "POST /users/register/ HTTP/1.1" 507 35
ERROR 2020-03-24 11:06:29,390 exceptions 25 [<users.views.UserView object at 0x7fe737689da0>] (1062, "Duplicate entry '' for key 'username'")
ERROR 2020-03-24 11:06:29,391 log 228 Insufficient Storage: /users/register/
ERROR 2020-03-24 11:06:29,391 basehttp 154 "POST /users/register/ HTTP/1.1" 507 35
ERROR 2020-03-24 11:07:13,606 exceptions 25 [<users.views.UserView object at 0x7fe75d8bc198>] (1062, "Duplicate entry '' for key 'username'")
ERROR 2020-03-24 11:07:13,607 log 228 Insufficient Storage: /users/register/
ERROR 2020-03-24 11:07:13,608 basehttp 154 "POST /users/register/ HTTP/1.1" 507 35
INFO 2020-03-24 11:33:14,826 basehttp 154 "GET /users/sms/?mobile=18638626521 HTTP/1.1" 200 4
ERROR 2020-03-24 11:33:40,928 exceptions 25 [<users.views.UserView object at 0x7f7412dd8eb8>] (1062, "Duplicate entry '' for key 'username'")
ERROR 2020-03-24 11:33:40,929 log 228 Insufficient Storage: /users/register/
ERROR 2020-03-24 11:33:40,930 basehttp 154 "POST /users/register/ HTTP/1.1" 507 35
ERROR 2020-03-24 11:34:25,367 exceptions 25 [<users.views.UserView object at 0x7fa7fa529a58>] (1062, "Duplicate entry '' for key 'username'")
ERROR 2020-03-24 11:34:25,368 log 228 Insufficient Storage: /users/register/
ERROR 2020-03-24 11:34:25,369 basehttp 154 "POST /users/register/ HTTP/1.1" 507 35
WARNING 2020-03-24 11:40:35,198 log 228 Bad Request: /users/register/
WARNING 2020-03-24 11:40:35,198 basehttp 154 "POST /users/register/ HTTP/1.1" 400 55
INFO 2020-03-24 11:40:40,281 basehttp 154 "GET /users/sms/?mobile=18638626521 HTTP/1.1" 200 4
ERROR 2020-03-24 11:41:02,268 exceptions 25 [<users.views.UserView object at 0x7f9a7e23fdd8>] (1062, "Duplicate entry '' for key 'username'")
ERROR 2020-03-24 11:41:02,269 log 228 Insufficient Storage: /users/register/
ERROR 2020-03-24 11:41:02,269 basehttp 154 "POST /users/register/ HTTP/1.1" 507 35
ERROR 2020-03-24 11:41:26,270 exceptions 25 [<users.views.UserView object at 0x7f0c0405ac50>] (1062, "Duplicate entry '' for key 'username'")
ERROR 2020-03-24 11:41:26,271 log 228 Insufficient Storage: /users/register/
ERROR 2020-03-24 11:41:26,271 basehttp 154 "POST /users/register/ HTTP/1.1" 507 35
ERROR 2020-03-24 11:43:42,338 exceptions 25 [<users.views.UserView object at 0x7f0bff4b5f28>] (1062, "Duplicate entry '' for key 'username'")
ERROR 2020-03-24 11:43:42,338 log 228 Insufficient Storage: /users/register/
ERROR 2020-03-24 11:43:42,339 basehttp 154 "POST /users/register/ HTTP/1.1" 507 35
WARNING 2020-03-24 11:52:09,503 log 228 Bad Request: /users/register/
WARNING 2020-03-24 11:52:09,504 basehttp 154 "POST /users/register/ HTTP/1.1" 400 41
WARNING 2020-03-24 14:34:24,694 log 228 Bad Request: /users/register/
WARNING 2020-03-24 14:34:24,705 basehttp 154 "POST /users/register/ HTTP/1.1" 400 41
INFO 2020-03-24 14:40:03,372 basehttp 154 "GET /users/sms/?mobile=18638626521 HTTP/1.1" 200 4
ERROR 2020-03-24 14:40:25,856 exceptions 25 [<users.views.UserView object at 0x7f138054feb8>] (1062, "Duplicate entry '' for key 'username'")
ERROR 2020-03-24 14:40:25,856 log 228 Insufficient Storage: /users/register/
ERROR 2020-03-24 14:40:25,857 basehttp 154 "POST /users/register/ HTTP/1.1" 507 35
ERROR 2020-03-24 14:40:56,543 exceptions 25 [<users.views.UserView object at 0x7f87a8553208>] (1062, "Duplicate entry '' for key 'username'")
ERROR 2020-03-24 14:40:56,543 log 228 Insufficient Storage: /users/register/
ERROR 2020-03-24 14:40:56,544 basehttp 154 "POST /users/register/ HTTP/1.1" 507 35
ERROR 2020-03-24 14:42:21,096 exceptions 25 [<users.views.UserView object at 0x7f5d9f476748>] (1062, "Duplicate entry '' for key 'username'")
ERROR 2020-03-24 14:42:21,097 log 228 Insufficient Storage: /users/register/
ERROR 2020-03-24 14:42:21,097 basehttp 154 "POST /users/register/ HTTP/1.1" 507 35
ERROR 2020-03-24 14:42:51,472 exceptions 25 [<users.views.UserView object at 0x7f7a424f3278>] (1062, "Duplicate entry '' for key 'username'")
ERROR 2020-03-24 14:42:51,473 log 228 Insufficient Storage: /users/register/
ERROR 2020-03-24 14:42:51,473 basehttp 154 "POST /users/register/ HTTP/1.1" 507 35
ERROR 2020-03-24 14:43:24,942 exceptions 25 [<users.views.UserView object at 0x7f8d26ad9518>] (1062, "Duplicate entry '' for key 'username'")
ERROR 2020-03-24 14:43:24,943 log 228 Insufficient Storage: /users/register/
ERROR 2020-03-24 14:43:24,943 basehttp 154 "POST /users/register/ HTTP/1.1" 507 35
ERROR 2020-03-24 14:44:29,571 exceptions 25 [<users.views.UserView object at 0x7fab1a928c88>] (1062, "Duplicate entry '' for key 'username'")
ERROR 2020-03-24 14:44:29,572 log 228 Insufficient Storage: /users/register/
ERROR 2020-03-24 14:44:29,572 basehttp 154 "POST /users/register/ HTTP/1.1" 507 35
WARNING 2020-03-24 14:45:33,050 log 228 Bad Request: /users/register/
WARNING 2020-03-24 14:45:33,050 basehttp 154 "POST /users/register/ HTTP/1.1" 400 55
INFO 2020-03-24 14:45:43,037 basehttp 154 "GET /users/sms/?mobile=18638626521 HTTP/1.1" 200 4
ERROR 2020-03-24 14:45:58,586 exceptions 25 [<users.views.UserView object at 0x7f4cc98f8518>] (1062, "Duplicate entry '' for key 'username'")
ERROR 2020-03-24 14:45:58,587 log 228 Insufficient Storage: /users/register/
ERROR 2020-03-24 14:45:58,588 basehttp 154 "POST /users/register/ HTTP/1.1" 507 35
ERROR 2020-03-24 14:48:10,122 exceptions 25 [<users.views.UserView object at 0x7f4cc98f8d68>] (1062, "Duplicate entry '' for key 'username'")
ERROR 2020-03-24 14:48:10,123 log 228 Insufficient Storage: /users/register/
ERROR 2020-03-24 14:48:10,124 basehttp 154 "POST /users/register/ HTTP/1.1" 507 35
ERROR 2020-03-24 14:48:41,662 exceptions 25 [<users.views.UserView object at 0x7fbecbd23c50>] (1062, "Duplicate entry '' for key 'username'")
ERROR 2020-03-24 14:48:41,663 log 228 Insufficient Storage: /users/register/
ERROR 2020-03-24 14:48:41,663 basehttp 154 "POST /users/register/ HTTP/1.1" 507 35
WARNING 2020-03-24 14:53:55,687 log 228 Bad Request: /users/register/
WARNING 2020-03-24 14:53:55,688 basehttp 154 "POST /users/register/ HTTP/1.1" 400 55
INFO 2020-03-24 14:54:08,856 basehttp 154 "GET /users/sms/?mobile=18638626521 HTTP/1.1" 200 4
ERROR 2020-03-24 14:54:25,780 exceptions 25 [<users.views.UserView object at 0x7fc964505358>] (1062, "Duplicate entry '' for key 'username'")
ERROR 2020-03-24 14:54:25,781 log 228 Insufficient Storage: /users/register/
ERROR 2020-03-24 14:54:25,783 basehttp 154 "POST /users/register/ HTTP/1.1" 507 35
ERROR 2020-03-24 14:55:41,000 exceptions 25 [<users.views.UserView object at 0x7f9485006e80>] (1062, "Duplicate entry '' for key 'username'")
ERROR 2020-03-24 14:55:41,001 log 228 Insufficient Storage: /users/register/
ERROR 2020-03-24 14:55:41,001 basehttp 154 "POST /users/register/ HTTP/1.1" 507 35
ERROR 2020-03-24 14:56:28,102 exceptions 25 [<users.views.UserView object at 0x7f98fe933f28>] (1062, "Duplicate entry '' for key 'username'")
ERROR 2020-03-24 14:56:28,104 log 228 Insufficient Storage: /users/register/
ERROR 2020-03-24 14:56:28,106 basehttp 154 "POST /users/register/ HTTP/1.1" 507 35
ERROR 2020-03-24 14:57:19,133 exceptions 25 [<users.views.UserView object at 0x7f98fd7a0668>] (1062, "Duplicate entry '' for key 'username'")
ERROR 2020-03-24 14:57:19,133 log 228 Insufficient Storage: /users/register/
ERROR 2020-03-24 14:57:19,134 basehttp 154 "POST /users/register/ HTTP/1.1" 507 35
ERROR 2020-03-24 14:57:21,312 exceptions 25 [<users.views.UserView object at 0x7f98fd75ecc0>] (1062, "Duplicate entry '' for key 'username'")
ERROR 2020-03-24 14:57:21,313 log 228 Insufficient Storage: /users/register/
ERROR 2020-03-24 14:57:21,313 basehttp 154 "POST /users/register/ HTTP/1.1" 507 35
INFO 2020-03-25 11:37:53,723 basehttp 154 "GET /users/sms/?mobile=18638626521 HTTP/1.1" 200 4
WARNING 2020-03-25 11:38:08,430 log 228 Bad Request: /users/register/
WARNING 2020-03-25 11:38:08,431 basehttp 154 "POST /users/register/ HTTP/1.1" 400 55
WARNING 2020-03-25 11:38:58,049 log 228 Bad Request: /users/register/
WARNING 2020-03-25 11:38:58,050 basehttp 154 "POST /users/register/ HTTP/1.1" 400 55
WARNING 2020-03-25 11:39:41,025 log 228 Bad Request: /users/register/
WARNING 2020-03-25 11:39:41,026 basehttp 154 "POST /users/register/ HTTP/1.1" 400 55
WARNING 2020-03-25 11:40:07,167 log 228 Bad Request: /users/register/
WARNING 2020-03-25 11:40:07,168 basehttp 154 "POST /users/register/ HTTP/1.1" 400 55
WARNING 2020-03-25 11:41:42,439 log 228 Bad Request: /users/register/
WARNING 2020-03-25 11:41:42,440 basehttp 154 "POST /users/register/ HTTP/1.1" 400 55
WARNING 2020-03-25 11:42:57,471 log 228 Bad Request: /users/register/
WARNING 2020-03-25 11:42:57,472 basehttp 154 "POST /users/register/ HTTP/1.1" 400 55
WARNING 2020-03-25 11:43:05,303 log 228 Bad Request: /users/register/
WARNING 2020-03-25 11:43:05,304 basehttp 154 "POST /users/register/ HTTP/1.1" 400 55
WARNING 2020-03-25 11:43:37,545 log 228 Bad Request: /users/register/
WARNING 2020-03-25 11:43:37,546 basehttp 154 "POST /users/register/ HTTP/1.1" 400 55
INFO 2020-03-25 11:43:55,530 basehttp 154 "GET /users/sms/?mobile=18638626521 HTTP/1.1" 200 4
ERROR 2020-03-25 11:44:11,661 log 228 Internal Server Error: /users/register/
Traceback (most recent call last):
  File "/home/yudashan/.virtualenvs/Django/lib/python3.6/site-packages/rest_framework/serializers.py", line 948, in create
    instance = ModelClass._default_manager.create(**validated_data)
  File "/home/yudashan/Desktop/Django-project/DRFBlog-2.2/Blog_project/Blog_project/apps/users/models.py", line 13, in create
    *extra_fields
TypeError: can't multiply sequence by non-int of type 'dict'

During handling of the above exception, another exception occurred:

Traceback (most recent call last):
  File "/home/yudashan/.virtualenvs/Django/lib/python3.6/site-packages/django/core/handlers/exception.py", line 34, in inner
    response = get_response(request)
  File "/home/yudashan/.virtualenvs/Django/lib/python3.6/site-packages/django/core/handlers/base.py", line 126, in _get_response
    response = self.process_exception_by_middleware(e, request)
  File "/home/yudashan/.virtualenvs/Django/lib/python3.6/site-packages/django/core/handlers/base.py", line 124, in _get_response
    response = wrapped_callback(request, *callback_args, **callback_kwargs)
  File "/home/yudashan/.virtualenvs/Django/lib/python3.6/site-packages/django/views/decorators/csrf.py", line 54, in wrapped_view
    return view_func(*args, **kwargs)
  File "/home/yudashan/.virtualenvs/Django/lib/python3.6/site-packages/django/views/generic/base.py", line 68, in view
    return self.dispatch(request, *args, **kwargs)
  File "/home/yudashan/.virtualenvs/Django/lib/python3.6/site-packages/rest_framework/views.py", line 505, in dispatch
    response = self.handle_exception(exc)
  File "/home/yudashan/.virtualenvs/Django/lib/python3.6/site-packages/rest_framework/views.py", line 465, in handle_exception
    self.raise_uncaught_exception(exc)
  File "/home/yudashan/.virtualenvs/Django/lib/python3.6/site-packages/rest_framework/views.py", line 476, in raise_uncaught_exception
    raise exc
  File "/home/yudashan/.virtualenvs/Django/lib/python3.6/site-packages/rest_framework/views.py", line 502, in dispatch
    response = handler(request, *args, **kwargs)
  File "/home/yudashan/.virtualenvs/Django/lib/python3.6/site-packages/rest_framework/generics.py", line 190, in post
    return self.create(request, *args, **kwargs)
  File "/home/yudashan/.virtualenvs/Django/lib/python3.6/site-packages/rest_framework/mixins.py", line 19, in create
    self.perform_create(serializer)
  File "/home/yudashan/.virtualenvs/Django/lib/python3.6/site-packages/rest_framework/mixins.py", line 24, in perform_create
    serializer.save()
  File "/home/yudashan/.virtualenvs/Django/lib/python3.6/site-packages/rest_framework/serializers.py", line 212, in save
    self.instance = self.create(validated_data)
  File "/home/yudashan/Desktop/Django-project/DRFBlog-2.2/Blog_project/Blog_project/apps/users/serializers.py", line 54, in create
    user = super().create(validated_data)
  File "/home/yudashan/.virtualenvs/Django/lib/python3.6/site-packages/rest_framework/serializers.py", line 967, in create
    raise TypeError(msg)
TypeError: Got a `TypeError` when calling `User.objects.create()`. This may be because you have a writable field on the serializer class that is not a valid argument to `User.objects.create()`. You may need to make the field read-only, or override the UserSerializer.create() method to handle this correctly.
Original exception was:
 Traceback (most recent call last):
  File "/home/yudashan/.virtualenvs/Django/lib/python3.6/site-packages/rest_framework/serializers.py", line 948, in create
    instance = ModelClass._default_manager.create(**validated_data)
  File "/home/yudashan/Desktop/Django-project/DRFBlog-2.2/Blog_project/Blog_project/apps/users/models.py", line 13, in create
    *extra_fields
TypeError: can't multiply sequence by non-int of type 'dict'

ERROR 2020-03-25 11:44:11,663 basehttp 154 "POST /users/register/ HTTP/1.1" 500 22169
ERROR 2020-03-25 11:44:41,033 log 228 Internal Server Error: /users/register/
Traceback (most recent call last):
  File "/home/yudashan/.virtualenvs/Django/lib/python3.6/site-packages/rest_framework/serializers.py", line 948, in create
    instance = ModelClass._default_manager.create(**validated_data)
  File "/home/yudashan/Desktop/Django-project/DRFBlog-2.2/Blog_project/Blog_project/apps/users/models.py", line 13, in create
    **extra_fields
TypeError: unsupported operand type(s) for ** or pow(): 'str' and 'dict'

During handling of the above exception, another exception occurred:

Traceback (most recent call last):
  File "/home/yudashan/.virtualenvs/Django/lib/python3.6/site-packages/django/core/handlers/exception.py", line 34, in inner
    response = get_response(request)
  File "/home/yudashan/.virtualenvs/Django/lib/python3.6/site-packages/django/core/handlers/base.py", line 126, in _get_response
    response = self.process_exception_by_middleware(e, request)
  File "/home/yudashan/.virtualenvs/Django/lib/python3.6/site-packages/django/core/handlers/base.py", line 124, in _get_response
    response = wrapped_callback(request, *callback_args, **callback_kwargs)
  File "/home/yudashan/.virtualenvs/Django/lib/python3.6/site-packages/django/views/decorators/csrf.py", line 54, in wrapped_view
    return view_func(*args, **kwargs)
  File "/home/yudashan/.virtualenvs/Django/lib/python3.6/site-packages/django/views/generic/base.py", line 68, in view
    return self.dispatch(request, *args, **kwargs)
  File "/home/yudashan/.virtualenvs/Django/lib/python3.6/site-packages/rest_framework/views.py", line 505, in dispatch
    response = self.handle_exception(exc)
  File "/home/yudashan/.virtualenvs/Django/lib/python3.6/site-packages/rest_framework/views.py", line 465, in handle_exception
    self.raise_uncaught_exception(exc)
  File "/home/yudashan/.virtualenvs/Django/lib/python3.6/site-packages/rest_framework/views.py", line 476, in raise_uncaught_exception
    raise exc
  File "/home/yudashan/.virtualenvs/Django/lib/python3.6/site-packages/rest_framework/views.py", line 502, in dispatch
    response = handler(request, *args, **kwargs)
  File "/home/yudashan/.virtualenvs/Django/lib/python3.6/site-packages/rest_framework/generics.py", line 190, in post
    return self.create(request, *args, **kwargs)
  File "/home/yudashan/.virtualenvs/Django/lib/python3.6/site-packages/rest_framework/mixins.py", line 19, in create
    self.perform_create(serializer)
  File "/home/yudashan/.virtualenvs/Django/lib/python3.6/site-packages/rest_framework/mixins.py", line 24, in perform_create
    serializer.save()
  File "/home/yudashan/.virtualenvs/Django/lib/python3.6/site-packages/rest_framework/serializers.py", line 212, in save
    self.instance = self.create(validated_data)
  File "/home/yudashan/Desktop/Django-project/DRFBlog-2.2/Blog_project/Blog_project/apps/users/serializers.py", line 54, in create
    user = super().create(validated_data)
  File "/home/yudashan/.virtualenvs/Django/lib/python3.6/site-packages/rest_framework/serializers.py", line 967, in create
    raise TypeError(msg)
TypeError: Got a `TypeError` when calling `User.objects.create()`. This may be because you have a writable field on the serializer class that is not a valid argument to `User.objects.create()`. You may need to make the field read-only, or override the UserSerializer.create() method to handle this correctly.
Original exception was:
 Traceback (most recent call last):
  File "/home/yudashan/.virtualenvs/Django/lib/python3.6/site-packages/rest_framework/serializers.py", line 948, in create
    instance = ModelClass._default_manager.create(**validated_data)
  File "/home/yudashan/Desktop/Django-project/DRFBlog-2.2/Blog_project/Blog_project/apps/users/models.py", line 13, in create
    **extra_fields
TypeError: unsupported operand type(s) for ** or pow(): 'str' and 'dict'

ERROR 2020-03-25 11:44:41,037 basehttp 154 "POST /users/register/ HTTP/1.1" 500 22208
ERROR 2020-03-25 11:45:48,179 log 228 Internal Server Error: /users/register/
Traceback (most recent call last):
  File "/home/yudashan/.virtualenvs/Django/lib/python3.6/site-packages/rest_framework/serializers.py", line 948, in create
    instance = ModelClass._default_manager.create(**validated_data)
  File "/home/yudashan/Desktop/Django-project/DRFBlog-2.2/Blog_project/Blog_project/apps/users/models.py", line 9, in create
    print(**extra_fields)
TypeError: 'mobile' is an invalid keyword argument for this function

During handling of the above exception, another exception occurred:

Traceback (most recent call last):
  File "/home/yudashan/.virtualenvs/Django/lib/python3.6/site-packages/django/core/handlers/exception.py", line 34, in inner
    response = get_response(request)
  File "/home/yudashan/.virtualenvs/Django/lib/python3.6/site-packages/django/core/handlers/base.py", line 126, in _get_response
    response = self.process_exception_by_middleware(e, request)
  File "/home/yudashan/.virtualenvs/Django/lib/python3.6/site-packages/django/core/handlers/base.py", line 124, in _get_response
    response = wrapped_callback(request, *callback_args, **callback_kwargs)
  File "/home/yudashan/.virtualenvs/Django/lib/python3.6/site-packages/django/views/decorators/csrf.py", line 54, in wrapped_view
    return view_func(*args, **kwargs)
  File "/home/yudashan/.virtualenvs/Django/lib/python3.6/site-packages/django/views/generic/base.py", line 68, in view
    return self.dispatch(request, *args, **kwargs)
  File "/home/yudashan/.virtualenvs/Django/lib/python3.6/site-packages/rest_framework/views.py", line 505, in dispatch
    response = self.handle_exception(exc)
  File "/home/yudashan/.virtualenvs/Django/lib/python3.6/site-packages/rest_framework/views.py", line 465, in handle_exception
    self.raise_uncaught_exception(exc)
  File "/home/yudashan/.virtualenvs/Django/lib/python3.6/site-packages/rest_framework/views.py", line 476, in raise_uncaught_exception
    raise exc
  File "/home/yudashan/.virtualenvs/Django/lib/python3.6/site-packages/rest_framework/views.py", line 502, in dispatch
    response = handler(request, *args, **kwargs)
  File "/home/yudashan/.virtualenvs/Django/lib/python3.6/site-packages/rest_framework/generics.py", line 190, in post
    return self.create(request, *args, **kwargs)
  File "/home/yudashan/.virtualenvs/Django/lib/python3.6/site-packages/rest_framework/mixins.py", line 19, in create
    self.perform_create(serializer)
  File "/home/yudashan/.virtualenvs/Django/lib/python3.6/site-packages/rest_framework/mixins.py", line 24, in perform_create
    serializer.save()
  File "/home/yudashan/.virtualenvs/Django/lib/python3.6/site-packages/rest_framework/serializers.py", line 212, in save
    self.instance = self.create(validated_data)
  File "/home/yudashan/Desktop/Django-project/DRFBlog-2.2/Blog_project/Blog_project/apps/users/serializers.py", line 54, in create
    user = super().create(validated_data)
  File "/home/yudashan/.virtualenvs/Django/lib/python3.6/site-packages/rest_framework/serializers.py", line 967, in create
    raise TypeError(msg)
TypeError: Got a `TypeError` when calling `User.objects.create()`. This may be because you have a writable field on the serializer class that is not a valid argument to `User.objects.create()`. You may need to make the field read-only, or override the UserSerializer.create() method to handle this correctly.
Original exception was:
 Traceback (most recent call last):
  File "/home/yudashan/.virtualenvs/Django/lib/python3.6/site-packages/rest_framework/serializers.py", line 948, in create
    instance = ModelClass._default_manager.create(**validated_data)
  File "/home/yudashan/Desktop/Django-project/DRFBlog-2.2/Blog_project/Blog_project/apps/users/models.py", line 9, in create
    print(**extra_fields)
TypeError: 'mobile' is an invalid keyword argument for this function

ERROR 2020-03-25 11:45:48,181 basehttp 154 "POST /users/register/ HTTP/1.1" 500 22210
ERROR 2020-03-25 11:48:19,395 log 228 Internal Server Error: /users/register/
Traceback (most recent call last):
  File "/home/yudashan/.virtualenvs/Django/lib/python3.6/site-packages/rest_framework/serializers.py", line 948, in create
    instance = ModelClass._default_manager.create(**validated_data)
  File "/home/yudashan/Desktop/Django-project/DRFBlog-2.2/Blog_project/Blog_project/apps/users/models.py", line 9, in create
    print(**extra_fields)
TypeError: 'mobile' is an invalid keyword argument for this function

During handling of the above exception, another exception occurred:

Traceback (most recent call last):
  File "/home/yudashan/.virtualenvs/Django/lib/python3.6/site-packages/django/core/handlers/exception.py", line 34, in inner
    response = get_response(request)
  File "/home/yudashan/.virtualenvs/Django/lib/python3.6/site-packages/django/core/handlers/base.py", line 126, in _get_response
    response = self.process_exception_by_middleware(e, request)
  File "/home/yudashan/.virtualenvs/Django/lib/python3.6/site-packages/django/core/handlers/base.py", line 124, in _get_response
    response = wrapped_callback(request, *callback_args, **callback_kwargs)
  File "/home/yudashan/.virtualenvs/Django/lib/python3.6/site-packages/django/views/decorators/csrf.py", line 54, in wrapped_view
    return view_func(*args, **kwargs)
  File "/home/yudashan/.virtualenvs/Django/lib/python3.6/site-packages/django/views/generic/base.py", line 68, in view
    return self.dispatch(request, *args, **kwargs)
  File "/home/yudashan/.virtualenvs/Django/lib/python3.6/site-packages/rest_framework/views.py", line 505, in dispatch
    response = self.handle_exception(exc)
  File "/home/yudashan/.virtualenvs/Django/lib/python3.6/site-packages/rest_framework/views.py", line 465, in handle_exception
    self.raise_uncaught_exception(exc)
  File "/home/yudashan/.virtualenvs/Django/lib/python3.6/site-packages/rest_framework/views.py", line 476, in raise_uncaught_exception
    raise exc
  File "/home/yudashan/.virtualenvs/Django/lib/python3.6/site-packages/rest_framework/views.py", line 502, in dispatch
    response = handler(request, *args, **kwargs)
  File "/home/yudashan/.virtualenvs/Django/lib/python3.6/site-packages/rest_framework/generics.py", line 190, in post
    return self.create(request, *args, **kwargs)
  File "/home/yudashan/.virtualenvs/Django/lib/python3.6/site-packages/rest_framework/mixins.py", line 19, in create
    self.perform_create(serializer)
  File "/home/yudashan/.virtualenvs/Django/lib/python3.6/site-packages/rest_framework/mixins.py", line 24, in perform_create
    serializer.save()
  File "/home/yudashan/.virtualenvs/Django/lib/python3.6/site-packages/rest_framework/serializers.py", line 212, in save
    self.instance = self.create(validated_data)
  File "/home/yudashan/Desktop/Django-project/DRFBlog-2.2/Blog_project/Blog_project/apps/users/serializers.py", line 54, in create
    user = super().create(validated_data)
  File "/home/yudashan/.virtualenvs/Django/lib/python3.6/site-packages/rest_framework/serializers.py", line 967, in create
    raise TypeError(msg)
TypeError: Got a `TypeError` when calling `User.objects.create()`. This may be because you have a writable field on the serializer class that is not a valid argument to `User.objects.create()`. You may need to make the field read-only, or override the UserSerializer.create() method to handle this correctly.
Original exception was:
 Traceback (most recent call last):
  File "/home/yudashan/.virtualenvs/Django/lib/python3.6/site-packages/rest_framework/serializers.py", line 948, in create
    instance = ModelClass._default_manager.create(**validated_data)
  File "/home/yudashan/Desktop/Django-project/DRFBlog-2.2/Blog_project/Blog_project/apps/users/models.py", line 9, in create
    print(**extra_fields)
TypeError: 'mobile' is an invalid keyword argument for this function

ERROR 2020-03-25 11:48:19,397 basehttp 154 "POST /users/register/ HTTP/1.1" 500 22210
ERROR 2020-03-25 11:48:39,435 log 228 Internal Server Error: /users/register/
Traceback (most recent call last):
  File "/home/yudashan/.virtualenvs/Django/lib/python3.6/site-packages/django/core/handlers/exception.py", line 34, in inner
    response = get_response(request)
  File "/home/yudashan/.virtualenvs/Django/lib/python3.6/site-packages/django/core/handlers/base.py", line 126, in _get_response
    response = self.process_exception_by_middleware(e, request)
  File "/home/yudashan/.virtualenvs/Django/lib/python3.6/site-packages/django/core/handlers/base.py", line 124, in _get_response
    response = wrapped_callback(request, *callback_args, **callback_kwargs)
  File "/home/yudashan/.virtualenvs/Django/lib/python3.6/site-packages/django/views/decorators/csrf.py", line 54, in wrapped_view
    return view_func(*args, **kwargs)
  File "/home/yudashan/.virtualenvs/Django/lib/python3.6/site-packages/django/views/generic/base.py", line 68, in view
    return self.dispatch(request, *args, **kwargs)
  File "/home/yudashan/.virtualenvs/Django/lib/python3.6/site-packages/rest_framework/views.py", line 505, in dispatch
    response = self.handle_exception(exc)
  File "/home/yudashan/.virtualenvs/Django/lib/python3.6/site-packages/rest_framework/views.py", line 465, in handle_exception
    self.raise_uncaught_exception(exc)
  File "/home/yudashan/.virtualenvs/Django/lib/python3.6/site-packages/rest_framework/views.py", line 476, in raise_uncaught_exception
    raise exc
  File "/home/yudashan/.virtualenvs/Django/lib/python3.6/site-packages/rest_framework/views.py", line 502, in dispatch
    response = handler(request, *args, **kwargs)
  File "/home/yudashan/.virtualenvs/Django/lib/python3.6/site-packages/rest_framework/generics.py", line 190, in post
    return self.create(request, *args, **kwargs)
  File "/home/yudashan/.virtualenvs/Django/lib/python3.6/site-packages/rest_framework/mixins.py", line 19, in create
    self.perform_create(serializer)
  File "/home/yudashan/.virtualenvs/Django/lib/python3.6/site-packages/rest_framework/mixins.py", line 24, in perform_create
    serializer.save()
  File "/home/yudashan/.virtualenvs/Django/lib/python3.6/site-packages/rest_framework/serializers.py", line 212, in save
    self.instance = self.create(validated_data)
  File "/home/yudashan/Desktop/Django-project/DRFBlog-2.2/Blog_project/Blog_project/apps/users/serializers.py", line 56, in create
    user.save()
AttributeError: 'NoneType' object has no attribute 'save'
ERROR 2020-03-25 11:48:39,437 basehttp 154 "POST /users/register/ HTTP/1.1" 500 20114
WARNING 2020-03-25 11:50:39,218 log 228 Bad Request: /users/register/
WARNING 2020-03-25 11:50:39,219 basehttp 154 "POST /users/register/ HTTP/1.1" 400 55
INFO 2020-03-25 11:50:44,845 basehttp 154 "GET /users/sms/?mobile=18638626521 HTTP/1.1" 200 4
ERROR 2020-03-25 11:50:57,222 log 228 Internal Server Error: /users/register/
Traceback (most recent call last):
  File "/home/yudashan/.virtualenvs/Django/lib/python3.6/site-packages/rest_framework/serializers.py", line 948, in create
    instance = ModelClass._default_manager.create(**validated_data)
  File "/home/yudashan/Desktop/Django-project/DRFBlog-2.2/Blog_project/Blog_project/apps/users/models.py", line 9, in create
    print(**extra_fields)
TypeError: 'mobile' is an invalid keyword argument for this function

During handling of the above exception, another exception occurred:

Traceback (most recent call last):
  File "/home/yudashan/.virtualenvs/Django/lib/python3.6/site-packages/django/core/handlers/exception.py", line 34, in inner
    response = get_response(request)
  File "/home/yudashan/.virtualenvs/Django/lib/python3.6/site-packages/django/core/handlers/base.py", line 126, in _get_response
    response = self.process_exception_by_middleware(e, request)
  File "/home/yudashan/.virtualenvs/Django/lib/python3.6/site-packages/django/core/handlers/base.py", line 124, in _get_response
    response = wrapped_callback(request, *callback_args, **callback_kwargs)
  File "/home/yudashan/.virtualenvs/Django/lib/python3.6/site-packages/django/views/decorators/csrf.py", line 54, in wrapped_view
    return view_func(*args, **kwargs)
  File "/home/yudashan/.virtualenvs/Django/lib/python3.6/site-packages/django/views/generic/base.py", line 68, in view
    return self.dispatch(request, *args, **kwargs)
  File "/home/yudashan/.virtualenvs/Django/lib/python3.6/site-packages/rest_framework/views.py", line 505, in dispatch
    response = self.handle_exception(exc)
  File "/home/yudashan/.virtualenvs/Django/lib/python3.6/site-packages/rest_framework/views.py", line 465, in handle_exception
    self.raise_uncaught_exception(exc)
  File "/home/yudashan/.virtualenvs/Django/lib/python3.6/site-packages/rest_framework/views.py", line 476, in raise_uncaught_exception
    raise exc
  File "/home/yudashan/.virtualenvs/Django/lib/python3.6/site-packages/rest_framework/views.py", line 502, in dispatch
    response = handler(request, *args, **kwargs)
  File "/home/yudashan/.virtualenvs/Django/lib/python3.6/site-packages/rest_framework/generics.py", line 190, in post
    return self.create(request, *args, **kwargs)
  File "/home/yudashan/.virtualenvs/Django/lib/python3.6/site-packages/rest_framework/mixins.py", line 19, in create
    self.perform_create(serializer)
  File "/home/yudashan/.virtualenvs/Django/lib/python3.6/site-packages/rest_framework/mixins.py", line 24, in perform_create
    serializer.save()
  File "/home/yudashan/.virtualenvs/Django/lib/python3.6/site-packages/rest_framework/serializers.py", line 212, in save
    self.instance = self.create(validated_data)
  File "/home/yudashan/Desktop/Django-project/DRFBlog-2.2/Blog_project/Blog_project/apps/users/serializers.py", line 52, in create
    user = super().create(validated_data)
  File "/home/yudashan/.virtualenvs/Django/lib/python3.6/site-packages/rest_framework/serializers.py", line 967, in create
    raise TypeError(msg)
TypeError: Got a `TypeError` when calling `User.objects.create()`. This may be because you have a writable field on the serializer class that is not a valid argument to `User.objects.create()`. You may need to make the field read-only, or override the UserSerializer.create() method to handle this correctly.
Original exception was:
 Traceback (most recent call last):
  File "/home/yudashan/.virtualenvs/Django/lib/python3.6/site-packages/rest_framework/serializers.py", line 948, in create
    instance = ModelClass._default_manager.create(**validated_data)
  File "/home/yudashan/Desktop/Django-project/DRFBlog-2.2/Blog_project/Blog_project/apps/users/models.py", line 9, in create
    print(**extra_fields)
TypeError: 'mobile' is an invalid keyword argument for this function

ERROR 2020-03-25 11:50:57,224 basehttp 154 "POST /users/register/ HTTP/1.1" 500 22210
ERROR 2020-03-25 11:52:01,951 log 228 Internal Server Error: /users/register/
Traceback (most recent call last):
  File "/home/yudashan/.virtualenvs/Django/lib/python3.6/site-packages/django/core/handlers/exception.py", line 34, in inner
    response = get_response(request)
  File "/home/yudashan/.virtualenvs/Django/lib/python3.6/site-packages/django/core/handlers/base.py", line 126, in _get_response
    response = self.process_exception_by_middleware(e, request)
  File "/home/yudashan/.virtualenvs/Django/lib/python3.6/site-packages/django/core/handlers/base.py", line 124, in _get_response
    response = wrapped_callback(request, *callback_args, **callback_kwargs)
  File "/home/yudashan/.virtualenvs/Django/lib/python3.6/site-packages/django/views/decorators/csrf.py", line 54, in wrapped_view
    return view_func(*args, **kwargs)
  File "/home/yudashan/.virtualenvs/Django/lib/python3.6/site-packages/django/views/generic/base.py", line 68, in view
    return self.dispatch(request, *args, **kwargs)
  File "/home/yudashan/.virtualenvs/Django/lib/python3.6/site-packages/rest_framework/views.py", line 505, in dispatch
    response = self.handle_exception(exc)
  File "/home/yudashan/.virtualenvs/Django/lib/python3.6/site-packages/rest_framework/views.py", line 465, in handle_exception
    self.raise_uncaught_exception(exc)
  File "/home/yudashan/.virtualenvs/Django/lib/python3.6/site-packages/rest_framework/views.py", line 476, in raise_uncaught_exception
    raise exc
  File "/home/yudashan/.virtualenvs/Django/lib/python3.6/site-packages/rest_framework/views.py", line 502, in dispatch
    response = handler(request, *args, **kwargs)
  File "/home/yudashan/.virtualenvs/Django/lib/python3.6/site-packages/rest_framework/generics.py", line 190, in post
    return self.create(request, *args, **kwargs)
  File "/home/yudashan/.virtualenvs/Django/lib/python3.6/site-packages/rest_framework/mixins.py", line 19, in create
    self.perform_create(serializer)
  File "/home/yudashan/.virtualenvs/Django/lib/python3.6/site-packages/rest_framework/mixins.py", line 24, in perform_create
    serializer.save()
  File "/home/yudashan/.virtualenvs/Django/lib/python3.6/site-packages/rest_framework/serializers.py", line 214, in save
    '`create()` did not return an object instance.'
AssertionError: `create()` did not return an object instance.
ERROR 2020-03-25 11:52:01,955 basehttp 154 "POST /users/register/ HTTP/1.1" 500 19984
ERROR 2020-03-25 11:52:37,610 log 228 Internal Server Error: /users/register/
Traceback (most recent call last):
  File "/home/yudashan/.virtualenvs/Django/lib/python3.6/site-packages/rest_framework/serializers.py", line 948, in create
    instance = ModelClass._default_manager.create(**validated_data)
  File "/home/yudashan/Desktop/Django-project/DRFBlog-2.2/Blog_project/Blog_project/apps/users/models.py", line 9, in create
    print(type(*extra_fields))
TypeError: type() takes 1 or 3 arguments

During handling of the above exception, another exception occurred:

Traceback (most recent call last):
  File "/home/yudashan/.virtualenvs/Django/lib/python3.6/site-packages/django/core/handlers/exception.py", line 34, in inner
    response = get_response(request)
  File "/home/yudashan/.virtualenvs/Django/lib/python3.6/site-packages/django/core/handlers/base.py", line 126, in _get_response
    response = self.process_exception_by_middleware(e, request)
  File "/home/yudashan/.virtualenvs/Django/lib/python3.6/site-packages/django/core/handlers/base.py", line 124, in _get_response
    response = wrapped_callback(request, *callback_args, **callback_kwargs)
  File "/home/yudashan/.virtualenvs/Django/lib/python3.6/site-packages/django/views/decorators/csrf.py", line 54, in wrapped_view
    return view_func(*args, **kwargs)
  File "/home/yudashan/.virtualenvs/Django/lib/python3.6/site-packages/django/views/generic/base.py", line 68, in view
    return self.dispatch(request, *args, **kwargs)
  File "/home/yudashan/.virtualenvs/Django/lib/python3.6/site-packages/rest_framework/views.py", line 505, in dispatch
    response = self.handle_exception(exc)
  File "/home/yudashan/.virtualenvs/Django/lib/python3.6/site-packages/rest_framework/views.py", line 465, in handle_exception
    self.raise_uncaught_exception(exc)
  File "/home/yudashan/.virtualenvs/Django/lib/python3.6/site-packages/rest_framework/views.py", line 476, in raise_uncaught_exception
    raise exc
  File "/home/yudashan/.virtualenvs/Django/lib/python3.6/site-packages/rest_framework/views.py", line 502, in dispatch
    response = handler(request, *args, **kwargs)
  File "/home/yudashan/.virtualenvs/Django/lib/python3.6/site-packages/rest_framework/generics.py", line 190, in post
    return self.create(request, *args, **kwargs)
  File "/home/yudashan/.virtualenvs/Django/lib/python3.6/site-packages/rest_framework/mixins.py", line 19, in create
    self.perform_create(serializer)
  File "/home/yudashan/.virtualenvs/Django/lib/python3.6/site-packages/rest_framework/mixins.py", line 24, in perform_create
    serializer.save()
  File "/home/yudashan/.virtualenvs/Django/lib/python3.6/site-packages/rest_framework/serializers.py", line 212, in save
    self.instance = self.create(validated_data)
  File "/home/yudashan/Desktop/Django-project/DRFBlog-2.2/Blog_project/Blog_project/apps/users/serializers.py", line 52, in create
    user = super().create(validated_data)
  File "/home/yudashan/.virtualenvs/Django/lib/python3.6/site-packages/rest_framework/serializers.py", line 967, in create
    raise TypeError(msg)
TypeError: Got a `TypeError` when calling `User.objects.create()`. This may be because you have a writable field on the serializer class that is not a valid argument to `User.objects.create()`. You may need to make the field read-only, or override the UserSerializer.create() method to handle this correctly.
Original exception was:
 Traceback (most recent call last):
  File "/home/yudashan/.virtualenvs/Django/lib/python3.6/site-packages/rest_framework/serializers.py", line 948, in create
    instance = ModelClass._default_manager.create(**validated_data)
  File "/home/yudashan/Desktop/Django-project/DRFBlog-2.2/Blog_project/Blog_project/apps/users/models.py", line 9, in create
    print(type(*extra_fields))
TypeError: type() takes 1 or 3 arguments

ERROR 2020-03-25 11:52:37,613 basehttp 154 "POST /users/register/ HTTP/1.1" 500 22141
ERROR 2020-03-25 11:53:33,698 log 228 Internal Server Error: /users/register/
Traceback (most recent call last):
  File "/home/yudashan/.virtualenvs/Django/lib/python3.6/site-packages/rest_framework/serializers.py", line 948, in create
    instance = ModelClass._default_manager.create(**validated_data)
  File "/home/yudashan/Desktop/Django-project/DRFBlog-2.2/Blog_project/Blog_project/apps/users/models.py", line 9, in create
    print(type(**extra_fields))
TypeError: type() takes 1 or 3 arguments

During handling of the above exception, another exception occurred:

Traceback (most recent call last):
  File "/home/yudashan/.virtualenvs/Django/lib/python3.6/site-packages/django/core/handlers/exception.py", line 34, in inner
    response = get_response(request)
  File "/home/yudashan/.virtualenvs/Django/lib/python3.6/site-packages/django/core/handlers/base.py", line 126, in _get_response
    response = self.process_exception_by_middleware(e, request)
  File "/home/yudashan/.virtualenvs/Django/lib/python3.6/site-packages/django/core/handlers/base.py", line 124, in _get_response
    response = wrapped_callback(request, *callback_args, **callback_kwargs)
  File "/home/yudashan/.virtualenvs/Django/lib/python3.6/site-packages/django/views/decorators/csrf.py", line 54, in wrapped_view
    return view_func(*args, **kwargs)
  File "/home/yudashan/.virtualenvs/Django/lib/python3.6/site-packages/django/views/generic/base.py", line 68, in view
    return self.dispatch(request, *args, **kwargs)
  File "/home/yudashan/.virtualenvs/Django/lib/python3.6/site-packages/rest_framework/views.py", line 505, in dispatch
    response = self.handle_exception(exc)
  File "/home/yudashan/.virtualenvs/Django/lib/python3.6/site-packages/rest_framework/views.py", line 465, in handle_exception
    self.raise_uncaught_exception(exc)
  File "/home/yudashan/.virtualenvs/Django/lib/python3.6/site-packages/rest_framework/views.py", line 476, in raise_uncaught_exception
    raise exc
  File "/home/yudashan/.virtualenvs/Django/lib/python3.6/site-packages/rest_framework/views.py", line 502, in dispatch
    response = handler(request, *args, **kwargs)
  File "/home/yudashan/.virtualenvs/Django/lib/python3.6/site-packages/rest_framework/generics.py", line 190, in post
    return self.create(request, *args, **kwargs)
  File "/home/yudashan/.virtualenvs/Django/lib/python3.6/site-packages/rest_framework/mixins.py", line 19, in create
    self.perform_create(serializer)
  File "/home/yudashan/.virtualenvs/Django/lib/python3.6/site-packages/rest_framework/mixins.py", line 24, in perform_create
    serializer.save()
  File "/home/yudashan/.virtualenvs/Django/lib/python3.6/site-packages/rest_framework/serializers.py", line 212, in save
    self.instance = self.create(validated_data)
  File "/home/yudashan/Desktop/Django-project/DRFBlog-2.2/Blog_project/Blog_project/apps/users/serializers.py", line 52, in create
    user = super().create(validated_data)
  File "/home/yudashan/.virtualenvs/Django/lib/python3.6/site-packages/rest_framework/serializers.py", line 967, in create
    raise TypeError(msg)
TypeError: Got a `TypeError` when calling `User.objects.create()`. This may be because you have a writable field on the serializer class that is not a valid argument to `User.objects.create()`. You may need to make the field read-only, or override the UserSerializer.create() method to handle this correctly.
Original exception was:
 Traceback (most recent call last):
  File "/home/yudashan/.virtualenvs/Django/lib/python3.6/site-packages/rest_framework/serializers.py", line 948, in create
    instance = ModelClass._default_manager.create(**validated_data)
  File "/home/yudashan/Desktop/Django-project/DRFBlog-2.2/Blog_project/Blog_project/apps/users/models.py", line 9, in create
    print(type(**extra_fields))
TypeError: type() takes 1 or 3 arguments

ERROR 2020-03-25 11:53:33,703 basehttp 154 "POST /users/register/ HTTP/1.1" 500 22144
ERROR 2020-03-25 11:55:33,053 log 228 Internal Server Error: /users/register/
Traceback (most recent call last):
  File "/home/yudashan/.virtualenvs/Django/lib/python3.6/site-packages/django/core/handlers/exception.py", line 34, in inner
    response = get_response(request)
  File "/home/yudashan/.virtualenvs/Django/lib/python3.6/site-packages/django/core/handlers/base.py", line 126, in _get_response
    response = self.process_exception_by_middleware(e, request)
  File "/home/yudashan/.virtualenvs/Django/lib/python3.6/site-packages/django/core/handlers/base.py", line 124, in _get_response
    response = wrapped_callback(request, *callback_args, **callback_kwargs)
  File "/home/yudashan/.virtualenvs/Django/lib/python3.6/site-packages/django/views/decorators/csrf.py", line 54, in wrapped_view
    return view_func(*args, **kwargs)
  File "/home/yudashan/.virtualenvs/Django/lib/python3.6/site-packages/django/views/generic/base.py", line 68, in view
    return self.dispatch(request, *args, **kwargs)
  File "/home/yudashan/.virtualenvs/Django/lib/python3.6/site-packages/rest_framework/views.py", line 505, in dispatch
    response = self.handle_exception(exc)
  File "/home/yudashan/.virtualenvs/Django/lib/python3.6/site-packages/rest_framework/views.py", line 465, in handle_exception
    self.raise_uncaught_exception(exc)
  File "/home/yudashan/.virtualenvs/Django/lib/python3.6/site-packages/rest_framework/views.py", line 476, in raise_uncaught_exception
    raise exc
  File "/home/yudashan/.virtualenvs/Django/lib/python3.6/site-packages/rest_framework/views.py", line 502, in dispatch
    response = handler(request, *args, **kwargs)
  File "/home/yudashan/.virtualenvs/Django/lib/python3.6/site-packages/rest_framework/generics.py", line 190, in post
    return self.create(request, *args, **kwargs)
  File "/home/yudashan/.virtualenvs/Django/lib/python3.6/site-packages/rest_framework/mixins.py", line 19, in create
    self.perform_create(serializer)
  File "/home/yudashan/.virtualenvs/Django/lib/python3.6/site-packages/rest_framework/mixins.py", line 24, in perform_create
    serializer.save()
  File "/home/yudashan/.virtualenvs/Django/lib/python3.6/site-packages/rest_framework/serializers.py", line 214, in save
    '`create()` did not return an object instance.'
AssertionError: `create()` did not return an object instance.
ERROR 2020-03-25 11:55:33,056 basehttp 154 "POST /users/register/ HTTP/1.1" 500 19984
WARNING 2020-03-25 11:56:43,094 log 228 Bad Request: /users/register/
WARNING 2020-03-25 11:56:43,095 basehttp 154 "POST /users/register/ HTTP/1.1" 400 55
INFO 2020-03-25 11:56:50,490 basehttp 154 "GET /users/sms/?mobile=18638626521 HTTP/1.1" 200 4
ERROR 2020-03-25 11:57:03,978 log 228 Internal Server Error: /users/register/
Traceback (most recent call last):
  File "/home/yudashan/.virtualenvs/Django/lib/python3.6/site-packages/rest_framework/serializers.py", line 948, in create
    instance = ModelClass._default_manager.create(**validated_data)
  File "/home/yudashan/Desktop/Django-project/DRFBlog-2.2/Blog_project/Blog_project/apps/users/models.py", line 10, in create
    print(mobile["mobile"], password)
TypeError: string indices must be integers

During handling of the above exception, another exception occurred:

Traceback (most recent call last):
  File "/home/yudashan/.virtualenvs/Django/lib/python3.6/site-packages/django/core/handlers/exception.py", line 34, in inner
    response = get_response(request)
  File "/home/yudashan/.virtualenvs/Django/lib/python3.6/site-packages/django/core/handlers/base.py", line 126, in _get_response
    response = self.process_exception_by_middleware(e, request)
  File "/home/yudashan/.virtualenvs/Django/lib/python3.6/site-packages/django/core/handlers/base.py", line 124, in _get_response
    response = wrapped_callback(request, *callback_args, **callback_kwargs)
  File "/home/yudashan/.virtualenvs/Django/lib/python3.6/site-packages/django/views/decorators/csrf.py", line 54, in wrapped_view
    return view_func(*args, **kwargs)
  File "/home/yudashan/.virtualenvs/Django/lib/python3.6/site-packages/django/views/generic/base.py", line 68, in view
    return self.dispatch(request, *args, **kwargs)
  File "/home/yudashan/.virtualenvs/Django/lib/python3.6/site-packages/rest_framework/views.py", line 505, in dispatch
    response = self.handle_exception(exc)
  File "/home/yudashan/.virtualenvs/Django/lib/python3.6/site-packages/rest_framework/views.py", line 465, in handle_exception
    self.raise_uncaught_exception(exc)
  File "/home/yudashan/.virtualenvs/Django/lib/python3.6/site-packages/rest_framework/views.py", line 476, in raise_uncaught_exception
    raise exc
  File "/home/yudashan/.virtualenvs/Django/lib/python3.6/site-packages/rest_framework/views.py", line 502, in dispatch
    response = handler(request, *args, **kwargs)
  File "/home/yudashan/.virtualenvs/Django/lib/python3.6/site-packages/rest_framework/generics.py", line 190, in post
    return self.create(request, *args, **kwargs)
  File "/home/yudashan/.virtualenvs/Django/lib/python3.6/site-packages/rest_framework/mixins.py", line 19, in create
    self.perform_create(serializer)
  File "/home/yudashan/.virtualenvs/Django/lib/python3.6/site-packages/rest_framework/mixins.py", line 24, in perform_create
    serializer.save()
  File "/home/yudashan/.virtualenvs/Django/lib/python3.6/site-packages/rest_framework/serializers.py", line 212, in save
    self.instance = self.create(validated_data)
  File "/home/yudashan/Desktop/Django-project/DRFBlog-2.2/Blog_project/Blog_project/apps/users/serializers.py", line 52, in create
    user = super().create(validated_data)
  File "/home/yudashan/.virtualenvs/Django/lib/python3.6/site-packages/rest_framework/serializers.py", line 967, in create
    raise TypeError(msg)
TypeError: Got a `TypeError` when calling `User.objects.create()`. This may be because you have a writable field on the serializer class that is not a valid argument to `User.objects.create()`. You may need to make the field read-only, or override the UserSerializer.create() method to handle this correctly.
Original exception was:
 Traceback (most recent call last):
  File "/home/yudashan/.virtualenvs/Django/lib/python3.6/site-packages/rest_framework/serializers.py", line 948, in create
    instance = ModelClass._default_manager.create(**validated_data)
  File "/home/yudashan/Desktop/Django-project/DRFBlog-2.2/Blog_project/Blog_project/apps/users/models.py", line 10, in create
    print(mobile["mobile"], password)
TypeError: string indices must be integers

ERROR 2020-03-25 11:57:03,981 basehttp 154 "POST /users/register/ HTTP/1.1" 500 22171
ERROR 2020-03-25 11:57:36,131 log 228 Internal Server Error: /users/register/
Traceback (most recent call last):
  File "/home/yudashan/.virtualenvs/Django/lib/python3.6/site-packages/rest_framework/serializers.py", line 948, in create
    instance = ModelClass._default_manager.create(**validated_data)
  File "/home/yudashan/Desktop/Django-project/DRFBlog-2.2/Blog_project/Blog_project/apps/users/models.py", line 10, in create
    print(mobile["mobile"])
TypeError: string indices must be integers

During handling of the above exception, another exception occurred:

Traceback (most recent call last):
  File "/home/yudashan/.virtualenvs/Django/lib/python3.6/site-packages/django/core/handlers/exception.py", line 34, in inner
    response = get_response(request)
  File "/home/yudashan/.virtualenvs/Django/lib/python3.6/site-packages/django/core/handlers/base.py", line 126, in _get_response
    response = self.process_exception_by_middleware(e, request)
  File "/home/yudashan/.virtualenvs/Django/lib/python3.6/site-packages/django/core/handlers/base.py", line 124, in _get_response
    response = wrapped_callback(request, *callback_args, **callback_kwargs)
  File "/home/yudashan/.virtualenvs/Django/lib/python3.6/site-packages/django/views/decorators/csrf.py", line 54, in wrapped_view
    return view_func(*args, **kwargs)
  File "/home/yudashan/.virtualenvs/Django/lib/python3.6/site-packages/django/views/generic/base.py", line 68, in view
    return self.dispatch(request, *args, **kwargs)
  File "/home/yudashan/.virtualenvs/Django/lib/python3.6/site-packages/rest_framework/views.py", line 505, in dispatch
    response = self.handle_exception(exc)
  File "/home/yudashan/.virtualenvs/Django/lib/python3.6/site-packages/rest_framework/views.py", line 465, in handle_exception
    self.raise_uncaught_exception(exc)
  File "/home/yudashan/.virtualenvs/Django/lib/python3.6/site-packages/rest_framework/views.py", line 476, in raise_uncaught_exception
    raise exc
  File "/home/yudashan/.virtualenvs/Django/lib/python3.6/site-packages/rest_framework/views.py", line 502, in dispatch
    response = handler(request, *args, **kwargs)
  File "/home/yudashan/.virtualenvs/Django/lib/python3.6/site-packages/rest_framework/generics.py", line 190, in post
    return self.create(request, *args, **kwargs)
  File "/home/yudashan/.virtualenvs/Django/lib/python3.6/site-packages/rest_framework/mixins.py", line 19, in create
    self.perform_create(serializer)
  File "/home/yudashan/.virtualenvs/Django/lib/python3.6/site-packages/rest_framework/mixins.py", line 24, in perform_create
    serializer.save()
  File "/home/yudashan/.virtualenvs/Django/lib/python3.6/site-packages/rest_framework/serializers.py", line 212, in save
    self.instance = self.create(validated_data)
  File "/home/yudashan/Desktop/Django-project/DRFBlog-2.2/Blog_project/Blog_project/apps/users/serializers.py", line 52, in create
    user = super().create(validated_data)
  File "/home/yudashan/.virtualenvs/Django/lib/python3.6/site-packages/rest_framework/serializers.py", line 967, in create
    raise TypeError(msg)
TypeError: Got a `TypeError` when calling `User.objects.create()`. This may be because you have a writable field on the serializer class that is not a valid argument to `User.objects.create()`. You may need to make the field read-only, or override the UserSerializer.create() method to handle this correctly.
Original exception was:
 Traceback (most recent call last):
  File "/home/yudashan/.virtualenvs/Django/lib/python3.6/site-packages/rest_framework/serializers.py", line 948, in create
    instance = ModelClass._default_manager.create(**validated_data)
  File "/home/yudashan/Desktop/Django-project/DRFBlog-2.2/Blog_project/Blog_project/apps/users/models.py", line 10, in create
    print(mobile["mobile"])
TypeError: string indices must be integers

ERROR 2020-03-25 11:57:36,134 basehttp 154 "POST /users/register/ HTTP/1.1" 500 22141
ERROR 2020-03-25 11:58:12,601 log 228 Internal Server Error: /users/register/
Traceback (most recent call last):
  File "/home/yudashan/.virtualenvs/Django/lib/python3.6/site-packages/django/core/handlers/exception.py", line 34, in inner
    response = get_response(request)
  File "/home/yudashan/.virtualenvs/Django/lib/python3.6/site-packages/django/core/handlers/base.py", line 126, in _get_response
    response = self.process_exception_by_middleware(e, request)
  File "/home/yudashan/.virtualenvs/Django/lib/python3.6/site-packages/django/core/handlers/base.py", line 124, in _get_response
    response = wrapped_callback(request, *callback_args, **callback_kwargs)
  File "/home/yudashan/.virtualenvs/Django/lib/python3.6/site-packages/django/views/decorators/csrf.py", line 54, in wrapped_view
    return view_func(*args, **kwargs)
  File "/home/yudashan/.virtualenvs/Django/lib/python3.6/site-packages/django/views/generic/base.py", line 68, in view
    return self.dispatch(request, *args, **kwargs)
  File "/home/yudashan/.virtualenvs/Django/lib/python3.6/site-packages/rest_framework/views.py", line 505, in dispatch
    response = self.handle_exception(exc)
  File "/home/yudashan/.virtualenvs/Django/lib/python3.6/site-packages/rest_framework/views.py", line 465, in handle_exception
    self.raise_uncaught_exception(exc)
  File "/home/yudashan/.virtualenvs/Django/lib/python3.6/site-packages/rest_framework/views.py", line 476, in raise_uncaught_exception
    raise exc
  File "/home/yudashan/.virtualenvs/Django/lib/python3.6/site-packages/rest_framework/views.py", line 502, in dispatch
    response = handler(request, *args, **kwargs)
  File "/home/yudashan/.virtualenvs/Django/lib/python3.6/site-packages/rest_framework/generics.py", line 190, in post
    return self.create(request, *args, **kwargs)
  File "/home/yudashan/.virtualenvs/Django/lib/python3.6/site-packages/rest_framework/mixins.py", line 19, in create
    self.perform_create(serializer)
  File "/home/yudashan/.virtualenvs/Django/lib/python3.6/site-packages/rest_framework/mixins.py", line 24, in perform_create
    serializer.save()
  File "/home/yudashan/.virtualenvs/Django/lib/python3.6/site-packages/rest_framework/serializers.py", line 214, in save
    '`create()` did not return an object instance.'
AssertionError: `create()` did not return an object instance.
ERROR 2020-03-25 11:58:12,604 basehttp 154 "POST /users/register/ HTTP/1.1" 500 19984
ERROR 2020-03-25 12:01:40,434 log 228 Internal Server Error: /users/register/
Traceback (most recent call last):
  File "/home/yudashan/.virtualenvs/Django/lib/python3.6/site-packages/rest_framework/serializers.py", line 948, in create
    instance = ModelClass._default_manager.create(**validated_data)
  File "/home/yudashan/Desktop/Django-project/DRFBlog-2.2/Blog_project/Blog_project/apps/users/models.py", line 15, in create
    user.set_password(extra_fields.get("password"), "")
TypeError: set_password() takes 2 positional arguments but 3 were given

During handling of the above exception, another exception occurred:

Traceback (most recent call last):
  File "/home/yudashan/.virtualenvs/Django/lib/python3.6/site-packages/django/core/handlers/exception.py", line 34, in inner
    response = get_response(request)
  File "/home/yudashan/.virtualenvs/Django/lib/python3.6/site-packages/django/core/handlers/base.py", line 126, in _get_response
    response = self.process_exception_by_middleware(e, request)
  File "/home/yudashan/.virtualenvs/Django/lib/python3.6/site-packages/django/core/handlers/base.py", line 124, in _get_response
    response = wrapped_callback(request, *callback_args, **callback_kwargs)
  File "/home/yudashan/.virtualenvs/Django/lib/python3.6/site-packages/django/views/decorators/csrf.py", line 54, in wrapped_view
    return view_func(*args, **kwargs)
  File "/home/yudashan/.virtualenvs/Django/lib/python3.6/site-packages/django/views/generic/base.py", line 68, in view
    return self.dispatch(request, *args, **kwargs)
  File "/home/yudashan/.virtualenvs/Django/lib/python3.6/site-packages/rest_framework/views.py", line 505, in dispatch
    response = self.handle_exception(exc)
  File "/home/yudashan/.virtualenvs/Django/lib/python3.6/site-packages/rest_framework/views.py", line 465, in handle_exception
    self.raise_uncaught_exception(exc)
  File "/home/yudashan/.virtualenvs/Django/lib/python3.6/site-packages/rest_framework/views.py", line 476, in raise_uncaught_exception
    raise exc
  File "/home/yudashan/.virtualenvs/Django/lib/python3.6/site-packages/rest_framework/views.py", line 502, in dispatch
    response = handler(request, *args, **kwargs)
  File "/home/yudashan/.virtualenvs/Django/lib/python3.6/site-packages/rest_framework/generics.py", line 190, in post
    return self.create(request, *args, **kwargs)
  File "/home/yudashan/.virtualenvs/Django/lib/python3.6/site-packages/rest_framework/mixins.py", line 19, in create
    self.perform_create(serializer)
  File "/home/yudashan/.virtualenvs/Django/lib/python3.6/site-packages/rest_framework/mixins.py", line 24, in perform_create
    serializer.save()
  File "/home/yudashan/.virtualenvs/Django/lib/python3.6/site-packages/rest_framework/serializers.py", line 212, in save
    self.instance = self.create(validated_data)
  File "/home/yudashan/Desktop/Django-project/DRFBlog-2.2/Blog_project/Blog_project/apps/users/serializers.py", line 52, in create
    user = super().create(validated_data)
  File "/home/yudashan/.virtualenvs/Django/lib/python3.6/site-packages/rest_framework/serializers.py", line 967, in create
    raise TypeError(msg)
TypeError: Got a `TypeError` when calling `User.objects.create()`. This may be because you have a writable field on the serializer class that is not a valid argument to `User.objects.create()`. You may need to make the field read-only, or override the UserSerializer.create() method to handle this correctly.
Original exception was:
 Traceback (most recent call last):
  File "/home/yudashan/.virtualenvs/Django/lib/python3.6/site-packages/rest_framework/serializers.py", line 948, in create
    instance = ModelClass._default_manager.create(**validated_data)
  File "/home/yudashan/Desktop/Django-project/DRFBlog-2.2/Blog_project/Blog_project/apps/users/models.py", line 15, in create
    user.set_password(extra_fields.get("password"), "")
TypeError: set_password() takes 2 positional arguments but 3 were given

ERROR 2020-03-25 12:01:40,437 basehttp 154 "POST /users/register/ HTTP/1.1" 500 22312
WARNING 2020-03-25 12:02:07,582 log 228 Bad Request: /users/register/
WARNING 2020-03-25 12:02:07,583 basehttp 154 "POST /users/register/ HTTP/1.1" 400 55
INFO 2020-03-25 12:02:12,266 basehttp 154 "GET /users/sms/?mobile=18638626521 HTTP/1.1" 200 4
INFO 2020-03-25 12:02:30,478 basehttp 154 "POST /users/register/ HTTP/1.1" 201 40
INFO 2020-03-25 13:06:44,476 basehttp 154 "GET /users/sms/?mobile=18638626520 HTTP/1.1" 200 4
INFO 2020-03-25 13:06:59,305 basehttp 154 "POST /users/register/ HTTP/1.1" 201 40
INFO 2020-03-25 13:07:47,387 basehttp 154 "GET /users/sms/?mobile=18638626523 HTTP/1.1" 200 4
INFO 2020-03-25 13:08:03,417 basehttp 154 "POST /users/register/ HTTP/1.1" 201 40
INFO 2020-03-25 13:16:09,811 basehttp 154 "GET /users/sms/?mobile=18638626524 HTTP/1.1" 200 4
INFO 2020-03-25 13:16:31,166 basehttp 154 "POST /users/register/ HTTP/1.1" 201 40
INFO 2020-03-25 13:18:06,956 basehttp 154 "GET /users/sms/?mobile=18638626526 HTTP/1.1" 200 4
INFO 2020-03-25 13:18:19,132 basehttp 154 "POST /users/register/ HTTP/1.1" 201 40
WARNING 2020-03-25 13:19:03,220 log 228 Bad Request: /users/register/
WARNING 2020-03-25 13:19:03,221 basehttp 154 "POST /users/register/ HTTP/1.1" 400 55
INFO 2020-03-25 13:19:17,274 basehttp 154 "GET /users/sms/?mobile=18638626528 HTTP/1.1" 200 4
INFO 2020-03-25 13:19:26,656 basehttp 154 "POST /users/register/ HTTP/1.1" 201 40
INFO 2020-03-25 13:27:15,232 basehttp 154 "GET /users/sms/?mobile=18638626529 HTTP/1.1" 200 4
ERROR 2020-03-25 13:28:06,634 log 228 Internal Server Error: /users/register/
Traceback (most recent call last):
  File "/home/yudashan/.virtualenvs/Django/lib/python3.6/site-packages/django/core/handlers/exception.py", line 34, in inner
    response = get_response(request)
  File "/home/yudashan/.virtualenvs/Django/lib/python3.6/site-packages/django/core/handlers/base.py", line 126, in _get_response
    response = self.process_exception_by_middleware(e, request)
  File "/home/yudashan/.virtualenvs/Django/lib/python3.6/site-packages/django/core/handlers/base.py", line 124, in _get_response
    response = wrapped_callback(request, *callback_args, **callback_kwargs)
  File "/home/yudashan/.virtualenvs/Django/lib/python3.6/site-packages/django/views/decorators/csrf.py", line 54, in wrapped_view
    return view_func(*args, **kwargs)
  File "/home/yudashan/.virtualenvs/Django/lib/python3.6/site-packages/django/views/generic/base.py", line 68, in view
    return self.dispatch(request, *args, **kwargs)
  File "/home/yudashan/.virtualenvs/Django/lib/python3.6/site-packages/rest_framework/views.py", line 505, in dispatch
    response = self.handle_exception(exc)
  File "/home/yudashan/.virtualenvs/Django/lib/python3.6/site-packages/rest_framework/views.py", line 465, in handle_exception
    self.raise_uncaught_exception(exc)
  File "/home/yudashan/.virtualenvs/Django/lib/python3.6/site-packages/rest_framework/views.py", line 476, in raise_uncaught_exception
    raise exc
  File "/home/yudashan/.virtualenvs/Django/lib/python3.6/site-packages/rest_framework/views.py", line 502, in dispatch
    response = handler(request, *args, **kwargs)
  File "/home/yudashan/.virtualenvs/Django/lib/python3.6/site-packages/rest_framework/generics.py", line 190, in post
    return self.create(request, *args, **kwargs)
  File "/home/yudashan/.virtualenvs/Django/lib/python3.6/site-packages/rest_framework/mixins.py", line 18, in create
    serializer.is_valid(raise_exception=True)
  File "/home/yudashan/.virtualenvs/Django/lib/python3.6/site-packages/rest_framework/serializers.py", line 234, in is_valid
    self._validated_data = self.run_validation(self.initial_data)
  File "/home/yudashan/.virtualenvs/Django/lib/python3.6/site-packages/rest_framework/serializers.py", line 433, in run_validation
    value = self.to_internal_value(data)
  File "/home/yudashan/.virtualenvs/Django/lib/python3.6/site-packages/rest_framework/serializers.py", line 486, in to_internal_value
    for field in fields:
  File "/home/yudashan/.virtualenvs/Django/lib/python3.6/site-packages/rest_framework/serializers.py", line 369, in _writable_fields
    for field in self.fields.values():
  File "/home/yudashan/.virtualenvs/Django/lib/python3.6/site-packages/django/utils/functional.py", line 37, in __get__
    res = instance.__dict__[self.name] = self.func(instance)
  File "/home/yudashan/.virtualenvs/Django/lib/python3.6/site-packages/rest_framework/serializers.py", line 363, in fields
    for key, value in self.get_fields().items():
  File "/home/yudashan/.virtualenvs/Django/lib/python3.6/site-packages/rest_framework/serializers.py", line 1038, in get_fields
    field_names = self.get_field_names(declared_fields, info)
  File "/home/yudashan/.virtualenvs/Django/lib/python3.6/site-packages/rest_framework/serializers.py", line 1139, in get_field_names
    serializer_class=self.__class__.__name__
AssertionError: The field 'token' was declared on serializer UserSerializer, but has not been included in the 'fields' option.
ERROR 2020-03-25 13:28:06,638 basehttp 154 "POST /users/register/ HTTP/1.1" 500 21496
INFO 2020-03-25 13:28:48,844 basehttp 154 "POST /users/register/ HTTP/1.1" 201 251
WARNING 2020-03-25 14:13:08,415 log 228 Bad Request: /users/login/
WARNING 2020-03-25 14:13:08,416 basehttp 154 "POST /users/login/ HTTP/1.1" 400 67
WARNING 2020-03-25 14:14:31,230 log 228 Bad Request: /users/login/
WARNING 2020-03-25 14:14:31,231 basehttp 154 "POST /users/login/ HTTP/1.1" 400 67
WARNING 2020-03-25 14:15:45,619 log 228 Bad Request: /users/login/
WARNING 2020-03-25 14:15:45,620 basehttp 154 "POST /users/login/ HTTP/1.1" 400 67
INFO 2020-03-25 14:17:17,638 basehttp 154 "POST /users/login/ HTTP/1.1" 200 212
INFO 2020-03-25 14:17:34,746 basehttp 154 "POST /users/login/ HTTP/1.1" 200 212
INFO 2020-03-25 14:17:45,032 basehttp 154 "POST /users/login/ HTTP/1.1" 200 212
INFO 2020-03-25 14:19:09,657 basehttp 154 "POST /users/login/ HTTP/1.1" 200 212
INFO 2020-03-25 14:19:39,703 basehttp 154 "POST /users/login/ HTTP/1.1" 200 212
INFO 2020-03-25 14:20:57,224 basehttp 154 "POST /users/login/ HTTP/1.1" 200 212
INFO 2020-03-25 14:21:12,442 basehttp 154 "POST /users/login/ HTTP/1.1" 200 212
INFO 2020-03-25 14:21:36,248 basehttp 154 "POST /users/login/ HTTP/1.1" 200 212
INFO 2020-03-25 14:22:04,898 basehttp 154 "POST /users/login/ HTTP/1.1" 200 212
INFO 2020-03-25 14:22:24,244 basehttp 154 "POST /users/login/ HTTP/1.1" 200 212
INFO 2020-03-25 14:22:43,323 basehttp 154 "POST /users/login/ HTTP/1.1" 200 212
INFO 2020-03-25 14:30:26,490 basehttp 154 "POST /users/login/ HTTP/1.1" 200 212
INFO 2020-03-25 14:32:55,357 basehttp 154 "POST /users/login/ HTTP/1.1" 200 212
INFO 2020-03-25 14:33:12,080 basehttp 154 "POST /users/login/ HTTP/1.1" 200 212
ERROR 2020-03-25 14:34:13,095 log 228 Internal Server Error: /users/login/
Traceback (most recent call last):
  File "/home/yudashan/.virtualenvs/Django/lib/python3.6/site-packages/rest_framework/fields.py", line 454, in get_attribute
    return get_attribute(instance, self.source_attrs)
  File "/home/yudashan/.virtualenvs/Django/lib/python3.6/site-packages/rest_framework/fields.py", line 92, in get_attribute
    instance = instance[attr]
KeyError: 'mobile'

During handling of the above exception, another exception occurred:

Traceback (most recent call last):
  File "/home/yudashan/.virtualenvs/Django/lib/python3.6/site-packages/django/core/handlers/exception.py", line 34, in inner
    response = get_response(request)
  File "/home/yudashan/.virtualenvs/Django/lib/python3.6/site-packages/django/core/handlers/base.py", line 126, in _get_response
    response = self.process_exception_by_middleware(e, request)
  File "/home/yudashan/.virtualenvs/Django/lib/python3.6/site-packages/django/core/handlers/base.py", line 124, in _get_response
    response = wrapped_callback(request, *callback_args, **callback_kwargs)
  File "/home/yudashan/.virtualenvs/Django/lib/python3.6/site-packages/django/views/decorators/csrf.py", line 54, in wrapped_view
    return view_func(*args, **kwargs)
  File "/home/yudashan/.virtualenvs/Django/lib/python3.6/site-packages/django/views/generic/base.py", line 68, in view
    return self.dispatch(request, *args, **kwargs)
  File "/home/yudashan/.virtualenvs/Django/lib/python3.6/site-packages/rest_framework/views.py", line 505, in dispatch
    response = self.handle_exception(exc)
  File "/home/yudashan/.virtualenvs/Django/lib/python3.6/site-packages/rest_framework/views.py", line 465, in handle_exception
    self.raise_uncaught_exception(exc)
  File "/home/yudashan/.virtualenvs/Django/lib/python3.6/site-packages/rest_framework/views.py", line 476, in raise_uncaught_exception
    raise exc
  File "/home/yudashan/.virtualenvs/Django/lib/python3.6/site-packages/rest_framework/views.py", line 502, in dispatch
    response = handler(request, *args, **kwargs)
  File "/home/yudashan/.virtualenvs/Django/lib/python3.6/site-packages/rest_framework_jwt/views.py", line 62, in post
    print(serializer.data)
  File "/home/yudashan/.virtualenvs/Django/lib/python3.6/site-packages/rest_framework/serializers.py", line 562, in data
    ret = super().data
  File "/home/yudashan/.virtualenvs/Django/lib/python3.6/site-packages/rest_framework/serializers.py", line 262, in data
    self._data = self.to_representation(self.validated_data)
  File "/home/yudashan/.virtualenvs/Django/lib/python3.6/site-packages/rest_framework/serializers.py", line 516, in to_representation
    attribute = field.get_attribute(instance)
  File "/home/yudashan/.virtualenvs/Django/lib/python3.6/site-packages/rest_framework/fields.py", line 487, in get_attribute
    raise type(exc)(msg)
KeyError: "Got KeyError when attempting to get a value for field `mobile` on serializer `JSONWebTokenSerializer`.\nThe serializer field might be named incorrectly and not match any attribute or key on the `dict` instance.\nOriginal exception text was: 'mobile'."
ERROR 2020-03-25 14:34:13,102 basehttp 154 "POST /users/login/ HTTP/1.1" 500 21184
ERROR 2020-03-25 14:36:11,769 log 228 Internal Server Error: /users/login/
Traceback (most recent call last):
  File "/home/yudashan/.virtualenvs/Django/lib/python3.6/site-packages/django/core/handlers/exception.py", line 34, in inner
    response = get_response(request)
  File "/home/yudashan/.virtualenvs/Django/lib/python3.6/site-packages/django/core/handlers/base.py", line 126, in _get_response
    response = self.process_exception_by_middleware(e, request)
  File "/home/yudashan/.virtualenvs/Django/lib/python3.6/site-packages/django/core/handlers/base.py", line 124, in _get_response
    response = wrapped_callback(request, *callback_args, **callback_kwargs)
  File "/home/yudashan/.virtualenvs/Django/lib/python3.6/site-packages/django/views/decorators/csrf.py", line 54, in wrapped_view
    return view_func(*args, **kwargs)
  File "/home/yudashan/.virtualenvs/Django/lib/python3.6/site-packages/django/views/generic/base.py", line 68, in view
    return self.dispatch(request, *args, **kwargs)
  File "/home/yudashan/.virtualenvs/Django/lib/python3.6/site-packages/rest_framework/views.py", line 505, in dispatch
    response = self.handle_exception(exc)
  File "/home/yudashan/.virtualenvs/Django/lib/python3.6/site-packages/rest_framework/views.py", line 465, in handle_exception
    self.raise_uncaught_exception(exc)
  File "/home/yudashan/.virtualenvs/Django/lib/python3.6/site-packages/rest_framework/views.py", line 476, in raise_uncaught_exception
    raise exc
  File "/home/yudashan/.virtualenvs/Django/lib/python3.6/site-packages/rest_framework/views.py", line 502, in dispatch
    response = handler(request, *args, **kwargs)
  File "/home/yudashan/.virtualenvs/Django/lib/python3.6/site-packages/rest_framework_jwt/views.py", line 63, in post
    print(s.data)
AttributeError: 'function' object has no attribute 'data'
ERROR 2020-03-25 14:36:11,772 basehttp 154 "POST /users/login/ HTTP/1.1" 500 19670
ERROR 2020-03-25 14:36:42,998 log 228 Internal Server Error: /users/login/
Traceback (most recent call last):
  File "/home/yudashan/.virtualenvs/Django/lib/python3.6/site-packages/django/core/handlers/exception.py", line 34, in inner
    response = get_response(request)
  File "/home/yudashan/.virtualenvs/Django/lib/python3.6/site-packages/django/core/handlers/base.py", line 126, in _get_response
    response = self.process_exception_by_middleware(e, request)
  File "/home/yudashan/.virtualenvs/Django/lib/python3.6/site-packages/django/core/handlers/base.py", line 124, in _get_response
    response = wrapped_callback(request, *callback_args, **callback_kwargs)
  File "/home/yudashan/.virtualenvs/Django/lib/python3.6/site-packages/django/views/decorators/csrf.py", line 54, in wrapped_view
    return view_func(*args, **kwargs)
  File "/home/yudashan/.virtualenvs/Django/lib/python3.6/site-packages/django/views/generic/base.py", line 68, in view
    return self.dispatch(request, *args, **kwargs)
  File "/home/yudashan/.virtualenvs/Django/lib/python3.6/site-packages/rest_framework/views.py", line 505, in dispatch
    response = self.handle_exception(exc)
  File "/home/yudashan/.virtualenvs/Django/lib/python3.6/site-packages/rest_framework/views.py", line 465, in handle_exception
    self.raise_uncaught_exception(exc)
  File "/home/yudashan/.virtualenvs/Django/lib/python3.6/site-packages/rest_framework/views.py", line 476, in raise_uncaught_exception
    raise exc
  File "/home/yudashan/.virtualenvs/Django/lib/python3.6/site-packages/rest_framework/views.py", line 502, in dispatch
    response = handler(request, *args, **kwargs)
  File "/home/yudashan/.virtualenvs/Django/lib/python3.6/site-packages/rest_framework_jwt/views.py", line 63, in post
    print(s.data)
AttributeError: 'bool' object has no attribute 'data'
ERROR 2020-03-25 14:36:43,001 basehttp 154 "POST /users/login/ HTTP/1.1" 500 19662
ERROR 2020-03-25 14:40:00,153 log 228 Internal Server Error: /users/login/
Traceback (most recent call last):
  File "/home/yudashan/.virtualenvs/Django/lib/python3.6/site-packages/django/core/handlers/exception.py", line 34, in inner
    response = get_response(request)
  File "/home/yudashan/.virtualenvs/Django/lib/python3.6/site-packages/django/core/handlers/base.py", line 126, in _get_response
    response = self.process_exception_by_middleware(e, request)
  File "/home/yudashan/.virtualenvs/Django/lib/python3.6/site-packages/django/core/handlers/base.py", line 124, in _get_response
    response = wrapped_callback(request, *callback_args, **callback_kwargs)
  File "/home/yudashan/.virtualenvs/Django/lib/python3.6/site-packages/django/views/decorators/csrf.py", line 54, in wrapped_view
    return view_func(*args, **kwargs)
  File "/home/yudashan/.virtualenvs/Django/lib/python3.6/site-packages/django/views/generic/base.py", line 68, in view
    return self.dispatch(request, *args, **kwargs)
  File "/home/yudashan/.virtualenvs/Django/lib/python3.6/site-packages/rest_framework/views.py", line 505, in dispatch
    response = self.handle_exception(exc)
  File "/home/yudashan/.virtualenvs/Django/lib/python3.6/site-packages/rest_framework/views.py", line 465, in handle_exception
    self.raise_uncaught_exception(exc)
  File "/home/yudashan/.virtualenvs/Django/lib/python3.6/site-packages/rest_framework/views.py", line 476, in raise_uncaught_exception
    raise exc
  File "/home/yudashan/.virtualenvs/Django/lib/python3.6/site-packages/rest_framework/views.py", line 502, in dispatch
    response = handler(request, *args, **kwargs)
  File "/home/yudashan/.virtualenvs/Django/lib/python3.6/site-packages/rest_framework_jwt/views.py", line 56, in post
    print(serializer.data)
  File "/home/yudashan/.virtualenvs/Django/lib/python3.6/site-packages/rest_framework/serializers.py", line 562, in data
    ret = super().data
  File "/home/yudashan/.virtualenvs/Django/lib/python3.6/site-packages/rest_framework/serializers.py", line 256, in data
    raise AssertionError(msg)
AssertionError: When a serializer is passed a `data` keyword argument you must call `.is_valid()` before attempting to access the serialized `.data` representation.
You should either call `.is_valid()` first, or access `.initial_data` instead.
ERROR 2020-03-25 14:40:00,157 basehttp 154 "POST /users/login/ HTTP/1.1" 500 20344
ERROR 2020-03-25 14:41:35,160 log 228 Internal Server Error: /users/login/
Traceback (most recent call last):
  File "/home/yudashan/.virtualenvs/Django/lib/python3.6/site-packages/rest_framework/fields.py", line 454, in get_attribute
    return get_attribute(instance, self.source_attrs)
  File "/home/yudashan/.virtualenvs/Django/lib/python3.6/site-packages/rest_framework/fields.py", line 92, in get_attribute
    instance = instance[attr]
KeyError: 'mobile'

During handling of the above exception, another exception occurred:

Traceback (most recent call last):
  File "/home/yudashan/.virtualenvs/Django/lib/python3.6/site-packages/django/core/handlers/exception.py", line 34, in inner
    response = get_response(request)
  File "/home/yudashan/.virtualenvs/Django/lib/python3.6/site-packages/django/core/handlers/base.py", line 126, in _get_response
    response = self.process_exception_by_middleware(e, request)
  File "/home/yudashan/.virtualenvs/Django/lib/python3.6/site-packages/django/core/handlers/base.py", line 124, in _get_response
    response = wrapped_callback(request, *callback_args, **callback_kwargs)
  File "/home/yudashan/.virtualenvs/Django/lib/python3.6/site-packages/django/views/decorators/csrf.py", line 54, in wrapped_view
    return view_func(*args, **kwargs)
  File "/home/yudashan/.virtualenvs/Django/lib/python3.6/site-packages/django/views/generic/base.py", line 68, in view
    return self.dispatch(request, *args, **kwargs)
  File "/home/yudashan/.virtualenvs/Django/lib/python3.6/site-packages/rest_framework/views.py", line 505, in dispatch
    response = self.handle_exception(exc)
  File "/home/yudashan/.virtualenvs/Django/lib/python3.6/site-packages/rest_framework/views.py", line 465, in handle_exception
    self.raise_uncaught_exception(exc)
  File "/home/yudashan/.virtualenvs/Django/lib/python3.6/site-packages/rest_framework/views.py", line 476, in raise_uncaught_exception
    raise exc
  File "/home/yudashan/.virtualenvs/Django/lib/python3.6/site-packages/rest_framework/views.py", line 502, in dispatch
    response = handler(request, *args, **kwargs)
  File "/home/yudashan/.virtualenvs/Django/lib/python3.6/site-packages/rest_framework_jwt/views.py", line 57, in post
    print(serializer.data)
  File "/home/yudashan/.virtualenvs/Django/lib/python3.6/site-packages/rest_framework/serializers.py", line 562, in data
    ret = super().data
  File "/home/yudashan/.virtualenvs/Django/lib/python3.6/site-packages/rest_framework/serializers.py", line 262, in data
    self._data = self.to_representation(self.validated_data)
  File "/home/yudashan/.virtualenvs/Django/lib/python3.6/site-packages/rest_framework/serializers.py", line 516, in to_representation
    attribute = field.get_attribute(instance)
  File "/home/yudashan/.virtualenvs/Django/lib/python3.6/site-packages/rest_framework/fields.py", line 487, in get_attribute
    raise type(exc)(msg)
KeyError: "Got KeyError when attempting to get a value for field `mobile` on serializer `JSONWebTokenSerializer`.\nThe serializer field might be named incorrectly and not match any attribute or key on the `dict` instance.\nOriginal exception text was: 'mobile'."
ERROR 2020-03-25 14:41:35,163 basehttp 154 "POST /users/login/ HTTP/1.1" 500 21180
INFO 2020-03-25 14:47:40,855 basehttp 154 "POST /users/login/ HTTP/1.1" 200 212
ERROR 2020-03-25 14:48:43,741 log 228 Internal Server Error: /users/login/
Traceback (most recent call last):
  File "/home/yudashan/.virtualenvs/Django/lib/python3.6/site-packages/rest_framework/fields.py", line 454, in get_attribute
    return get_attribute(instance, self.source_attrs)
  File "/home/yudashan/.virtualenvs/Django/lib/python3.6/site-packages/rest_framework/fields.py", line 92, in get_attribute
    instance = instance[attr]
KeyError: 'mobile'

During handling of the above exception, another exception occurred:

Traceback (most recent call last):
  File "/home/yudashan/.virtualenvs/Django/lib/python3.6/site-packages/django/core/handlers/exception.py", line 34, in inner
    response = get_response(request)
  File "/home/yudashan/.virtualenvs/Django/lib/python3.6/site-packages/django/core/handlers/base.py", line 126, in _get_response
    response = self.process_exception_by_middleware(e, request)
  File "/home/yudashan/.virtualenvs/Django/lib/python3.6/site-packages/django/core/handlers/base.py", line 124, in _get_response
    response = wrapped_callback(request, *callback_args, **callback_kwargs)
  File "/home/yudashan/.virtualenvs/Django/lib/python3.6/site-packages/django/views/decorators/csrf.py", line 54, in wrapped_view
    return view_func(*args, **kwargs)
  File "/home/yudashan/.virtualenvs/Django/lib/python3.6/site-packages/django/views/generic/base.py", line 68, in view
    return self.dispatch(request, *args, **kwargs)
  File "/home/yudashan/.virtualenvs/Django/lib/python3.6/site-packages/rest_framework/views.py", line 505, in dispatch
    response = self.handle_exception(exc)
  File "/home/yudashan/.virtualenvs/Django/lib/python3.6/site-packages/rest_framework/views.py", line 465, in handle_exception
    self.raise_uncaught_exception(exc)
  File "/home/yudashan/.virtualenvs/Django/lib/python3.6/site-packages/rest_framework/views.py", line 476, in raise_uncaught_exception
    raise exc
  File "/home/yudashan/.virtualenvs/Django/lib/python3.6/site-packages/rest_framework/views.py", line 502, in dispatch
    response = handler(request, *args, **kwargs)
  File "/home/yudashan/.virtualenvs/Django/lib/python3.6/site-packages/rest_framework_jwt/views.py", line 57, in post
    print(serializer.data)
  File "/home/yudashan/.virtualenvs/Django/lib/python3.6/site-packages/rest_framework/serializers.py", line 562, in data
    ret = super().data
  File "/home/yudashan/.virtualenvs/Django/lib/python3.6/site-packages/rest_framework/serializers.py", line 262, in data
    self._data = self.to_representation(self.validated_data)
  File "/home/yudashan/.virtualenvs/Django/lib/python3.6/site-packages/rest_framework/serializers.py", line 516, in to_representation
    attribute = field.get_attribute(instance)
  File "/home/yudashan/.virtualenvs/Django/lib/python3.6/site-packages/rest_framework/fields.py", line 487, in get_attribute
    raise type(exc)(msg)
KeyError: "Got KeyError when attempting to get a value for field `mobile` on serializer `JSONWebTokenSerializer`.\nThe serializer field might be named incorrectly and not match any attribute or key on the `dict` instance.\nOriginal exception text was: 'mobile'."
ERROR 2020-03-25 14:48:43,749 basehttp 154 "POST /users/login/ HTTP/1.1" 500 21198
INFO 2020-03-25 14:51:56,283 basehttp 154 "POST /users/login/ HTTP/1.1" 200 212
INFO 2020-03-25 15:03:00,166 basehttp 154 "GET /users/sms/?mobile=18638626519 HTTP/1.1" 200 4
WARNING 2020-03-25 15:03:19,450 log 228 Bad Request: /users/login/
WARNING 2020-03-25 15:03:19,451 basehttp 154 "POST /users/login/ HTTP/1.1" 400 67
WARNING 2020-03-25 15:04:24,047 log 228 Method Not Allowed: /users/register/
WARNING 2020-03-25 15:04:24,048 basehttp 154 "GET /users/register/?mibile=18638626519&password=123456&password2=123456&allow=true&sms_code=367356 HTTP/1.1" 405 45
WARNING 2020-03-25 15:04:28,993 log 228 Bad Request: /users/register/
WARNING 2020-03-25 15:04:28,993 basehttp 154 "POST /users/register/?mibile=18638626519&password=123456&password2=123456&allow=true&sms_code=367356 HTTP/1.1" 400 197
WARNING 2020-03-25 15:05:20,807 log 228 Bad Request: /users/register/
WARNING 2020-03-25 15:05:20,808 basehttp 154 "POST /users/register/?mibile=18638626519&password=123456&password2=123456&allow=true&sms_code=367356 HTTP/1.1" 400 197
WARNING 2020-03-25 15:05:52,353 log 228 Bad Request: /users/register/
WARNING 2020-03-25 15:05:52,354 basehttp 154 "POST /users/register/?mobile=18638626519&password=123456&password2=123456&allow=true&sms_code=367356 HTTP/1.1" 400 197
INFO 2020-03-25 15:08:15,372 basehttp 154 "GET /users/sms/?mobile=18638626519 HTTP/1.1" 200 4
INFO 2020-03-25 15:08:28,957 basehttp 154 "POST /users/register/ HTTP/1.1" 201 251
INFO 2020-03-25 15:09:47,658 basehttp 154 "GET /users/sms/?mobile=18638626529 HTTP/1.1" 200 4
WARNING 2020-03-25 15:10:03,150 log 228 Bad Request: /users/register/
WARNING 2020-03-25 15:10:03,154 basehttp 154 "POST /users/register/ HTTP/1.1" 400 55
INFO 2020-03-25 15:10:30,908 basehttp 154 "GET /users/sms/?mobile=18638626539 HTTP/1.1" 200 4
INFO 2020-03-25 15:10:48,289 basehttp 154 "POST /users/register/ HTTP/1.1" 201 265
WARNING 2020-03-25 16:14:53,522 log 228 Bad Request: /users/register/
WARNING 2020-03-25 16:14:53,523 basehttp 154 "POST /users/register/ HTTP/1.1" 400 55
ERROR 2020-03-25 16:16:28,656 log 228 Internal Server Error: /users/register/
Traceback (most recent call last):
  File "/home/yudashan/.virtualenvs/Django/lib/python3.6/site-packages/django/core/handlers/exception.py", line 34, in inner
    response = get_response(request)
  File "/home/yudashan/.virtualenvs/Django/lib/python3.6/site-packages/django/core/handlers/base.py", line 126, in _get_response
    response = self.process_exception_by_middleware(e, request)
  File "/home/yudashan/.virtualenvs/Django/lib/python3.6/site-packages/django/core/handlers/base.py", line 124, in _get_response
    response = wrapped_callback(request, *callback_args, **callback_kwargs)
  File "/home/yudashan/.virtualenvs/Django/lib/python3.6/site-packages/django/views/decorators/csrf.py", line 54, in wrapped_view
    return view_func(*args, **kwargs)
  File "/home/yudashan/.virtualenvs/Django/lib/python3.6/site-packages/django/views/generic/base.py", line 68, in view
    return self.dispatch(request, *args, **kwargs)
  File "/home/yudashan/.virtualenvs/Django/lib/python3.6/site-packages/rest_framework/views.py", line 505, in dispatch
    response = self.handle_exception(exc)
  File "/home/yudashan/.virtualenvs/Django/lib/python3.6/site-packages/rest_framework/views.py", line 465, in handle_exception
    self.raise_uncaught_exception(exc)
  File "/home/yudashan/.virtualenvs/Django/lib/python3.6/site-packages/rest_framework/views.py", line 476, in raise_uncaught_exception
    raise exc
  File "/home/yudashan/.virtualenvs/Django/lib/python3.6/site-packages/rest_framework/views.py", line 502, in dispatch
    response = handler(request, *args, **kwargs)
  File "/home/yudashan/.virtualenvs/Django/lib/python3.6/site-packages/rest_framework/generics.py", line 190, in post
    return self.create(request, *args, **kwargs)
  File "/home/yudashan/.virtualenvs/Django/lib/python3.6/site-packages/rest_framework/mixins.py", line 19, in create
    self.perform_create(serializer)
  File "/home/yudashan/.virtualenvs/Django/lib/python3.6/site-packages/rest_framework/mixins.py", line 24, in perform_create
    serializer.save()
  File "/home/yudashan/.virtualenvs/Django/lib/python3.6/site-packages/rest_framework/serializers.py", line 212, in save
    self.instance = self.create(validated_data)
  File "/home/yudashan/Desktop/Django-project/DRFBlog-2.2/Blog_project/Blog_project/apps/users/serializers.py", line 56, in create
    print(validated_data.dict())
AttributeError: 'dict' object has no attribute 'dict'
ERROR 2020-03-25 16:16:28,660 basehttp 154 "POST /users/register/ HTTP/1.1" 500 20390
ERROR 2020-03-25 16:17:20,632 log 228 Internal Server Error: /users/register/
Traceback (most recent call last):
  File "/home/yudashan/.virtualenvs/Django/lib/python3.6/site-packages/rest_framework/fields.py", line 454, in get_attribute
    return get_attribute(instance, self.source_attrs)
  File "/home/yudashan/.virtualenvs/Django/lib/python3.6/site-packages/rest_framework/fields.py", line 94, in get_attribute
    instance = getattr(instance, attr)
AttributeError: 'str' object has no attribute 'mobile'

During handling of the above exception, another exception occurred:

Traceback (most recent call last):
  File "/home/yudashan/.virtualenvs/Django/lib/python3.6/site-packages/django/core/handlers/exception.py", line 34, in inner
    response = get_response(request)
  File "/home/yudashan/.virtualenvs/Django/lib/python3.6/site-packages/django/core/handlers/base.py", line 126, in _get_response
    response = self.process_exception_by_middleware(e, request)
  File "/home/yudashan/.virtualenvs/Django/lib/python3.6/site-packages/django/core/handlers/base.py", line 124, in _get_response
    response = wrapped_callback(request, *callback_args, **callback_kwargs)
  File "/home/yudashan/.virtualenvs/Django/lib/python3.6/site-packages/django/views/decorators/csrf.py", line 54, in wrapped_view
    return view_func(*args, **kwargs)
  File "/home/yudashan/.virtualenvs/Django/lib/python3.6/site-packages/django/views/generic/base.py", line 68, in view
    return self.dispatch(request, *args, **kwargs)
  File "/home/yudashan/.virtualenvs/Django/lib/python3.6/site-packages/rest_framework/views.py", line 505, in dispatch
    response = self.handle_exception(exc)
  File "/home/yudashan/.virtualenvs/Django/lib/python3.6/site-packages/rest_framework/views.py", line 465, in handle_exception
    self.raise_uncaught_exception(exc)
  File "/home/yudashan/.virtualenvs/Django/lib/python3.6/site-packages/rest_framework/views.py", line 476, in raise_uncaught_exception
    raise exc
  File "/home/yudashan/.virtualenvs/Django/lib/python3.6/site-packages/rest_framework/views.py", line 502, in dispatch
    response = handler(request, *args, **kwargs)
  File "/home/yudashan/.virtualenvs/Django/lib/python3.6/site-packages/rest_framework/generics.py", line 190, in post
    return self.create(request, *args, **kwargs)
  File "/home/yudashan/.virtualenvs/Django/lib/python3.6/site-packages/rest_framework/mixins.py", line 20, in create
    headers = self.get_success_headers(serializer.data)
  File "/home/yudashan/.virtualenvs/Django/lib/python3.6/site-packages/rest_framework/serializers.py", line 562, in data
    ret = super().data
  File "/home/yudashan/.virtualenvs/Django/lib/python3.6/site-packages/rest_framework/serializers.py", line 260, in data
    self._data = self.to_representation(self.instance)
  File "/home/yudashan/.virtualenvs/Django/lib/python3.6/site-packages/rest_framework/serializers.py", line 516, in to_representation
    attribute = field.get_attribute(instance)
  File "/home/yudashan/.virtualenvs/Django/lib/python3.6/site-packages/rest_framework/fields.py", line 487, in get_attribute
    raise type(exc)(msg)
AttributeError: Got AttributeError when attempting to get a value for field `mobile` on serializer `UserSerializer`.
The serializer field might be named incorrectly and not match any attribute or key on the `str` instance.
Original exception text was: 'str' object has no attribute 'mobile'.
ERROR 2020-03-25 16:17:20,635 basehttp 154 "POST /users/register/ HTTP/1.1" 500 21533
ERROR 2020-03-25 16:18:29,101 log 228 Internal Server Error: /users/register/
Traceback (most recent call last):
  File "/home/yudashan/.virtualenvs/Django/lib/python3.6/site-packages/rest_framework/fields.py", line 454, in get_attribute
    return get_attribute(instance, self.source_attrs)
  File "/home/yudashan/.virtualenvs/Django/lib/python3.6/site-packages/rest_framework/fields.py", line 94, in get_attribute
    instance = getattr(instance, attr)
AttributeError: 'str' object has no attribute 'mobile'

During handling of the above exception, another exception occurred:

Traceback (most recent call last):
  File "/home/yudashan/.virtualenvs/Django/lib/python3.6/site-packages/django/core/handlers/exception.py", line 34, in inner
    response = get_response(request)
  File "/home/yudashan/.virtualenvs/Django/lib/python3.6/site-packages/django/core/handlers/base.py", line 126, in _get_response
    response = self.process_exception_by_middleware(e, request)
  File "/home/yudashan/.virtualenvs/Django/lib/python3.6/site-packages/django/core/handlers/base.py", line 124, in _get_response
    response = wrapped_callback(request, *callback_args, **callback_kwargs)
  File "/home/yudashan/.virtualenvs/Django/lib/python3.6/site-packages/django/views/decorators/csrf.py", line 54, in wrapped_view
    return view_func(*args, **kwargs)
  File "/home/yudashan/.virtualenvs/Django/lib/python3.6/site-packages/django/views/generic/base.py", line 68, in view
    return self.dispatch(request, *args, **kwargs)
  File "/home/yudashan/.virtualenvs/Django/lib/python3.6/site-packages/rest_framework/views.py", line 505, in dispatch
    response = self.handle_exception(exc)
  File "/home/yudashan/.virtualenvs/Django/lib/python3.6/site-packages/rest_framework/views.py", line 465, in handle_exception
    self.raise_uncaught_exception(exc)
  File "/home/yudashan/.virtualenvs/Django/lib/python3.6/site-packages/rest_framework/views.py", line 476, in raise_uncaught_exception
    raise exc
  File "/home/yudashan/.virtualenvs/Django/lib/python3.6/site-packages/rest_framework/views.py", line 502, in dispatch
    response = handler(request, *args, **kwargs)
  File "/home/yudashan/.virtualenvs/Django/lib/python3.6/site-packages/rest_framework/generics.py", line 190, in post
    return self.create(request, *args, **kwargs)
  File "/home/yudashan/.virtualenvs/Django/lib/python3.6/site-packages/rest_framework/mixins.py", line 20, in create
    headers = self.get_success_headers(serializer.data)
  File "/home/yudashan/.virtualenvs/Django/lib/python3.6/site-packages/rest_framework/serializers.py", line 562, in data
    ret = super().data
  File "/home/yudashan/.virtualenvs/Django/lib/python3.6/site-packages/rest_framework/serializers.py", line 260, in data
    self._data = self.to_representation(self.instance)
  File "/home/yudashan/.virtualenvs/Django/lib/python3.6/site-packages/rest_framework/serializers.py", line 516, in to_representation
    attribute = field.get_attribute(instance)
  File "/home/yudashan/.virtualenvs/Django/lib/python3.6/site-packages/rest_framework/fields.py", line 487, in get_attribute
    raise type(exc)(msg)
AttributeError: Got AttributeError when attempting to get a value for field `mobile` on serializer `UserSerializer`.
The serializer field might be named incorrectly and not match any attribute or key on the `str` instance.
Original exception text was: 'str' object has no attribute 'mobile'.
ERROR 2020-03-25 16:18:29,105 basehttp 154 "POST /users/register/ HTTP/1.1" 500 21533
ERROR 2020-03-25 16:19:31,953 log 228 Internal Server Error: /users/register/
Traceback (most recent call last):
  File "/home/yudashan/.virtualenvs/Django/lib/python3.6/site-packages/rest_framework/fields.py", line 454, in get_attribute
    return get_attribute(instance, self.source_attrs)
  File "/home/yudashan/.virtualenvs/Django/lib/python3.6/site-packages/rest_framework/fields.py", line 94, in get_attribute
    instance = getattr(instance, attr)
AttributeError: 'str' object has no attribute 'mobile'

During handling of the above exception, another exception occurred:

Traceback (most recent call last):
  File "/home/yudashan/.virtualenvs/Django/lib/python3.6/site-packages/django/core/handlers/exception.py", line 34, in inner
    response = get_response(request)
  File "/home/yudashan/.virtualenvs/Django/lib/python3.6/site-packages/django/core/handlers/base.py", line 126, in _get_response
    response = self.process_exception_by_middleware(e, request)
  File "/home/yudashan/.virtualenvs/Django/lib/python3.6/site-packages/django/core/handlers/base.py", line 124, in _get_response
    response = wrapped_callback(request, *callback_args, **callback_kwargs)
  File "/home/yudashan/.virtualenvs/Django/lib/python3.6/site-packages/django/views/decorators/csrf.py", line 54, in wrapped_view
    return view_func(*args, **kwargs)
  File "/home/yudashan/.virtualenvs/Django/lib/python3.6/site-packages/django/views/generic/base.py", line 68, in view
    return self.dispatch(request, *args, **kwargs)
  File "/home/yudashan/.virtualenvs/Django/lib/python3.6/site-packages/rest_framework/views.py", line 505, in dispatch
    response = self.handle_exception(exc)
  File "/home/yudashan/.virtualenvs/Django/lib/python3.6/site-packages/rest_framework/views.py", line 465, in handle_exception
    self.raise_uncaught_exception(exc)
  File "/home/yudashan/.virtualenvs/Django/lib/python3.6/site-packages/rest_framework/views.py", line 476, in raise_uncaught_exception
    raise exc
  File "/home/yudashan/.virtualenvs/Django/lib/python3.6/site-packages/rest_framework/views.py", line 502, in dispatch
    response = handler(request, *args, **kwargs)
  File "/home/yudashan/.virtualenvs/Django/lib/python3.6/site-packages/rest_framework/generics.py", line 190, in post
    return self.create(request, *args, **kwargs)
  File "/home/yudashan/.virtualenvs/Django/lib/python3.6/site-packages/rest_framework/mixins.py", line 20, in create
    headers = self.get_success_headers(serializer.data)
  File "/home/yudashan/.virtualenvs/Django/lib/python3.6/site-packages/rest_framework/serializers.py", line 562, in data
    ret = super().data
  File "/home/yudashan/.virtualenvs/Django/lib/python3.6/site-packages/rest_framework/serializers.py", line 260, in data
    self._data = self.to_representation(self.instance)
  File "/home/yudashan/.virtualenvs/Django/lib/python3.6/site-packages/rest_framework/serializers.py", line 516, in to_representation
    attribute = field.get_attribute(instance)
  File "/home/yudashan/.virtualenvs/Django/lib/python3.6/site-packages/rest_framework/fields.py", line 487, in get_attribute
    raise type(exc)(msg)
AttributeError: Got AttributeError when attempting to get a value for field `mobile` on serializer `UserSerializer`.
The serializer field might be named incorrectly and not match any attribute or key on the `str` instance.
Original exception text was: 'str' object has no attribute 'mobile'.
ERROR 2020-03-25 16:19:31,957 basehttp 154 "POST /users/register/ HTTP/1.1" 500 21533
ERROR 2020-03-25 16:22:11,343 log 228 Internal Server Error: /users/register/
Traceback (most recent call last):
  File "/home/yudashan/.virtualenvs/Django/lib/python3.6/site-packages/rest_framework/serializers.py", line 948, in create
    instance = ModelClass._default_manager.create(**validated_data)
  File "/home/yudashan/Desktop/Django-project/DRFBlog-2.2/Blog_project/Blog_project/apps/users/models.py", line 13, in create
    **extra_fields
  File "/home/yudashan/.virtualenvs/Django/lib/python3.6/site-packages/django/db/models/base.py", line 485, in __init__
    raise TypeError("'%s' is an invalid keyword argument for this function" % kwarg)
TypeError: 'register_time' is an invalid keyword argument for this function

During handling of the above exception, another exception occurred:

Traceback (most recent call last):
  File "/home/yudashan/.virtualenvs/Django/lib/python3.6/site-packages/django/core/handlers/exception.py", line 34, in inner
    response = get_response(request)
  File "/home/yudashan/.virtualenvs/Django/lib/python3.6/site-packages/django/core/handlers/base.py", line 126, in _get_response
    response = self.process_exception_by_middleware(e, request)
  File "/home/yudashan/.virtualenvs/Django/lib/python3.6/site-packages/django/core/handlers/base.py", line 124, in _get_response
    response = wrapped_callback(request, *callback_args, **callback_kwargs)
  File "/home/yudashan/.virtualenvs/Django/lib/python3.6/site-packages/django/views/decorators/csrf.py", line 54, in wrapped_view
    return view_func(*args, **kwargs)
  File "/home/yudashan/.virtualenvs/Django/lib/python3.6/site-packages/django/views/generic/base.py", line 68, in view
    return self.dispatch(request, *args, **kwargs)
  File "/home/yudashan/.virtualenvs/Django/lib/python3.6/site-packages/rest_framework/views.py", line 505, in dispatch
    response = self.handle_exception(exc)
  File "/home/yudashan/.virtualenvs/Django/lib/python3.6/site-packages/rest_framework/views.py", line 465, in handle_exception
    self.raise_uncaught_exception(exc)
  File "/home/yudashan/.virtualenvs/Django/lib/python3.6/site-packages/rest_framework/views.py", line 476, in raise_uncaught_exception
    raise exc
  File "/home/yudashan/.virtualenvs/Django/lib/python3.6/site-packages/rest_framework/views.py", line 502, in dispatch
    response = handler(request, *args, **kwargs)
  File "/home/yudashan/.virtualenvs/Django/lib/python3.6/site-packages/rest_framework/generics.py", line 190, in post
    return self.create(request, *args, **kwargs)
  File "/home/yudashan/.virtualenvs/Django/lib/python3.6/site-packages/rest_framework/mixins.py", line 19, in create
    self.perform_create(serializer)
  File "/home/yudashan/.virtualenvs/Django/lib/python3.6/site-packages/rest_framework/mixins.py", line 24, in perform_create
    serializer.save()
  File "/home/yudashan/.virtualenvs/Django/lib/python3.6/site-packages/rest_framework/serializers.py", line 212, in save
    self.instance = self.create(validated_data)
  File "/home/yudashan/Desktop/Django-project/DRFBlog-2.2/Blog_project/Blog_project/apps/users/serializers.py", line 60, in create
    user = super().create(validated_data)
  File "/home/yudashan/.virtualenvs/Django/lib/python3.6/site-packages/rest_framework/serializers.py", line 967, in create
    raise TypeError(msg)
TypeError: Got a `TypeError` when calling `User.objects.create()`. This may be because you have a writable field on the serializer class that is not a valid argument to `User.objects.create()`. You may need to make the field read-only, or override the UserSerializer.create() method to handle this correctly.
Original exception was:
 Traceback (most recent call last):
  File "/home/yudashan/.virtualenvs/Django/lib/python3.6/site-packages/rest_framework/serializers.py", line 948, in create
    instance = ModelClass._default_manager.create(**validated_data)
  File "/home/yudashan/Desktop/Django-project/DRFBlog-2.2/Blog_project/Blog_project/apps/users/models.py", line 13, in create
    **extra_fields
  File "/home/yudashan/.virtualenvs/Django/lib/python3.6/site-packages/django/db/models/base.py", line 485, in __init__
    raise TypeError("'%s' is an invalid keyword argument for this function" % kwarg)
TypeError: 'register_time' is an invalid keyword argument for this function

ERROR 2020-03-25 16:22:11,346 basehttp 154 "POST /users/register/ HTTP/1.1" 500 23106
WARNING 2020-03-25 17:41:25,869 log 228 Unauthorized: /users/info/
WARNING 2020-03-25 17:41:25,870 basehttp 154 "GET /users/info/ HTTP/1.1" 401 43
INFO 2020-03-25 17:41:52,482 basehttp 154 "POST /users/login/ HTTP/1.1" 200 212
WARNING 2020-03-25 17:42:02,700 log 228 Unauthorized: /users/info/
WARNING 2020-03-25 17:42:02,701 basehttp 154 "GET /users/info/ HTTP/1.1" 401 43
WARNING 2020-03-25 17:42:21,515 log 228 Unauthorized: /users/info/
WARNING 2020-03-25 17:42:21,516 basehttp 154 "GET /users/info/ HTTP/1.1" 401 43
WARNING 2020-03-25 17:45:06,747 log 228 Unauthorized: /users/info/
WARNING 2020-03-25 17:45:06,747 basehttp 154 "GET /users/info/?mobile=18638626519 HTTP/1.1" 401 43
WARNING 2020-03-25 17:45:29,907 log 228 Unauthorized: /users/info/
WARNING 2020-03-25 17:45:29,908 basehttp 154 "GET /users/info/?mobile=18638626519&username HTTP/1.1" 401 43
WARNING 2020-03-25 17:50:59,587 log 228 Unauthorized: /users/info/
WARNING 2020-03-25 17:50:59,588 basehttp 154 "GET /users/info/ HTTP/1.1" 401 43
INFO 2020-03-25 17:51:09,083 basehttp 154 "POST /users/login/ HTTP/1.1" 200 212
WARNING 2020-03-25 17:51:53,928 log 228 Unauthorized: /users/info/
WARNING 2020-03-25 17:51:53,929 basehttp 154 "GET /users/info/ HTTP/1.1" 401 43
INFO 2020-03-25 17:52:03,028 basehttp 154 "POST /users/login/ HTTP/1.1" 200 212
WARNING 2020-03-25 17:52:13,270 log 228 Unauthorized: /users/info/
WARNING 2020-03-25 17:52:13,271 basehttp 154 "GET /users/info/ HTTP/1.1" 401 43
WARNING 2020-03-25 17:52:16,499 log 228 Unauthorized: /users/info/
WARNING 2020-03-25 17:52:16,500 basehttp 154 "GET /users/info/?mobile=18638626519 HTTP/1.1" 401 43
WARNING 2020-03-25 18:04:15,706 log 228 Unauthorized: /users/info/
WARNING 2020-03-25 18:04:15,707 basehttp 154 "GET /users/info/?mobile=18638626519 HTTP/1.1" 401 43
WARNING 2020-03-25 18:04:21,137 log 228 Unauthorized: /users/info/
WARNING 2020-03-25 18:04:21,138 basehttp 154 "GET /users/info/ HTTP/1.1" 401 43
WARNING 2020-03-25 18:04:25,115 log 228 Unauthorized: /users/info/
WARNING 2020-03-25 18:04:25,116 basehttp 154 "GET /users/info/ HTTP/1.1" 401 43
WARNING 2020-03-25 18:06:00,943 log 228 Unauthorized: /users/info/
WARNING 2020-03-25 18:06:00,943 basehttp 154 "GET /users/info/?token=%22eyJ0eXAiOiJKV1QiLCJhbGciOiJIUzI1NiJ9.eyJ1c2VyX2lkIjo5LCJ1c2VybmFtZSI6IjE4NjM4NjI2NTE5IiwiZXhwIjoxNTg1MjE2MzIzLCJlbWFpbCI6IiIsIm1vYmlsZSI6IjE4NjM4NjI2NTE5In0.II6n43y3XcYbmbs-SiLMqOVhYObs7YibpAaqf0vMVek%22 HTTP/1.1" 401 43
WARNING 2020-03-25 18:06:11,479 log 228 Unauthorized: /users/info/
WARNING 2020-03-25 18:06:11,479 basehttp 154 "GET /users/info/?token=eyJ0eXAiOiJKV1QiLCJhbGciOiJIUzI1NiJ9.eyJ1c2VyX2lkIjo5LCJ1c2VybmFtZSI6IjE4NjM4NjI2NTE5IiwiZXhwIjoxNTg1MjE2MzIzLCJlbWFpbCI6IiIsIm1vYmlsZSI6IjE4NjM4NjI2NTE5In0.II6n43y3XcYbmbs-SiLMqOVhYObs7YibpAaqf0vMVek HTTP/1.1" 401 43
WARNING 2020-03-25 18:06:37,275 log 228 Unauthorized: /users/info/
WARNING 2020-03-25 18:06:37,276 basehttp 154 "GET /users/info/ HTTP/1.1" 401 43
INFO 2020-03-25 18:12:34,696 basehttp 154 "GET /users/info/ HTTP/1.1" 200 47
INFO 2020-03-26 09:54:06,389 basehttp 154 "GET /users/info/ HTTP/1.1" 200 47
